Workbook

Sheet Indice
B2: NOMENCLATURA | E2: INDICE
B4: Act | C4: Actividad | E4: Metas
B5: PIUP | C5: Procesos Industriales y Uso de Productos | E5: Act_Cemento_Otros_PIUP_sinHFC
B6: HFC | C6: Hidrofluorocarbonos | E6: Act_HFC
B7: 5CN | C7: 5ta Comunicación Nacional | E7: Act_5CN_OtrosPIUP
B8: 4CN | C8: 4ta Comunicación Nacional | E8: Otras_CementoMiscelanea

Sheet Metas
C1: 2010 | D1: 2011 | E1: 2012 | F1: 2013 | G1: 2014 | H1: 2015 | I1: 2016 | J1: 2017 | K1: 2018 | L1: 2019 | M1: 2020 | N1: 2021 | O1: 2022 | P1: 2023 | Q1: 2024 | R1: 2025 | S1: 2026 | T1: 2027 | U1: 2028 | V1: 2029 | W1: 2030 | X1: 2031 | Y1: 2032 | Z1: 2033 | AA1: 2034 | AB1: 2035
B4: Emisiones [GgCO2e] - Sin HFC
B7: Nuevo Tendencial 1era NDC = Tendencial 5ta Comunicación y PLANMICC - Iniciativas Condicionales 1era NDC | C7: =SUM(C8:C9) -> 2205.4688 | D7: =SUM(D8:D9) -> 2307.3023 | E7: =SUM(E8:E9) -> 2409.1358 | F7: =SUM(F8:F9) -> 2406.0279 | G7: =SUM(G8:G9) -> 2402.82 | H7: =SUM(H8:H9) -> 2348.68 | I7: =SUM(I8:I9) -> 2294.44 | J7: =SUM(J8:J9) -> 2395.2739 | ... AB7: =SUM(AB8:AB9) -> 3975.4248
B8: Producción de Clinker | C8: =Act_Cemento_Otros_PIUP_sinHFC!H66 -> 1781.9688 | D8: =Act_Cemento_Otros_PIUP_sinHFC!I66 -> 1784.8023 | E8: =Act_Cemento_Otros_PIUP_sinHFC!J66 -> 1787.6358 | F8: =Act_Cemento_Otros_PIUP_sinHFC!K66 -> 1836.2279 | G8: =Act_Cemento_Otros_PIUP_sinHFC!L66 -> 1884.82 | H8: =Act_Cemento_Otros_PIUP_sinHFC!M66 -> 1817.78 | I8: =Act_Cemento_Otros_PIUP_sinHFC!N66 -> 1750.74 | J8: =Act_Cemento_Otros_PIUP_sinHFC!O66 -> 1925.7739 | ... AB8: =Act_Cemento_Otros_PIUP_sinHFC!AG66 -> 3329.8248
B9: Otros PI y UP | C9: =Act_Cemento_Otros_PIUP_sinHFC!H58 -> 423.5 | D9: =Act_Cemento_Otros_PIUP_sinHFC!I58 -> 522.5 | E9: =Act_Cemento_Otros_PIUP_sinHFC!J58 -> 621.5 | F9: =Act_Cemento_Otros_PIUP_sinHFC!K58 -> 569.8 | G9: =Act_Cemento_Otros_PIUP_sinHFC!L58 -> 518 | H9: =Act_Cemento_Otros_PIUP_sinHFC!M58 -> 530.9 | I9: =Act_Cemento_Otros_PIUP_sinHFC!N58 -> 543.7 | J9: =Act_Cemento_Otros_PIUP_sinHFC!O58 -> 469.5 | ... AB9: =Act_Cemento_Otros_PIUP_sinHFC!AG58 -> 645.6
B10: NDC Incondicional de la 2da NDC (5ta Comunicación) | C10: =SUM(C11:C12) -> 2205.4688 | D10: =SUM(D11:D12) -> 2307.3023 | E10: =SUM(E11:E12) -> 2409.1358 | F10: =SUM(F11:F12) -> 2406.0279 | G10: =SUM(G11:G12) -> 2402.82 | H10: =SUM(H11:H12) -> 2348.68 | I10: =SUM(I11:I12) -> 2294.44 | J10: =SUM(J11:J12) -> 2359.385 | ... AB10: =SUM(AB11:AB12) -> 3445.2848
B11: Producción de Clinker | C11: =Act_Cemento_Otros_PIUP_sinHFC!H67 -> 1781.9688 | D11: =Act_Cemento_Otros_PIUP_sinHFC!I67 -> 1784.8023 | E11: =Act_Cemento_Otros_PIUP_sinHFC!J67 -> 1787.6358 | F11: =Act_Cemento_Otros_PIUP_sinHFC!K67 -> 1836.2279 | G11: =Act_Cemento_Otros_PIUP_sinHFC!L67 -> 1884.82 | H11: =Act_Cemento_Otros_PIUP_sinHFC!M67 -> 1817.78 | I11: =Act_Cemento_Otros_PIUP_sinHFC!N67 -> 1750.74 | J11: =Act_Cemento_Otros_PIUP_sinHFC!O67 -> 1889.885 | ... AB11: =Act_Cemento_Otros_PIUP_sinHFC!AG67 -> 2799.6848
B12: Otros PI y UP | C12: =Act_Cemento_Otros_PIUP_sinHFC!H58 -> 423.5 | D12: =Act_Cemento_Otros_PIUP_sinHFC!I58 -> 522.5 | E12: =Act_Cemento_Otros_PIUP_sinHFC!J58 -> 621.5 | F12: =Act_Cemento_Otros_PIUP_sinHFC!K58 -> 569.8 | G12: =Act_Cemento_Otros_PIUP_sinHFC!L58 -> 518 | H12: =Act_Cemento_Otros_PIUP_sinHFC!M58 -> 530.9 | I12: =Act_Cemento_Otros_PIUP_sinHFC!N58 -> 543.7 | J12: =Act_Cemento_Otros_PIUP_sinHFC!O58 -> 469.5 | ... AB12: =Act_Cemento_Otros_PIUP_sinHFC!AG58 -> 645.6
B13: NDC Incondicional + Condicional de la 2da NDC (5ta Comunicación) | C13: =SUM(C14:C15) -> 2205.4688 | D13: =SUM(D14:D15) -> 2307.3023 | E13: =SUM(E14:E15) -> 2409.1358 | F13: =SUM(F14:F15) -> 2406.0279 | G13: =SUM(G14:G15) -> 2402.82 | H13: =SUM(H14:H15) -> 2348.68 | I13: =SUM(I14:I15) -> 2294.44 | J13: =SUM(J14:J15) -> 2359.385 | ... AB13: =SUM(AB14:AB15) -> 3445.2848
B14: Producción de Clinker | C14: =Act_Cemento_Otros_PIUP_sinHFC!H68 -> 1781.9688 | D14: =Act_Cemento_Otros_PIUP_sinHFC!I68 -> 1784.8023 | E14: =Act_Cemento_Otros_PIUP_sinHFC!J68 -> 1787.6358 | F14: =Act_Cemento_Otros_PIUP_sinHFC!K68 -> 1836.2279 | G14: =Act_Cemento_Otros_PIUP_sinHFC!L68 -> 1884.82 | H14: =Act_Cemento_Otros_PIUP_sinHFC!M68 -> 1817.78 | I14: =Act_Cemento_Otros_PIUP_sinHFC!N68 -> 1750.74 | J14: =Act_Cemento_Otros_PIUP_sinHFC!O68 -> 1889.885 | ... AB14: =Act_Cemento_Otros_PIUP_sinHFC!AG68 -> 2799.6848
B15: Otros PI y UP | C15: =Act_Cemento_Otros_PIUP_sinHFC!H58 -> 423.5 | D15: =Act_Cemento_Otros_PIUP_sinHFC!I58 -> 522.5 | E15: =Act_Cemento_Otros_PIUP_sinHFC!J58 -> 621.5 | F15: =Act_Cemento_Otros_PIUP_sinHFC!K58 -> 569.8 | G15: =Act_Cemento_Otros_PIUP_sinHFC!L58 -> 518 | H15: =Act_Cemento_Otros_PIUP_sinHFC!M58 -> 530.9 | I15: =Act_Cemento_Otros_PIUP_sinHFC!N58 -> 543.7 | J15: =Act_Cemento_Otros_PIUP_sinHFC!O58 -> 469.5 | ... AB15: =Act_Cemento_Otros_PIUP_sinHFC!AG58 -> 645.6
B18: Meta 2da NDC [GgCO2e] - sin HFC
B20: NDC Incondicional de la 2da NDC (5ta Comunicación) | C20: =C10-C7 -> 0 | D20: =D10-D7 -> 0 | E20: =E10-E7 -> 0 | F20: =F10-F7 -> 0 | G20: =G10-G7 -> 0 | H20: =H10-H7 -> 0 | I20: =I10-I7 -> 0 | J20: =J10-J7 -> -35.888889 | ... AB20: =AB10-AB7 -> -530.14
B21: NDC Incondicional + Condicional de la 2da NDC (5ta Comunicación) | C21: =C13-C7 -> 0 | D21: =D13-D7 -> 0 | E21: =E13-E7 -> 0 | F21: =F13-F7 -> 0 | G21: =G13-G7 -> 0 | H21: =H13-H7 -> 0 | I21: =I13-I7 -> 0 | J21: =J13-J7 -> -35.888889 | ... AB21: =AB13-AB7 -> -530.14
B24: Meta 2da NDC [%] - sin HFC
B26: NDC Incondicional de la 2da NDC (5ta Comunicación) | C26: =(C10-C7)/C7 -> 0 | D26: =(D10-D7)/D7 -> 0 | E26: =(E10-E7)/E7 -> 0 | F26: =(F10-F7)/F7 -> 0 | G26: =(G10-G7)/G7 -> 0 | H26: =(H10-H7)/H7 -> 0 | I26: =(I10-I7)/I7 -> 0 | J26: =(J10-J7)/J7 -> -0.014983209 | ... AB26: =(AB10-AB7)/AB7 -> -0.1333543
B27: NDC Incondicional + Condicional de la 2da NDC (5ta Comunicación) | C27: =(C13-C7)/C7 -> 0 | D27: =(D13-D7)/D7 -> 0 | E27: =(E13-E7)/E7 -> 0 | F27: =(F13-F7)/F7 -> 0 | G27: =(G13-G7)/G7 -> 0 | H27: =(H13-H7)/H7 -> 0 | I27: =(I13-I7)/I7 -> 0 | J27: =(J13-J7)/J7 -> -0.014983209 | ... AB27: =(AB13-AB7)/AB7 -> -0.1333543
B31: Emisiones [GgCO2e] - con HFC
B34: Nuevo Tendencial 1era NDC = Tendencial 5ta Comunicación y PLANMICC - Iniciativas Condicionales 1era NDC | C34: =SUM(C35:C37) -> 2420.3688 | D34: =SUM(D35:D37) -> 2559.3023 | E34: =SUM(E35:E37) -> 2698.2358 | F34: =SUM(F35:F37) -> 2737.8279 | G34: =SUM(G35:G37) -> 2777.32 | H34: =SUM(H35:H37) -> 2772.38 | I34: =SUM(I35:I37) -> 2767.34 | J34: =SUM(J35:J37) -> 2891.2739 | ... AB34: =SUM(AB35:AB37) -> 9400.7248
B35: Producción de Clinker | C35: =Act_Cemento_Otros_PIUP_sinHFC!H66 -> 1781.9688 | D35: =Act_Cemento_Otros_PIUP_sinHFC!I66 -> 1784.8023 | E35: =Act_Cemento_Otros_PIUP_sinHFC!J66 -> 1787.6358 | F35: =Act_Cemento_Otros_PIUP_sinHFC!K66 -> 1836.2279 | G35: =Act_Cemento_Otros_PIUP_sinHFC!L66 -> 1884.82 | H35: =Act_Cemento_Otros_PIUP_sinHFC!M66 -> 1817.78 | I35: =Act_Cemento_Otros_PIUP_sinHFC!N66 -> 1750.74 | J35: =Act_Cemento_Otros_PIUP_sinHFC!O66 -> 1925.7739 | ... AB35: =Act_Cemento_Otros_PIUP_sinHFC!AG66 -> 3329.8248
B36: Otros PI y UP | C36: =Act_Cemento_Otros_PIUP_sinHFC!H58 -> 423.5 | D36: =Act_Cemento_Otros_PIUP_sinHFC!I58 -> 522.5 | E36: =Act_Cemento_Otros_PIUP_sinHFC!J58 -> 621.5 | F36: =Act_Cemento_Otros_PIUP_sinHFC!K58 -> 569.8 | G36: =Act_Cemento_Otros_PIUP_sinHFC!L58 -> 518 | H36: =Act_Cemento_Otros_PIUP_sinHFC!M58 -> 530.9 | I36: =Act_Cemento_Otros_PIUP_sinHFC!N58 -> 543.7 | J36: =Act_Cemento_Otros_PIUP_sinHFC!O58 -> 469.5 | ... AB36: =Act_Cemento_Otros_PIUP_sinHFC!AG58 -> 645.6
B37: HFC | C37: =Act_HFC!F19*1000 -> 214.9 | D37: =Act_HFC!G19*1000 -> 252 | E37: =Act_HFC!H19*1000 -> 289.1 | F37: =Act_HFC!I19*1000 -> 331.8 | G37: =Act_HFC!J19*1000 -> 374.5 | H37: =Act_HFC!K19*1000 -> 423.7 | I37: =Act_HFC!L19*1000 -> 472.9 | J37: =Act_HFC!M19*1000 -> 496 | ... AB37: =Act_HFC!AE19*1000 -> 5425.3
B38: NDC Incondicional de la 2da NDC (5ta Comunicación) | C38: =SUM(C39:C41) -> 2420.3688 | D38: =SUM(D39:D41) -> 2559.3023 | E38: =SUM(E39:E41) -> 2698.2358 | F38: =SUM(F39:F41) -> 2737.8279 | G38: =SUM(G39:G41) -> 2777.32 | H38: =SUM(H39:H41) -> 2772.38 | I38: =SUM(I39:I41) -> 2767.34 | J38: =SUM(J39:J41) -> 2855.385 | ... AB38: =SUM(AB39:AB41) -> 8234.7848
B39: Producción de Clinker | C39: =Act_Cemento_Otros_PIUP_sinHFC!H67 -> 1781.9688 | D39: =Act_Cemento_Otros_PIUP_sinHFC!I67 -> 1784.8023 | E39: =Act_Cemento_Otros_PIUP_sinHFC!J67 -> 1787.6358 | F39: =Act_Cemento_Otros_PIUP_sinHFC!K67 -> 1836.2279 | G39: =Act_Cemento_Otros_PIUP_sinHFC!L67 -> 1884.82 | H39: =Act_Cemento_Otros_PIUP_sinHFC!M67 -> 1817.78 | I39: =Act_Cemento_Otros_PIUP_sinHFC!N67 -> 1750.74 | J39: =Act_Cemento_Otros_PIUP_sinHFC!O67 -> 1889.885 | ... AB39: =Act_Cemento_Otros_PIUP_sinHFC!AG67 -> 2799.6848
B40: Otros PI y UP | C40: =Act_Cemento_Otros_PIUP_sinHFC!H58 -> 423.5 | D40: =Act_Cemento_Otros_PIUP_sinHFC!I58 -> 522.5 | E40: =Act_Cemento_Otros_PIUP_sinHFC!J58 -> 621.5 | F40: =Act_Cemento_Otros_PIUP_sinHFC!K58 -> 569.8 | G40: =Act_Cemento_Otros_PIUP_sinHFC!L58 -> 518 | H40: =Act_Cemento_Otros_PIUP_sinHFC!M58 -> 530.9 | I40: =Act_Cemento_Otros_PIUP_sinHFC!N58 -> 543.7 | J40: =Act_Cemento_Otros_PIUP_sinHFC!O58 -> 469.5 | ... AB40: =Act_Cemento_Otros_PIUP_sinHFC!AG58 -> 645.6
B41: HFC | C41: =Act_HFC!F20*1000 -> 214.9 | D41: =Act_HFC!G20*1000 -> 252 | E41: =Act_HFC!H20*1000 -> 289.1 | F41: =Act_HFC!I20*1000 -> 331.8 | G41: =Act_HFC!J20*1000 -> 374.5 | H41: =Act_HFC!K20*1000 -> 423.7 | I41: =Act_HFC!L20*1000 -> 472.9 | J41: =Act_HFC!M20*1000 -> 496 | ... AB41: =Act_HFC!AE20*1000 -> 4789.5
B42: NDC Incondicional + Condicional de la 2da NDC (5ta Comunicación) | C42: =SUM(C43:C45) -> 2420.3688 | D42: =SUM(D43:D45) -> 2559.3023 | E42: =SUM(E43:E45) -> 2698.2358 | F42: =SUM(F43:F45) -> 2737.8279 | G42: =SUM(G43:G45) -> 2777.32 | H42: =SUM(H43:H45) -> 2772.38 | I42: =SUM(I43:I45) -> 2767.34 | J42: =SUM(J43:J45) -> 2855.385 | ... AB42: =SUM(AB43:AB45) -> 8234.7848
B43: Producción de Clinker | C43: =Act_Cemento_Otros_PIUP_sinHFC!H68 -> 1781.9688 | D43: =Act_Cemento_Otros_PIUP_sinHFC!I68 -> 1784.8023 | E43: =Act_Cemento_Otros_PIUP_sinHFC!J68 -> 1787.6358 | F43: =Act_Cemento_Otros_PIUP_sinHFC!K68 -> 1836.2279 | G43: =Act_Cemento_Otros_PIUP_sinHFC!L68 -> 1884.82 | H43: =Act_Cemento_Otros_PIUP_sinHFC!M68 -> 1817.78 | I43: =Act_Cemento_Otros_PIUP_sinHFC!N68 -> 1750.74 | J43: =Act_Cemento_Otros_PIUP_sinHFC!O68 -> 1889.885 | ... AB43: =Act_Cemento_Otros_PIUP_sinHFC!AG68 -> 2799.6848
B44: Otros PI y UP | C44: =Act_Cemento_Otros_PIUP_sinHFC!H58 -> 423.5 | D44: =Act_Cemento_Otros_PIUP_sinHFC!I58 -> 522.5 | E44: =Act_Cemento_Otros_PIUP_sinHFC!J58 -> 621.5 | F44: =Act_Cemento_Otros_PIUP_sinHFC!K58 -> 569.8 | G44: =Act_Cemento_Otros_PIUP_sinHFC!L58 -> 518 | H44: =Act_Cemento_Otros_PIUP_sinHFC!M58 -> 530.9 | I44: =Act_Cemento_Otros_PIUP_sinHFC!N58 -> 543.7 | J44: =Act_Cemento_Otros_PIUP_sinHFC!O58 -> 469.5 | ... AB44: =Act_Cemento_Otros_PIUP_sinHFC!AG58 -> 645.6
B45: HFC | C45: =Act_HFC!F20*1000 -> 214.9 | D45: =Act_HFC!G20*1000 -> 252 | E45: =Act_HFC!H20*1000 -> 289.1 | F45: =Act_HFC!I20*1000 -> 331.8 | G45: =Act_HFC!J20*1000 -> 374.5 | H45: =Act_HFC!K20*1000 -> 423.7 | I45: =Act_HFC!L20*1000 -> 472.9 | J45: =Act_HFC!M20*1000 -> 496 | ... AB45: =Act_HFC!AE20*1000 -> 4789.5
B48: Meta 2da NDC [GgCO2e] - con HFC
B50: NDC Incondicional de la 2da NDC (5ta Comunicación) | C50: =C38-C34 -> 0 | D50: =D38-D34 -> 0 | E50: =E38-E34 -> 0 | F50: =F38-F34 -> 0 | G50: =G38-G34 -> 0 | H50: =H38-H34 -> 0 | I50: =I38-I34 -> 0 | J50: =J38-J34 -> -35.888889 | ... AB50: =AB38-AB34 -> -1165.94
B51: NDC Incondicional + Condicional de la 2da NDC (5ta Comunicación) | C51: =C42-C34 -> 0 | D51: =D42-D34 -> 0 | E51: =E42-E34 -> 0 | F51: =F42-F34 -> 0 | G51: =G42-G34 -> 0 | H51: =H42-H34 -> 0 | I51: =I42-I34 -> 0 | J51: =J42-J34 -> -35.888889 | ... AB51: =AB42-AB34 -> -1165.94
B54: Meta 2da NDC [%] - con HFC
B56: NDC Incondicional de la 2da NDC (5ta Comunicación) | C56: =(C38-C34)/C34 -> 0 | D56: =(D38-D34)/D34 -> 0 | E56: =(E38-E34)/E34 -> 0 | F56: =(F38-F34)/F34 -> 0 | G56: =(G38-G34)/G34 -> 0 | H56: =(H38-H34)/H34 -> 0 | I56: =(I38-I34)/I34 -> 0 | J56: =(J38-J34)/J34 -> -0.012412829 | ... AB56: =(AB38-AB34)/AB34 -> -0.12402661
B57: NDC Incondicional + Condicional de la 2da NDC (5ta Comunicación) | C57: =(C42-C34)/C34 -> 0 | D57: =(D42-D34)/D34 -> 0 | E57: =(E42-E34)/E34 -> 0 | F57: =(F42-F34)/F34 -> 0 | G57: =(G42-G34)/G34 -> 0 | H57: =(H42-H34)/H34 -> 0 | I57: =(I42-I34)/I34 -> 0 | J57: =(J42-J34)/J34 -> -0.012412829 | ... AB57: =(AB42-AB34)/AB34 -> -0.12402661

Sheet Act_Cemento_Otros_PIUP_sinHFC
H1: 2010 | I1: 2011 | J1: 2012 | K1: 2013 | L1: 2014 | M1: 2015 | N1: 2016 | O1: 2017 | P1: 2018 | Q1: 2019 | R1: 2020 | S1: 2021 | T1: 2022 | U1: 2023 | V1: 2024 | W1: 2025 | X1: 2026 | Y1: 2027 | Z1: 2028 | AA1: 2029 | AB1: 2030 | AC1: 2031 | AD1: 2032 | AE1: 2033 | AF1: 2034 | AG1: 2035
C4: Fuente: Emisiones | G4: Sector PIUP Emisiones por escenario [GgCO2e] - SIN HFC
C6: 4CN y 5CN para datos históricos 2010-2022 y PLANMICC para futuro 2023-2050 | G6: Tendencial 5ta Comunicación y pocos supuestos del PLANMICC | H6: =H76 -> 2205.4688 | I6: =I76 -> 2307.3023 | J6: =J76 -> 2409.1358 | K6: =K76 -> 2406.0279 | L6: =L76 -> 2402.82 | M6: =M76 -> 2348.68 | N6: =N76 -> 2294.44 | O6: =O76 -> 2359.385 | ... AG6: =AG76 -> 3975.4248
C7: Iniciativas 1era NDC | G7: Nuevo Tendencial 1era NDC = Tendencial 5ta Comunicación y pocos supuestos del PLANMICC - Iniciativas Condicionales 1era NDC | H7: =H77 -> 2205.4688 | I7: =I77 -> 2307.3023 | J7: =J77 -> 2409.1358 | K7: =K77 -> 2406.0279 | L7: =L77 -> 2402.82 | M7: =M77 -> 2348.68 | N7: =N77 -> 2294.44 | O7: =O77 -> 2395.2739 | ... AG7: =AG77 -> 3975.4248
C8: Escenario tendencial + Iniciativas 2da NDC | G8: NDC Incondicional de la 2da NDC (5ta Comunicación) | H8: =H78 -> 2205.4688 | I8: =I78 -> 2307.3023 | J8: =J78 -> 2409.1358 | K8: =K78 -> 2406.0279 | L8: =L78 -> 2402.82 | M8: =M78 -> 2348.68 | N8: =N78 -> 2294.44 | O8: =O78 -> 2359.385 | ... AG8: =AG78 -> 3445.2848
G9: NDC Incondicional + Condicional de la 2da NDC (5ta Comunicación) | H9: =H79 -> 2205.4688 | I9: =I79 -> 2307.3023 | J9: =J79 -> 2409.1358 | K9: =K79 -> 2406.0279 | L9: =L79 -> 2402.82 | M9: =M79 -> 2348.68 | N9: =N79 -> 2294.44 | O9: =O79 -> 2359.385 | ... AG9: =AG79 -> 3445.2848
G13: Meta Incondicional | H13: =(H8-H7)/H7 -> 0 | I13: =(I8-I7)/I7 -> 0 | J13: =(J8-J7)/J7 -> 0 | K13: =(K8-K7)/K7 -> 0 | L13: =(L8-L7)/L7 -> 0 | M13: =(M8-M7)/M7 -> 0 | N13: =(N8-N7)/N7 -> 0 | O13: =(O8-O7)/O7 -> -0.014983209 | ... AG13: =(AG8-AG7)/AG7 -> -0.1333543
G14: Meta Incondicional + Condicional | H14: =(H9-H7)/H7 -> 0 | I14: =(I9-I7)/I7 -> 0 | J14: =(J9-J7)/J7 -> 0 | K14: =(K9-K7)/K7 -> 0 | L14: =(L9-L7)/L7 -> 0 | M14: =(M9-M7)/M7 -> 0 | N14: =(N9-N7)/N7 -> 0 | O14: =(O9-O7)/O7 -> -0.014983209 | ... AG14: =(AG9-AG7)/AG7 -> -0.1333543
C19: Iniciativas 1era NDC | G19: Potencial de reducción de Iniciativa Incondicional de factor de Clinker 1era NDC [GgCO2e] | H19: 2.8421709e-14 | I19: 0 | J19: 0 | K19: 0 | L19: 0 | M19: 0 | N19: 0 | O19: 35.888889 | P19: 71.777778 | Q19: 107.66667 | R19: 143.55556 | S19: 179.44444 | T19: 215.33333 | U19: 251.22222 | V19: 287.11111 | W19: 323 | X19: 0 | Y19: 0 | Z19: 0 | AA19: 0 | AB19: 0 | AC19: 0 | AD19: 0 | AE19: 0 | AF19: 0 | AG19: 0
C20: Instituto Ecuatoriano deñ Cemento y del Hormigón | G20: Potencial de reducción de Iniciativa 2da NDC convenida por cementeras [GgCO2e] | H20: 0 | I20: 0 | J20: 0 | K20: 0 | L20: 0 | M20: 0 | N20: 0 | O20: 0 | P20: 0 | Q20: 0 | R20: 0 | S20: 0 | T20: 0 | U20: 0 | V20: 0 | W20: 0 | X20: 343.714 | Y20: 364.428 | Z20: 385.142 | AA20: 405.856 | AB20: 426.57 | AC20: 447.284 | AD20: 467.998 | AE20: 488.712 | AF20: 509.426 | AG20: 530.14
C24: Fuente: Supuestos | G24: Producción de cemento [Mt]
C26: 4CN y 5CN para datos históricos 2010-2022 y PLANMICC para futuro 2023-2050 | G26: Tendencial 5ta Comunicación y pocos supuestos del PLANMICC | H26: 5.2749 | I26: 5.6682 | J26: 6.0615 | K26: 6.3078 | L26: 6.5541 | M26: 5.7819 | N26: 5.0097 | O26: 5.0328 | P26: 5.0559 | Q26: =Q28 -> 4.2404072 | R26: =R28 -> 3.4118925 | S26: =S28 -> 5.0137299 | T26: =T28 -> 4.6245831 | U26: =$T$26*Otras_CementoMiscelanea!S29 -> 4.8610755 | V26: =$T$26*Otras_CementoMiscelanea!T29 -> 5.0974588 | W26: =$T$26*Otras_CementoMiscelanea!U29 -> 5.3339513 | X26: =$T$26*Otras_CementoMiscelanea!V29 -> 5.5704437 | Y26: =$T$26*Otras_CementoMiscelanea!W29 -> 5.806827 | Z26: =$T$26*Otras_CementoMiscelanea!X29 -> 6.0433194 | AA26: =$T$26*Otras_CementoMiscelanea!Y29 -> 6.2798119 | AB26: =$T$26*Otras_CementoMiscelanea!Z29 -> 6.5161952 | ... AG26: =$T$26*Otras_CementoMiscelanea!AE29 -> 7.6985482
G27: Nuevo Tendencial 1era NDC = Tendencial 5ta Comunicación y pocos supuestos del PLANMICC - Iniciativas Condicionales 1era NDC | H27: 5.2749 | I27: 5.6682 | J27: 6.0615 | K27: 6.3078 | L27: 6.5541 | M27: 5.7819 | N27: 5.0097 | O27: 5.0328 | P27: 5.0559 | Q27: =Q28 -> 4.2404072 | R27: =R28 -> 3.4118925 | S27: =S28 -> 5.0137299 | T27: =T28 -> 4.6245831 | U27: =U26 -> 4.8610755 | V27: =V26 -> 5.0974588 | W27: =W26 -> 5.3339513 | X27: =X26 -> 5.5704437 | Y27: =Y26 -> 5.806827 | Z27: =Z26 -> 6.0433194 | AA27: =AA26 -> 6.2798119 | AB27: =AB26 -> 6.5161952 | ... AG27: =AG26 -> 7.6985482
G28: NDC Incondicional de la 2da NDC (5ta Comunicación) | H28: 5.2749 | I28: 5.6682 | J28: 6.0615 | K28: 6.3078 | L28: 6.5541 | M28: 5.7819 | N28: 5.0097 | O28: 5.0328 | P28: 5.0559 | Q28: =Q39/Q50 -> 4.2404072 | R28: =R39/R50 -> 3.4118925 | S28: =S39/S50 -> 5.0137299 | T28: =T39/T50 -> 4.6245831 | U28: =U26 -> 4.8610755 | V28: =V26 -> 5.0974588 | W28: =W26 -> 5.3339513 | X28: =X26 -> 5.5704437 | Y28: =Y26 -> 5.806827 | Z28: =Z26 -> 6.0433194 | AA28: =AA26 -> 6.2798119 | AB28: =AB26 -> 6.5161952 | ... AG28: =AG26 -> 7.6985482
G29: NDC Incondicional + Condicional de la 2da NDC (5ta Comunicación) | H29: 5.2749 | I29: 5.6682 | J29: 6.0615 | K29: 6.3078 | L29: 6.5541 | M29: 5.7819 | N29: 5.0097 | O29: 5.0328 | P29: 5.0559 | Q29: =Q40/Q51 -> 4.2404072 | R29: =R40/R51 -> 3.4118925 | S29: =S40/S51 -> 5.0137299 | T29: =T40/T51 -> 4.6245831 | U29: =U26 -> 4.8610755 | V29: =V26 -> 5.0974588 | W29: =W26 -> 5.3339513 | X29: =X26 -> 5.5704437 | Y29: =Y26 -> 5.806827 | Z29: =Z26 -> 6.0433194 | AA29: =AA26 -> 6.2798119 | AB29: =AB26 -> 6.5161952 | ... AG29: =AG26 -> 7.6985482
G35: Producción de Clinker [Mt]
C37: 4CN y 5CN para datos históricos 2010-2022 y PLANMICC para futuro 2023-2050 | G37: Tendencial 5ta Comunicación y pocos supuestos del PLANMICC | H37: =H26*H48 -> 3.3289894 | I37: =I26*I48 -> 3.328367 | J37: =J26*J48 -> 3.3277635 | K37: =K26*K48 -> 3.4339663 | L37: =L26*L48 -> 3.5398694 | M37: =M26*M48 -> 3.4107428 | N37: =N26*N48 -> 3.2818545 | O37: =O26*O48 -> 3.5380584 | P37: =P26*P48 -> 3.7939474 | Q37: =Q65/(Q57*1000) -> 3.1571245 | R37: =R65/(R57*1000) -> 2.5202513 | S37: =S65/(S57*1000) -> 3.6740613 | T37: =T65/(T57*1000) -> 3.3617636 | U37: =U65/(U57*1000) -> 3.5051595 | V37: =V65/(V57*1000) -> 3.6457026 | W37: =W65/(W57*1000) -> 3.7835494 | X37: =X65/(X57*1000) -> 4.5613178 | ... AG37: =AG65/(AG57*1000) -> 6.2262992
G38: Nuevo Tendencial 1era NDC = Tendencial 5ta Comunicación y pocos supuestos del PLANMICC - Iniciativas Condicionales 1era NDC | H38: =H66/(H57*1000) -> 3.3289161 | I38: =I66/(I57*1000) -> 3.328613 | J38: =J66/(J57*1000) -> 3.3276914 | K38: =K66/(K57*1000) -> 3.4341274 | L38: =L66/(L57*1000) -> 3.5395681 | M38: =M66/(M57*1000) -> 3.411109 | N38: =N66/(N57*1000) -> 3.281612 | O38: =O66/(O57*1000) -> 3.6053054 | ... AG38: =AG66/(AG57*1000) -> 6.2262992
G39: NDC Incondicional de la 2da NDC (5ta Comunicación) | H39: =H67/(H57*1000) -> 3.3289161 | I39: =I67/(I57*1000) -> 3.328613 | J39: =J67/(J57*1000) -> 3.3276914 | K39: =K67/(K57*1000) -> 3.4341274 | L39: =L67/(L57*1000) -> 3.5395681 | M39: =M67/(M57*1000) -> 3.411109 | N39: =N67/(N57*1000) -> 3.281612 | O39: =O67/(O57*1000) -> 3.5381166 | ... T39: =T67/(T57*1000) -> 3.3617636 | U39: =U28*U50 -> 3.5051595 | V39: =V28*V50 -> 3.6457026 | W39: =W28*W50 -> 3.7835494 | X39: =X28*X50 -> 3.9186214 | Y39: =Y28*Y50 -> 4.0508425 | Z39: =Z28*Z50 -> 4.1803655 | AA39: =AA28*AA50 -> 4.3071136 | AB39: =AB28*AB50 -> 4.4310127 | ... AG39: =AG28*AG50 -> 5.2350128
G40: NDC Incondicional + Condicional de la 2da NDC (5ta Comunicación) | H40: =H68/(H57*1000) -> 3.3289161 | I40: =I68/(I57*1000) -> 3.328613 | J40: =J68/(J57*1000) -> 3.3276914 | K40: =K68/(K57*1000) -> 3.4341274 | L40: =L68/(L57*1000) -> 3.5395681 | M40: =M68/(M57*1000) -> 3.411109 | N40: =N68/(N57*1000) -> 3.281612 | O40: =O68/(O57*1000) -> 3.5381166 | ... T40: =T68/(T57*1000) -> 3.3617636 | U40: =U29*U51 -> 3.5051595 | V40: =V29*V51 -> 3.6457026 | W40: =W29*W51 -> 3.7835494 | X40: =X29*X51 -> 3.9186214 | Y40: =Y29*Y51 -> 4.0508425 | Z40: =Z29*Z51 -> 4.1803655 | AA40: =AA29*AA51 -> 4.3071136 | AB40: =AB29*AB51 -> 4.4310127 | ... AG40: =AG29*AG51 -> 5.2350128
G46: Factor de Clinker [%]
C48: 4CN y 5CN para datos históricos 2010-2022 y PLANMICC para futuro 2023-2050 | G48: Tendencial 5ta Comunicación y pocos supuestos del PLANMICC | H48: 0.6311 | I48: 0.5872 | J48: 0.549 | K48: 0.5444 | L48: 0.5401 | M48: 0.5899 | N48: 0.6551 | O48: 0.703 | P48: 0.7504 | Q48: =Q37/Q26 -> 0.74453333 | R48: =R37/R26 -> 0.73866667 | S48: =S37/S26 -> 0.7328 | T48: =T37/T26 -> 0.72693333 | U48: =U37/U26 -> 0.72106667 | V48: =V37/V26 -> 0.7152 | W48: =W37/W26 -> 0.70933333 | X48: =X37/X26 -> 0.81884281 | ... AG48: =AG37/AG26 -> 0.80876278
C49: 4CN y 5CN para datos históricos 2010-2022 y PLANMICC para futuro 2023-2050 + 1era NDC y PI | G49: Nuevo Tendencial 1era NDC = Tendencial 5ta Comunicación y pocos supuestos del PLANMICC - Iniciativas Condicionales 1era NDC | H49: =H38/H27 -> 0.6310861 | I49: =I38/I27 -> 0.5872434 | J49: =J38/J27 -> 0.54898811 | K49: =K38/K27 -> 0.54442553 | L49: =L38/L27 -> 0.54005402 | M49: =M38/M27 -> 0.58996334 | N49: =N38/N27 -> 0.6550516 | O49: =O38/O27 -> 0.71636175 | ... AG49: =AG38/AG27 -> 0.80876278
C50: Iniciativas 2da NDC | G50: NDC Incondicional de la 2da NDC (5ta Comunicación) | H50: =H39/H28 -> 0.6310861 | I50: =I39/I28 -> 0.5872434 | J50: =J39/J28 -> 0.54898811 | K50: =K39/K28 -> 0.54442553 | L50: =L39/L28 -> 0.54005402 | M50: =M39/M28 -> 0.58996334 | N50: =N39/N28 -> 0.6550516 | O50: =O39/O28 -> 0.70301157 | P50: 0.7504 | Q50: 0.74453333 | R50: 0.73866667 | S50: 0.7328 | T50: 0.72693333 | U50: 0.72106667 | V50: 0.7152 | W50: 0.70933333 | X50: 0.70346667 | Y50: 0.6976 | Z50: 0.69173333 | AA50: 0.68586667 | AB50: 0.68 | AC50: 0.68 | AD50: 0.68 | AE50: 0.68 | AF50: 0.68 | AG50: 0.68
G51: NDC Incondicional + Condicional de la 2da NDC (5ta Comunicación) | H51: =H40/H29 -> 0.6310861 | I51: =I40/I29 -> 0.5872434 | J51: =J40/J29 -> 0.54898811 | K51: =K40/K29 -> 0.54442553 | L51: =L40/L29 -> 0.54005402 | M51: =M40/M29 -> 0.58996334 | N51: =N40/N29 -> 0.6550516 | O51: =O40/O29 -> 0.70301157 | P51: 0.7504 | Q51: 0.74453333 | R51: 0.73866667 | S51: 0.7328 | T51: 0.72693333 | U51: 0.72106667 | V51: 0.7152 | W51: 0.70933333 | X51: 0.70346667 | Y51: 0.6976 | Z51: 0.69173333 | AA51: 0.68586667 | AB51: 0.68 | AC51: 0.68 | AD51: 0.68 | AE51: 0.68 | AF51: 0.68 | AG51: 0.68
C57: NIR histórico | G57: Factor de emisión [MtCO2e/Mt Clinker] | H57: 0.5353 | I57: 0.5362 | J57: 0.5372 | K57: 0.5347 | L57: 0.5325 | M57: 0.5329 | N57: 0.5335 | O57: 0.53415 | P57: 0.5348 | Q57: 0.5348 | R57: 0.5348 | S57: 0.5348 | T57: 0.5348 | U57: 0.5348 | V57: 0.5348 | W57: 0.5348 | X57: 0.5348 | Y57: 0.5348 | Z57: 0.5348 | AA57: 0.5348 | AB57: 0.5348 | AC57: 0.5348 | AD57: 0.5348 | AE57: 0.5348 | AF57: 0.5348 | AG57: 0.5348
C58: 4CN y 5CN para histórico 2010-2022 y PLANMICC para futuro 2023-2035 | G58: Emisiones de otros PI y UP [GgCO2e] | H58: =Act_5CN_OtrosPIUP!E48 -> 423.5 | I58: =Act_5CN_OtrosPIUP!F48 -> 522.5 | J58: =Act_5CN_OtrosPIUP!G48 -> 621.5 | K58: =Act_5CN_OtrosPIUP!H48 -> 569.8 | L58: =Act_5CN_OtrosPIUP!I48 -> 518 | M58: =Act_5CN_OtrosPIUP!J48 -> 530.9 | N58: =Act_5CN_OtrosPIUP!K48 -> 543.7 | O58: =Act_5CN_OtrosPIUP!L48 -> 469.5 | ... AG58: =Act_5CN_OtrosPIUP!AD48 -> 645.6
G63: Comprobación de emisiones por Clinker [GgCO2e]
C65: Cálculo comprobación | G65: Tendencial 5ta Comunicación y pocos supuestos del PLANMICC | H65: 1781.9688 | I65: 1784.8023 | J65: 1787.6358 | K65: 1836.2279 | L65: 1884.82 | M65: 1817.78 | N65: 1750.74 | O65: 1889.885 | P65: 2029.03 | Q65: 1688.4302 | R65: 1347.8304 | S65: 1964.888 | T65: 1797.8712 | U65: =U67+U20 -> 1874.5593 | V65: =V67+V20 -> 1949.7217 | W65: =W67+W20 -> 2023.4422 | X65: =X67+X20 -> 2439.3928 | Y65: =Y67+Y20 -> 2530.8186 | Z65: =Z67+Z20 -> 2620.8015 | AA65: =AA67+AA20 -> 2709.3004 | AB65: =AB67+AB20 -> 2796.2756 | ... AG65: =AG67+AG20 -> 3329.8248
G66: Nuevo Tendencial 1era NDC = Tendencial 5ta Comunicación y pocos supuestos del PLANMICC - Iniciativas Condicionales 1era NDC | H66: =H77-H58 -> 1781.9688 | I66: =I77-I58 -> 1784.8023 | J66: =J77-J58 -> 1787.6358 | K66: =K77-K58 -> 1836.2279 | L66: =L77-L58 -> 1884.82 | M66: =M77-M58 -> 1817.78 | N66: =N77-N58 -> 1750.74 | O66: =O77-O58 -> 1925.7739 | ... T66: =T77-T58 -> 2013.2045 | U66: =U67+U20+U19 -> 2125.7815 | V66: =V67+V20+V19 -> 2236.8328 | W66: =W67+W20+W19 -> 2346.4422 | X66: =X67+X20+X19 -> 2439.3928 | Y66: =Y67+Y20+Y19 -> 2530.8186 | Z66: =Z67+Z20+Z19 -> 2620.8015 | AA66: =AA67+AA20+AA19 -> 2709.3004 | AB66: =AB67+AB20+AB19 -> 2796.2756 | ... AG66: =AG67+AG20+AG19 -> 3329.8248
G67: NDC Incondicional de la 2da NDC (5ta Comunicación) | H67: =H78-H58 -> 1781.9688 | I67: =I78-I58 -> 1784.8023 | J67: =J78-J58 -> 1787.6358 | K67: =K78-K58 -> 1836.2279 | L67: =L78-L58 -> 1884.82 | M67: =M78-M58 -> 1817.78 | N67: =N78-N58 -> 1750.74 | O67: =O78-O58 -> 1889.885 | ... T67: =T78-T58 -> 1797.8712 | U67: =U39*U57*1000 -> 1874.5593 | V67: =V39*V57*1000 -> 1949.7217 | W67: =W39*W57*1000 -> 2023.4422 | X67: =X39*X57*1000 -> 2095.6788 | Y67: =Y39*Y57*1000 -> 2166.3906 | Z67: =Z39*Z57*1000 -> 2235.6595 | AA67: =AA39*AA57*1000 -> 2303.4444 | AB67: =AB39*AB57*1000 -> 2369.7056 | ... AG67: =AG39*AG57*1000 -> 2799.6848
G68: NDC Incondicional + Condicional de la 2da NDC (5ta Comunicación) | H68: =H79-H58 -> 1781.9688 | I68: =I79-I58 -> 1784.8023 | J68: =J79-J58 -> 1787.6358 | K68: =K79-K58 -> 1836.2279 | L68: =L79-L58 -> 1884.82 | M68: =M79-M58 -> 1817.78 | N68: =N79-N58 -> 1750.74 | O68: =O79-O58 -> 1889.885 | ... T68: =T79-T58 -> 1797.8712 | U68: =U40*U57*1000 -> 1874.5593 | V68: =V40*V57*1000 -> 1949.7217 | W68: =W40*W57*1000 -> 2023.4422 | X68: =X40*X57*1000 -> 2095.6788 | Y68: =Y40*Y57*1000 -> 2166.3906 | Z68: =Z40*Z57*1000 -> 2235.6595 | AA68: =AA40*AA57*1000 -> 2303.4444 | AB68: =AB40*AB57*1000 -> 2369.7056 | ... AG68: =AG40*AG57*1000 -> 2799.6848
G74: Comprobación de emisiones totales [GgCO2e] - SIN HFC
C76: Cálculo comprobación | G76: Tendencial 5ta Comunicación y pocos supuestos del PLANMICC | H76: =H58+H65 -> 2205.4688 | I76: =I58+I65 -> 2307.3023 | J76: =J58+J65 -> 2409.1358 | K76: =K58+K65 -> 2406.0279 | L76: =L58+L65 -> 2402.82 | M76: =M58+M65 -> 2348.68 | N76: =N58+N65 -> 2294.44 | O76: =O58+O65 -> 2359.385 | ... T76: =T58+T65 -> 2288.2712 | U76: =U65+U58 -> 2375.3593 | V76: =V65+V58 -> 2461.2217 | W76: =W65+W58 -> 2545.8422 | X76: =X65+X58 -> 2973.1928 | Y76: =Y65+Y58 -> 3075.8186 | Z76: =Z65+Z58 -> 3177.6015 | AA76: =AA65+AA58 -> 3278.1004 | AB76: =AB65+AB58 -> 3377.0756 | ... AG76: =AG65+AG58 -> 3975.4248
G77: Nuevo Tendencial 1era NDC = Tendencial 5ta Comunicación y pocos supuestos del PLANMICC - Iniciativas Condicionales 1era NDC | H77: =H76+H19 -> 2205.4688 | I77: =I76+I19 -> 2307.3023 | J77: =J76+J19 -> 2409.1358 | K77: =K76+K19 -> 2406.0279 | L77: =L76+L19 -> 2402.82 | M77: =M76+M19 -> 2348.68 | N77: =N76+N19 -> 2294.44 | O77: =O76+O19 -> 2395.2739 | ... T77: =T76+T19 -> 2503.6045 | U77: =U66+U58 -> 2626.5815 | V77: =V66+V58 -> 2748.3328 | W77: =W66+W58 -> 2868.8422 | X77: =X66+X58 -> 2973.1928 | Y77: =Y66+Y58 -> 3075.8186 | Z77: =Z66+Z58 -> 3177.6015 | AA77: =AA66+AA58 -> 3278.1004 | AB77: =AB66+AB58 -> 3377.0756 | ... AG77: =AG66+AG58 -> 3975.4248
G78: NDC Incondicional de la 2da NDC (5ta Comunicación) | H78: =H76 -> 2205.4688 | I78: =I76 -> 2307.3023 | J78: =J76 -> 2409.1358 | K78: =K76 -> 2406.0279 | L78: =L76 -> 2402.82 | M78: =M76 -> 2348.68 | N78: =N76 -> 2294.44 | O78: =O76 -> 2359.385 | ... T78: =T76 -> 2288.2712 | U78: =U67+U58 -> 2375.3593 | V78: =V67+V58 -> 2461.2217 | W78: =W67+W58 -> 2545.8422 | X78: =X67+X58 -> 2629.4788 | Y78: =Y67+Y58 -> 2711.3906 | Z78: =Z67+Z58 -> 2792.4595 | AA78: =AA67+AA58 -> 2872.2444 | AB78: =AB67+AB58 -> 2950.5056 | ... AG78: =AG67+AG58 -> 3445.2848
G79: NDC Incondicional + Condicional de la 2da NDC (5ta Comunicación) | H79: =H76 -> 2205.4688 | I79: =I76 -> 2307.3023 | J79: =J76 -> 2409.1358 | K79: =K76 -> 2406.0279 | L79: =L76 -> 2402.82 | M79: =M76 -> 2348.68 | N79: =N76 -> 2294.44 | O79: =O76 -> 2359.385 | ... T79: =T76 -> 2288.2712 | U79: =U68+U58 -> 2375.3593 | V79: =V68+V58 -> 2461.2217 | W79: =W68+W58 -> 2545.8422 | X79: =X68+X58 -> 2629.4788 | Y79: =Y68+Y58 -> 2711.3906 | Z79: =Z68+Z58 -> 2792.4595 | AA79: =AA68+AA58 -> 2872.2444 | AB79: =AB68+AB58 -> 2950.5056 | ... AG79: =AG68+AG58 -> 3445.2848
G85: Demanda | H85: =ROUND(H27,4) -> 5.2749 | I85: =ROUND(I27,4) -> 5.6682 | J85: =ROUND(J27,4) -> 6.0615 | K85: =ROUND(K27,4) -> 6.3078 | L85: =ROUND(L27,4) -> 6.5541 | M85: =ROUND(M27,4) -> 5.7819 | N85: =ROUND(N27,4) -> 5.0097 | O85: =ROUND(O27,4) -> 5.0328 | ... AG85: =ROUND(AG27,4) -> 7.6985
G87: FC 1 | H87: =ROUND(H49,4) -> 0.6311 | I87: =ROUND(I49,4) -> 0.5872 | J87: =ROUND(J49,4) -> 0.549 | K87: =ROUND(K49,4) -> 0.5444 | L87: =ROUND(L49,4) -> 0.5401 | M87: =ROUND(M49,4) -> 0.59 | N87: =ROUND(N49,4) -> 0.6551 | O87: =ROUND(O49,4) -> 0.7164 | ... AG87: =ROUND(AG49,4) -> 0.8088
G88: FC 2 | H88: =ROUND(H50,4) -> 0.6311 | I88: =ROUND(I50,4) -> 0.5872 | J88: =ROUND(J50,4) -> 0.549 | K88: =ROUND(K50,4) -> 0.5444 | L88: =ROUND(L50,4) -> 0.5401 | M88: =ROUND(M50,4) -> 0.59 | N88: =ROUND(N50,4) -> 0.6551 | O88: =ROUND(O50,4) -> 0.703 | ... AG88: =ROUND(AG50,4) -> 0.68
...

Sheet Act_HFC
G5: Interpolación | R5: Calculado reconstruyendo figura 6 de la Hoja de ruta de HFC: no es el mejor enfoque pero es al menos numéricamente viable
F6: 2010 | G6: 2011 | H6: 2012 | I6: 2013 | J6: 2014 | K6: 2015 | L6: 2016 | M6: 2017 | N6: 2018 | O6: 2019 | P6: 2020 | Q6: 2021 | R6: 2022 | S6: 2023 | T6: 2024 | U6: 2025 | V6: 2026 | W6: 2027 | X6: 2028 | Y6: 2029 | Z6: 2030 | AA6: 2031 | AB6: 2032 | AC6: 2033 | AD6: 2034 | AE6: 2035
C7: GgCO2e | E7: 2F1 Refrigeración y Aire Acondicionado | F7: 214.93 | G7: 252.02 | H7: 289.11 | I7: 331.795 | J7: 374.48 | K7: 423.69 | L7: 472.9 | M7: 496 | N7: 519.1 | O7: 861.05 | P7: 1203 | Q7: 1325.05 | R7: 1957.58 | S7: 2383.9599 | T7: 2810.3397 | U7: 3236.7196 | V7: 3663.0995 | W7: 4089.4794 | X7: 4515.8593 | Y7: 4942.2391 | Z7: 5368.619 | AA7: 5379.9602 | AB7: 5391.3013 | AC7: 5402.6425 | AD7: 5413.9836 | AE7: 5425.3248
F8: =(G7-F7)/F7 -> 0.17256781 | G8: =(H7-G7)/G7 -> 0.14717086 | H8: =(I7-H7)/H7 -> 0.14764277 | I8: =(J7-I7)/I7 -> 0.12864871 | J8: =(K7-J7)/J7 -> 0.13140889 | K8: =(L7-K7)/K7 -> 0.11614624 | L8: =(M7-L7)/L7 -> 0.048847536 | M8: =(N7-M7)/M7 -> 0.046572581 | ... Q8: =(R7-Q7)/Q7 -> 0.47736312
Q9: =AVERAGE(F8:Q8) -> 0.21447424
E14: Reducción establecida por los proponentes de la iniciativa | F14: 0 | G14: 0 | H14: 0 | I14: 0 | J14: 0 | K14: 0 | L14: 0 | M14: 0 | N14: 0 | O14: 0 | P14: 0 | Q14: 0 | R14: 0 | S14: 0 | T14: 0 | U14: 0 | V14: 79.25 | W14: 158.5 | X14: 237.75 | Y14: 317 | Z14: 370.13667 | AA14: 423.27333 | AB14: 476.41 | AC14: 529.54667 | AD14: 582.68333 | AE14: 635.82
C18: MtCO2e
E19: Redondeo Tendencial | F19: =ROUND(F7/1000,4) -> 0.2149 | G19: =ROUND(G7/1000,4) -> 0.252 | H19: =ROUND(H7/1000,4) -> 0.2891 | I19: =ROUND(I7/1000,4) -> 0.3318 | J19: =ROUND(J7/1000,4) -> 0.3745 | K19: =ROUND(K7/1000,4) -> 0.4237 | L19: =ROUND(L7/1000,4) -> 0.4729 | M19: =ROUND(M7/1000,4) -> 0.496 | ... AE19: =ROUND(AE7/1000,4) -> 5.4253
E20: Redondeo Enmienda de Kigali | F20: =ROUND((F7-F14)/1000,4) -> 0.2149 | G20: =ROUND((G7-G14)/1000,4) -> 0.252 | H20: =ROUND((H7-H14)/1000,4) -> 0.2891 | I20: =ROUND((I7-I14)/1000,4) -> 0.3318 | J20: =ROUND((J7-J14)/1000,4) -> 0.3745 | K20: =ROUND((K7-K14)/1000,4) -> 0.4237 | L20: =ROUND((L7-L14)/1000,4) -> 0.4729 | M20: =ROUND((M7-M14)/1000,4) -> 0.496 | ... AE20: =ROUND((AE7-AE14)/1000,4) -> 4.7895

Sheet Act_5CN_OtrosPIUP
B1: 5ta CN
B3: GgCO2e | D3: CATEGORÍA | E3: 2010 | F3: 2011 | G3: 2012 | H3: 2013 | I3: 2014 | J3: 2015 | K3: 2016 | L3: 2017 | M3: 2018 | N3: 2019 | O3: 2020 | P3: 2021 | Q3: 2022 | R3: 2023 | S3: 2024 | T3: 2025 | U3: 2026 | V3: 2027 | W3: 2028 | X3: 2029 | Y3: 2030 | Z3: 2031 | AA3: 2032 | AB3: 2033 | AC3: 2034 | AD3: 2035
D4: 2A1 Producción de Cemento | E4: 1781.9688 | G4: 1787.6358 | I4: 1884.82 | K4: 1750.74 | M4: 2029.03 | O4: 1347.8304 | P4: 1964.888 | Q4: 1797.8712
D5: 2A2 Producción de Cal | E5: 66.49798 | F5: 69.184432 | G5: 71.870884 | H5: 74.235442 | I5: 76.6 | J5: 85.19 | K5: 93.78 | L5: 100.455 | M5: 107.13 | N5: 114.35282 | O5: 121.57564 | P5: 219.89981 | Q5: 179.05715
D6: 2A3 Producción de Vidrio | E6: 7.5096794 | F6: 9.1974452 | G6: 10.885211 | H6: 12.592605 | I6: 14.3 | J6: 12.51 | K6: 10.72 | L6: 12.42 | M6: 14.12 | N6: 9.4119149 | O6: 4.7038299 | P6: 8.9208317 | Q6: 8.1065266
D7: 2A4a Cerámica | E7: 318.06379 | F7: 409.63545 | G7: 501.20712 | H7: 440.06356 | I7: 378.92 | J7: 383.04 | K7: 387.16 | L7: 296.03 | M7: 204.9 | N7: 152.17844 | O7: 99.456879 | P7: 44.588128 | Q7: 211.67639
D8: 2A4b Otros Usos de la Soda Ash | E8: -1.110223e-16 | F8: 0.8999511 | G8: 1.7999022 | H8: 1.7999511 | I8: 1.8 | J8: 0.9 | K8: 0 | L8: 1.53 | M8: 3.06 | N8: 5.767578 | O8: 8.4751559 | P8: 1.22349 | Q8: 1.6787663
D9: 2C1 Producción de Hierro y Acero | E9: 29.76 | F9: 31.68 | G9: 33.6 | H9: 35.72 | I9: 37.84 | J9: 40.36 | K9: 42.88 | L9: 49.64 | M9: 56.4 | N9: 45.895758 | O9: 35.391517 | P9: 77.936107 | Q9: 80.062922
D10: 2C5 Producción de Plomo | E10: 1.2835778 | F10: 1.5765538 | G10: 1.8695298 | H10: 2.3047649 | I10: 2.74 | J10: 2.88 | K10: 3.02 | L10: 3.51 | M10: 4 | N10: 6.992284 | O10: 9.984568 | P10: 8.703916 | Q10: 6.604146
D11: 2D1 Uso de Lubricantes | E11: -1.3877788e-17 | F11: 0.11938667 | G11: 0.23877333 | H11: 2.8343867 | I11: 5.43 | J11: 5.56 | K11: 5.69 | L11: 5.315 | M11: 4.94 | N11: 4.2985667 | O11: 3.6571333 | P11: 3.5550533 | Q11: 3.01708
D12: 2D2 Uso de Cera de Parafina | E12: 0.28673333 | F12: 0.16529333 | G12: 0.04385333 | H12: 0.26192666 | I12: 0.48 | J12: 0.435 | K12: 0.39 | L12: 0.66 | M12: 0.93 | N12: 0.60345333 | O12: 0.27690667 | P12: 0.59326667 | Q12: 0.12702194
D13: 2F1 Refrigeración y Aire Acondicionado | E13: 214.93 | F13: 252.02 | G13: 289.11 | H13: 331.795 | I13: 374.48 | J13: 423.69 | K13: 472.9 | L13: 496 | M13: 519.1 | N13: 861.05 | O13: 1203 | P13: 1325.05 | Q13: 1957.58 | R13: 2383.9599 | S13: 2810.3397 | T13: 3236.7196 | U13: 3663.0995 | V13: 4089.4794 | W13: 4515.8593 | X13: 4942.2391 | Y13: 5368.619 | Z13: 5379.9602 | AA13: 5391.3013 | AB13: 5402.6425 | AC13: 5413.9836 | AD13: 5425.3248
D15: Otros PI y UP | E15: =SUM(E5:E12) -> 423.40176 | F15: =SUM(F5:F12) -> 522.45851 | G15: =SUM(G5:G12) -> 621.51527 | H15: =SUM(H5:H12) -> 569.81263 | I15: =SUM(I5:I12) -> 518.11 | J15: =SUM(J5:J12) -> 530.875 | K15: =SUM(K5:K12) -> 543.64 | L15: =SUM(L5:L12) -> 469.56 | ... Q15: =SUM(Q5:Q12) -> 490.33
F18: Interpolado | H18: Interpolado | J18: Interpolado | L18: Interpolado
B19: MtCO2e | D19: CATEGORÍA | E19: 2010 | F19: 2011 | G19: 2012 | H19: 2013 | I19: 2014 | J19: 2015 | K19: 2016 | L19: 2017 | M19: 2018 | N19: 2019 | O19: 2020 | P19: 2021 | Q19: 2022 | R19: 2023 | S19: 2024 | T19: 2025 | U19: 2026 | V19: 2027 | W19: 2028 | X19: 2029 | Y19: 2030 | Z19: 2031 | AA19: 2032 | AB19: 2033 | AC19: 2034 | AD19: 2035
D20: 2A1 Producción de Cemento | E20: =E4/1000 -> 1.7819688 | G20: =G4/1000 -> 1.7876358 | I20: =I4/1000 -> 1.88482 | K20: =K4/1000 -> 1.75074 | M20: =M4/1000 -> 2.02903 | N20: =N4/1000 -> 0 | O20: =O4/1000 -> 1.3478304 | P20: =P4/1000 -> 1.964888 | Q20: =Q4/1000 -> 1.7978712
D21: 2A2 Producción de Cal | E21: =E5/1000 -> 0.06649798 | F21: =F5/1000 -> 0.069184432 | G21: =G5/1000 -> 0.071870884 | H21: =H5/1000 -> 0.074235442 | I21: =I5/1000 -> 0.0766 | J21: =J5/1000 -> 0.08519 | K21: =K5/1000 -> 0.09378 | L21: =L5/1000 -> 0.100455 | ... Q21: =Q5/1000 -> 0.17905715
D22: 2A3 Producción de Vidrio | E22: =E6/1000 -> 0.0075096794 | F22: =F6/1000 -> 0.0091974452 | G22: =G6/1000 -> 0.010885211 | H22: =H6/1000 -> 0.012592605 | I22: =I6/1000 -> 0.0143 | J22: =J6/1000 -> 0.01251 | K22: =K6/1000 -> 0.01072 | L22: =L6/1000 -> 0.01242 | ... Q22: =Q6/1000 -> 0.0081065266
D23: 2A4a Cerámica | E23: =E7/1000 -> 0.31806379 | F23: =F7/1000 -> 0.40963545 | G23: =G7/1000 -> 0.50120712 | H23: =H7/1000 -> 0.44006356 | I23: =I7/1000 -> 0.37892 | J23: =J7/1000 -> 0.38304 | K23: =K7/1000 -> 0.38716 | L23: =L7/1000 -> 0.29603 | ... Q23: =Q7/1000 -> 0.21167639
D24: 2A4b Otros Usos de la Soda Ash | E24: =E8/1000 -> -1.110223e-19 | F24: =F8/1000 -> 0.0008999511 | G24: =G8/1000 -> 0.0017999022 | H24: =H8/1000 -> 0.0017999511 | I24: =I8/1000 -> 0.0018 | J24: =J8/1000 -> 0.0009 | K24: =K8/1000 -> 0 | L24: =L8/1000 -> 0.00153 | ... Q24: =Q8/1000 -> 0.0016787663
D25: 2C1 Producción de Hierro y Acero | E25: =E9/1000 -> 0.02976 | F25: =F9/1000 -> 0.03168 | G25: =G9/1000 -> 0.0336 | H25: =H9/1000 -> 0.03572 | I25: =I9/1000 -> 0.03784 | J25: =J9/1000 -> 0.04036 | K25: =K9/1000 -> 0.04288 | L25: =L9/1000 -> 0.04964 | ... Q25: =Q9/1000 -> 0.080062922
D26: 2C5 Producción de Plomo | E26: =E10/1000 -> 0.0012835778 | F26: =F10/1000 -> 0.0015765538 | G26: =G10/1000 -> 0.0018695298 | H26: =H10/1000 -> 0.0023047649 | I26: =I10/1000 -> 0.00274 | J26: =J10/1000 -> 0.00288 | K26: =K10/1000 -> 0.00302 | L26: =L10/1000 -> 0.00351 | ... Q26: =Q10/1000 -> 0.006604146
D27: 2D1 Uso de Lubricantes | E27: =E11/1000 -> -1.3877788e-20 | F27: =F11/1000 -> 0.00011938666 | G27: =G11/1000 -> 0.00023877333 | H27: =H11/1000 -> 0.0028343867 | I27: =I11/1000 -> 0.00543 | J27: =J11/1000 -> 0.00556 | K27: =K11/1000 -> 0.00569 | L27: =L11/1000 -> 0.005315 | ... Q27: =Q11/1000 -> 0.00301708
D28: 2D2 Uso de Cera de Parafina | E28: =E12/1000 -> 0.00028673333 | F28: =F12/1000 -> 0.00016529333 | G28: =G12/1000 -> 4.385333e-05 | H28: =H12/1000 -> 0.00026192666 | I28: =I12/1000 -> 0.00048 | J28: =J12/1000 -> 0.000435 | K28: =K12/1000 -> 0.00039 | L28: =L12/1000 -> 0.00066 | ... Q28: =Q12/1000 -> 0.00012702194
D29: 2F1 Refrigeración y Aire Acondicionado | E29: =E13/1000 -> 0.21493 | F29: =F13/1000 -> 0.25202 | G29: =G13/1000 -> 0.28911 | H29: =H13/1000 -> 0.331795 | I29: =I13/1000 -> 0.37448 | J29: =J13/1000 -> 0.42369 | K29: =K13/1000 -> 0.4729 | L29: =L13/1000 -> 0.496 | ... AD29: =AD13/1000 -> 5.4253248
D31: Otros PI y UP | E31: =SUM(E21:E28) -> 0.42340176 | F31: =SUM(F21:F28) -> 0.52245851 | G31: =SUM(G21:G28) -> 0.62151527 | H31: =SUM(H21:H28) -> 0.56981263 | I31: =SUM(I21:I28) -> 0.51811 | J31: =SUM(J21:J28) -> 0.530875 | K31: =SUM(K21:K28) -> 0.54364 | L31: =SUM(L21:L28) -> 0.46956 | ... Q31: =SUM(Q21:Q28) -> 0.49033
F34: Interpolado | H34: Interpolado | J34: Interpolado | L34: Interpolado
B35: MtCO2e | D35: CATEGORÍA | E35: 2010 | F35: 2011 | G35: 2012 | H35: 2013 | I35: 2014 | J35: 2015 | K35: 2016 | L35: 2017 | M35: 2018 | N35: 2019 | O35: 2020 | P35: 2021 | Q35: 2022 | R35: 2023 | S35: 2024 | T35: 2025 | U35: 2026 | V35: 2027 | W35: 2028 | X35: 2029 | Y35: 2030 | Z35: 2031 | AA35: 2032 | AB35: 2033 | AC35: 2034 | AD35: 2035
B36: ROUND 4 | D36: 2A1 Producción de Cemento | E36: =ROUND(E20,4) -> 1.782 | G36: =ROUND(G20,4) -> 1.7876 | I36: =ROUND(I20,4) -> 1.8848 | K36: =ROUND(K20,4) -> 1.7507 | M36: =ROUND(M20,4) -> 2.029 | N36: =ROUND(N20,4) -> 0 | O36: =ROUND(O20,4) -> 1.3478 | P36: =ROUND(P20,4) -> 1.9649 | Q36: =ROUND(Q20,4) -> 1.7979
D37: 2A2 Producción de Cal | E37: =ROUND(E21,4) -> 0.0665 | F37: =ROUND(F21,4) -> 0.0692 | G37: =ROUND(G21,4) -> 0.0719 | H37: =ROUND(H21,4) -> 0.0742 | I37: =ROUND(I21,4) -> 0.0766 | J37: =ROUND(J21,4) -> 0.0852 | K37: =ROUND(K21,4) -> 0.0938 | L37: =ROUND(L21,4) -> 0.1005 | ... Q37: =ROUND(Q21,4) -> 0.1791 | R37: =ROUND(R47*$Q$37/SUM($Q$37:$Q$44),4) -> 0.1829 | S37: =ROUND(S47*$Q$37/SUM($Q$37:$Q$44),4) -> 0.1868 | T37: =ROUND(T47*$Q$37/SUM($Q$37:$Q$44),4) -> 0.1908 | U37: =ROUND(U47*$Q$37/SUM($Q$37:$Q$44),4) -> 0.1949 | V37: =ROUND(V47*$Q$37/SUM($Q$37:$Q$44),4) -> 0.1991 | W37: =ROUND(W47*$Q$37/SUM($Q$37:$Q$44),4) -> 0.2034 | X37: =ROUND(X47*$Q$37/SUM($Q$37:$Q$44),4) -> 0.2077 | Y37: =ROUND(Y47*$Q$37/SUM($Q$37:$Q$44),4) -> 0.2121 | ... AD37: =ROUND(AD47*$Q$37/SUM($Q$37:$Q$44),4) -> 0.2358
D38: 2A3 Producción de Vidrio | E38: =ROUND(E22,4) -> 0.0075 | F38: =ROUND(F22,4) -> 0.0092 | G38: =ROUND(G22,4) -> 0.0109 | H38: =ROUND(H22,4) -> 0.0126 | I38: =ROUND(I22,4) -> 0.0143 | J38: =ROUND(J22,4) -> 0.0125 | K38: =ROUND(K22,4) -> 0.0107 | L38: =ROUND(L22,4) -> 0.0124 | ... Q38: =ROUND(Q22,4) -> 0.0081 | R38: =ROUND(R47*$Q$38/SUM($Q$37:$Q$44),4) -> 0.0083 | S38: =ROUND(S47*$Q$38/SUM($Q$37:$Q$44),4) -> 0.0084 | T38: =ROUND(T47*$Q$38/SUM($Q$37:$Q$44),4) -> 0.0086 | U38: =ROUND(U47*$Q$38/SUM($Q$37:$Q$44),4) -> 0.0088 | V38: =ROUND(V47*$Q$38/SUM($Q$37:$Q$44),4) -> 0.009 | W38: =ROUND(W47*$Q$38/SUM($Q$37:$Q$44),4) -> 0.0092 | X38: =ROUND(X47*$Q$38/SUM($Q$37:$Q$44),4) -> 0.0094 | Y38: =ROUND(Y47*$Q$38/SUM($Q$37:$Q$44),4) -> 0.0096 | ... AD38: =ROUND(AD47*$Q$38/SUM($Q$37:$Q$44),4) -> 0.0107
D39: 2A4a Cerámica | E39: =ROUND(E23,4) -> 0.3181 | F39: =ROUND(F23,4) -> 0.4096 | G39: =ROUND(G23,4) -> 0.5012 | H39: =ROUND(H23,4) -> 0.4401 | I39: =ROUND(I23,4) -> 0.3789 | J39: =ROUND(J23,4) -> 0.383 | K39: =ROUND(K23,4) -> 0.3872 | L39: =ROUND(L23,4) -> 0.296 | ... Q39: =ROUND(Q23,4) -> 0.2117 | R39: =ROUND(R47*$Q$39/SUM($Q$37:$Q$44),4) -> 0.2162 | S39: =ROUND(S47*$Q$39/SUM($Q$37:$Q$44),4) -> 0.2208 | T39: =ROUND(T47*$Q$39/SUM($Q$37:$Q$44),4) -> 0.2256 | U39: =ROUND(U47*$Q$39/SUM($Q$37:$Q$44),4) -> 0.2304 | V39: =ROUND(V47*$Q$39/SUM($Q$37:$Q$44),4) -> 0.2353 | W39: =ROUND(W47*$Q$39/SUM($Q$37:$Q$44),4) -> 0.2404 | X39: =ROUND(X47*$Q$39/SUM($Q$37:$Q$44),4) -> 0.2455 | Y39: =ROUND(Y47*$Q$39/SUM($Q$37:$Q$44),4) -> 0.2507 | ... AD39: =ROUND(AD47*$Q$39/SUM($Q$37:$Q$44),4) -> 0.2787
D40: 2A4b Otros Usos de la Soda Ash | E40: =ROUND(E24,4) -> 0 | F40: =ROUND(F24,4) -> 0.0009 | G40: =ROUND(G24,4) -> 0.0018 | H40: =ROUND(H24,4) -> 0.0018 | I40: =ROUND(I24,4) -> 0.0018 | J40: =ROUND(J24,4) -> 0.0009 | K40: =ROUND(K24,4) -> 0 | L40: =ROUND(L24,4) -> 0.0015 | ... Q40: =ROUND(Q24,4) -> 0.0017 | R40: =ROUND(R47*$Q$40/SUM($Q$37:$Q$44),4) -> 0.0017 | S40: =ROUND(S47*$Q$40/SUM($Q$37:$Q$44),4) -> 0.0018 | T40: =ROUND(T47*$Q$40/SUM($Q$37:$Q$44),4) -> 0.0018 | U40: =ROUND(U47*$Q$40/SUM($Q$37:$Q$44),4) -> 0.0019 | V40: =ROUND(V47*$Q$40/SUM($Q$37:$Q$44),4) -> 0.0019 | W40: =ROUND(W47*$Q$40/SUM($Q$37:$Q$44),4) -> 0.0019 | X40: =ROUND(X47*$Q$40/SUM($Q$37:$Q$44),4) -> 0.002 | Y40: =ROUND(Y47*$Q$40/SUM($Q$37:$Q$44),4) -> 0.002 | ... AD40: =ROUND(AD47*$Q$40/SUM($Q$37:$Q$44),4) -> 0.0022
D41: 2C1 Producción de Hierro y Acero | E41: =ROUND(E25,4) -> 0.0298 | F41: =ROUND(F25,4) -> 0.0317 | G41: =ROUND(G25,4) -> 0.0336 | H41: =ROUND(H25,4) -> 0.0357 | I41: =ROUND(I25,4) -> 0.0378 | J41: =ROUND(J25,4) -> 0.0404 | K41: =ROUND(K25,4) -> 0.0429 | L41: =ROUND(L25,4) -> 0.0496 | ... Q41: =ROUND(Q25,4) -> 0.0801 | R41: =ROUND(R47*$Q$41/SUM($Q$37:$Q$44),4) -> 0.0818 | S41: =ROUND(S47*$Q$41/SUM($Q$37:$Q$44),4) -> 0.0836 | T41: =ROUND(T47*$Q$41/SUM($Q$37:$Q$44),4) -> 0.0853 | U41: =ROUND(U47*$Q$41/SUM($Q$37:$Q$44),4) -> 0.0872 | V41: =ROUND(V47*$Q$41/SUM($Q$37:$Q$44),4) -> 0.089 | W41: =ROUND(W47*$Q$41/SUM($Q$37:$Q$44),4) -> 0.0909 | X41: =ROUND(X47*$Q$41/SUM($Q$37:$Q$44),4) -> 0.0929 | Y41: =ROUND(Y47*$Q$41/SUM($Q$37:$Q$44),4) -> 0.0949 | ... AD41: =ROUND(AD47*$Q$41/SUM($Q$37:$Q$44),4) -> 0.1055
D42: 2C5 Producción de Plomo | E42: =ROUND(E26,4) -> 0.0013 | F42: =ROUND(F26,4) -> 0.0016 | G42: =ROUND(G26,4) -> 0.0019 | H42: =ROUND(H26,4) -> 0.0023 | I42: =ROUND(I26,4) -> 0.0027 | J42: =ROUND(J26,4) -> 0.0029 | K42: =ROUND(K26,4) -> 0.003 | L42: =ROUND(L26,4) -> 0.0035 | ... Q42: =ROUND(Q26,4) -> 0.0066 | R42: =ROUND(R47*$Q$42/SUM($Q$37:$Q$44),4) -> 0.0067 | S42: =ROUND(S47*$Q$42/SUM($Q$37:$Q$44),4) -> 0.0069 | T42: =ROUND(T47*$Q$42/SUM($Q$37:$Q$44),4) -> 0.007 | U42: =ROUND(U47*$Q$42/SUM($Q$37:$Q$44),4) -> 0.0072 | V42: =ROUND(V47*$Q$42/SUM($Q$37:$Q$44),4) -> 0.0073 | W42: =ROUND(W47*$Q$42/SUM($Q$37:$Q$44),4) -> 0.0075 | X42: =ROUND(X47*$Q$42/SUM($Q$37:$Q$44),4) -> 0.0077 | Y42: =ROUND(Y47*$Q$42/SUM($Q$37:$Q$44),4) -> 0.0078 | ... AD42: =ROUND(AD47*$Q$42/SUM($Q$37:$Q$44),4) -> 0.0087
D43: 2D1 Uso de Lubricantes | E43: =ROUND(E27,4) -> 0 | F43: =ROUND(F27,4) -> 0.0001 | G43: =ROUND(G27,4) -> 0.0002 | H43: =ROUND(H27,4) -> 0.0028 | I43: =ROUND(I27,4) -> 0.0054 | J43: =ROUND(J27,4) -> 0.0056 | K43: =ROUND(K27,4) -> 0.0057 | L43: =ROUND(L27,4) -> 0.0053 | ... Q43: =ROUND(Q27,4) -> 0.003 | R43: =ROUND(R47*$Q$43/SUM($Q$37:$Q$44),4) -> 0.0031 | S43: =ROUND(S47*$Q$43/SUM($Q$37:$Q$44),4) -> 0.0031 | T43: =ROUND(T47*$Q$43/SUM($Q$37:$Q$44),4) -> 0.0032 | U43: =ROUND(U47*$Q$43/SUM($Q$37:$Q$44),4) -> 0.0033 | V43: =ROUND(V47*$Q$43/SUM($Q$37:$Q$44),4) -> 0.0033 | W43: =ROUND(W47*$Q$43/SUM($Q$37:$Q$44),4) -> 0.0034 | X43: =ROUND(X47*$Q$43/SUM($Q$37:$Q$44),4) -> 0.0035 | Y43: =ROUND(Y47*$Q$43/SUM($Q$37:$Q$44),4) -> 0.0036 | ... AD43: =ROUND(AD47*$Q$43/SUM($Q$37:$Q$44),4) -> 0.0039
D44: 2D2 Uso de Cera de Parafina | E44: =ROUND(E28,4) -> 0.0003 | F44: =ROUND(F28,4) -> 0.0002 | G44: =ROUND(G28,4) -> 0 | H44: =ROUND(H28,4) -> 0.0003 | I44: =ROUND(I28,4) -> 0.0005 | J44: =ROUND(J28,4) -> 0.0004 | K44: =ROUND(K28,4) -> 0.0004 | L44: =ROUND(L28,4) -> 0.0007 | ... Q44: =ROUND(Q28,4) -> 0.0001 | R44: =ROUND(R47*$Q$44/SUM($Q$37:$Q$44),4) -> 0.0001 | S44: =ROUND(S47*$Q$44/SUM($Q$37:$Q$44),4) -> 0.0001 | T44: =ROUND(T47*$Q$44/SUM($Q$37:$Q$44),4) -> 0.0001 | U44: =ROUND(U47*$Q$44/SUM($Q$37:$Q$44),4) -> 0.0001 | V44: =ROUND(V47*$Q$44/SUM($Q$37:$Q$44),4) -> 0.0001 | W44: =ROUND(W47*$Q$44/SUM($Q$37:$Q$44),4) -> 0.0001 | X44: =ROUND(X47*$Q$44/SUM($Q$37:$Q$44),4) -> 0.0001 | Y44: =ROUND(Y47*$Q$44/SUM($Q$37:$Q$44),4) -> 0.0001 | ... AD44: =ROUND(AD47*$Q$44/SUM($Q$37:$Q$44),4) -> 0.0001
D45: 2F1 Refrigeración y Aire Acondicionado | E45: 0.171 | F45: =ROUND(F29,4) -> 0.252 | G45: 0.2507 | H45: =ROUND(H29,4) -> 0.3318 | I45: 0.3676 | J45: =ROUND(J29,4) -> 0.4237 | K45: 0.4803 | L45: =ROUND(L29,4) -> 0.496 | M45: 0.5589 | N45: =ROUND(N29,4) -> 0.8611 | O45: =ROUND(O29,4) -> 1.203 | P45: =ROUND(P29,4) -> 1.3251 | Q45: =ROUND(Q29,4) -> 1.9576 | R45: 1.5229 | S45: 1.5229 | T45: 1.5229 | U45: 1.5229 | V45: 1.5229 | W45: 1.5229 | X45: 1.5229 | Y45: 1.5229 | Z45: 1.5229 | AA45: 1.5229 | AB45: 1.5229 | AC45: 1.5229 | AD45: 1.5229
D47: Otros PI y UP | E47: =SUM(E37:E44) -> 0.4235 | F47: =SUM(F37:F44) -> 0.5225 | G47: =SUM(G37:G44) -> 0.6215 | H47: =SUM(H37:H44) -> 0.5698 | I47: =SUM(I37:I44) -> 0.518 | J47: =SUM(J37:J44) -> 0.5309 | K47: =SUM(K37:K44) -> 0.5437 | L47: =SUM(L37:L44) -> 0.4695 | ... Q47: =SUM(Q37:Q44) -> 0.4904 | R47: =$Q$31*R55 -> 0.5008921 | S47: =$Q$31*S55 -> 0.51157846 | T47: =$Q$31*T55 -> 0.52251334 | U47: =$Q$31*U55 -> 0.53369674 | V47: =$Q$31*V55 -> 0.54512867 | W47: =$Q$31*W55 -> 0.55680911 | X47: =$Q$31*X55 -> 0.56861381 | Y47: =$Q$31*Y55 -> 0.58079129 | ... AD47: =$Q$31*AD55 -> 0.64565501
E48: =(E37+E38+E39+E40+E41+E42+E43+E44)*1000 -> 423.5 | F48: =(F37+F38+F39+F40+F41+F42+F43+F44)*1000 -> 522.5 | G48: =(G37+G38+G39+G40+G41+G42+G43+G44)*1000 -> 621.5 | H48: =(H37+H38+H39+H40+H41+H42+H43+H44)*1000 -> 569.8 | I48: =(I37+I38+I39+I40+I41+I42+I43+I44)*1000 -> 518 | J48: =(J37+J38+J39+J40+J41+J42+J43+J44)*1000 -> 530.9 | K48: =(K37+K38+K39+K40+K41+K42+K43+K44)*1000 -> 543.7 | L48: =(L37+L38+L39+L40+L41+L42+L43+L44)*1000 -> 469.5 | ... AD48: =(AD37+AD38+AD39+AD40+AD41+AD42+AD43+AD44)*1000 -> 645.6
...

Sheet Otras_CementoMiscelanea
G6: Calculados usando interpolación de alguna variable
E7: CATEGORÍA | F7: 2010 | G7: 2011 | H7: 2012 | I7: 2013 | J7: 2014 | K7: 2015 | L7: 2016 | M7: 2017 | N7: 2018 | O7: 2019 | P7: 2020 | Q7: 2021 | R7: 2022 | S7: 2023 | T7: 2024 | U7: 2025 | V7: 2026 | W7: 2027 | X7: 2028 | Y7: 2029 | Z7: 2030 | AA7: 2031 | AB7: 2032 | AC7: 2033 | AD7: 2034 | AE7: 2035
B8: Emisiones cuarta | E8: 2A1 Producción de Cemento | F8: 1781.97 | H8: 1787.64 | J8: 1884.82 | L8: 1750.74 | N8: 2008.62
B9: Emisiones quinta | E9: 2A1 Producción de Cemento | F9: 1781.9688 | G9: 1784.8023 | H9: 1787.6358 | I9: 1836.2279 | J9: 1884.82 | K9: 1817.78 | L9: 1750.74 | M9: 1889.885 | N9: 2029.03 | O9: 1688.4302 | P9: 1347.8304 | Q9: 1964.888 | R9: 1797.8712
F11: 3.329 | G11: 3.3284 | H11: 3.3278 | I11: 3.434 | J11: 3.5399 | K11: 3.4108 | L11: 3.2819 | M11: 3.5381 | N11: 3.7941
B12: Como las emisiones de cemento no varían entre 2010 y 2018, los factores de emisión y actividad son los mismos | F12: =ROUND(F9/(F11*1000),4) -> 0.5353 | G12: =ROUND(G9/(G11*1000),4) -> 0.5362 | H12: =ROUND(H9/(H11*1000),4) -> 0.5372 | I12: =ROUND(I9/(I11*1000),4) -> 0.5347 | J12: =ROUND(J9/(J11*1000),4) -> 0.5325 | K12: =ROUND(K9/(K11*1000),4) -> 0.5329 | L12: =ROUND(L9/(L11*1000),4) -> 0.5335 | M12: =ROUND(M9/(M11*1000),4) -> 0.5342 | N12: =ROUND(N9/(N11*1000),4) -> 0.5348
B13: Además, se mantien el ultimo valor conocido del 2018 para el factor de emisión
O15: Se mantiene constante el valor del 2018
B16: Factor de emisión cuarta | E16: MtCO2e/Mt Clinker | F16: 0.5353 | G16: 0.5362 | H16: 0.5372 | I16: 0.5347 | J16: 0.5325 | K16: 0.5329 | L16: 0.5335 | M16: 0.53415 | N16: 0.5348 | O16: 0.5348 | P16: 0.5348 | Q16: 0.5348 | R16: 0.5348 | S16: 0.5348 | T16: 0.5348 | U16: 0.5348 | V16: 0.5348 | W16: 0.5348 | X16: 0.5348 | Y16: 0.5348 | Z16: 0.5348 | AA16: 0.5348 | AB16: 0.5348 | AC16: 0.5348 | AD16: 0.5348 | AE16: 0.5348
B17: Factor de emisión quinta | E17: MtCO2e/Mt Clinker | F17: 0.5353 | G17: 0.5362 | H17: 0.5372 | I17: 0.5347 | J17: 0.5325 | K17: 0.5329 | L17: 0.5335 | M17: 0.53415 | N17: 0.5348 | O17: 0.5348 | P17: 0.5348 | Q17: 0.5348 | R17: 0.5348 | S17: 0.5348 | T17: 0.5348 | U17: 0.5348 | V17: 0.5348 | W17: 0.5348 | X17: 0.5348 | Y17: 0.5348 | Z17: 0.5348 | AA17: 0.5348 | AB17: 0.5348 | AC17: 0.5348 | AD17: 0.5348 | AE17: 0.5348
B20: Clinker [Mt] | F20: =F9/(F16*1000) -> 3.3289161 | G20: =G9/(G16*1000) -> 3.328613 | H20: =H9/(H16*1000) -> 3.3276914 | I20: =I9/(I16*1000) -> 3.4341274 | J20: =J9/(J16*1000) -> 3.5395681 | K20: =K9/(K16*1000) -> 3.411109 | L20: =L9/(L16*1000) -> 3.281612 | M20: =M9/(M16*1000) -> 3.5381166 | N20: =N9/(N16*1000) -> 3.7939978
B22: Factor de Clinker [%] calculado 4CN | F22: 0.6311 | G22: 0.5872 | H22: 0.549 | I22: 0.5444 | J22: 0.5401 | K22: 0.5899 | L22: 0.6551 | M22: 0.703 | N22: 0.7504
B25: Cemento [Mt] | F25: =F20/F22 -> 5.2747838 | G25: =G20/G22 -> 5.6686189 | H25: =H20/H22 -> 6.0613687 | I25: =I20/I22 -> 6.3080959 | J25: =J20/J22 -> 6.5535421 | K25: =K20/K22 -> 5.7825208 | L25: =L20/L22 -> 5.0093299 | M25: =M20/M22 -> 5.0328828 | N25: =N20/N22 -> 5.0559672
B28: PlanMICC cemento [Mt] | F28: 5.2749 | G28: 5.6682 | H28: 6.0615 | I28: 6.3078 | J28: 6.5541 | K28: 5.7819 | L28: 5.0097 | M28: 5.0328 | N28: 5.0559 | O28: 4.8176 | P28: 3.8519 | Q28: 3.5964 | R28: 4.2395 | S28: 4.4563 | T28: 4.673 | U28: 4.8898 | V28: 5.1066 | W28: 5.3233 | X28: 5.5401 | Y28: 5.7569 | Z28: 5.9736 | AA28: 6.1904 | AB28: 6.4072 | AC28: 6.6239 | AD28: 6.8407 | AE28: 7.0575
B29: PlanMICC normalizado 2022 | R29: =R28/$R$28 -> 1 | S29: =S28/$R$28 -> 1.0511381 | T29: =T28/$R$28 -> 1.1022526 | U29: =U28/$R$28 -> 1.1533907 | V29: =V28/$R$28 -> 1.2045288 | W29: =W28/$R$28 -> 1.2556434 | X29: =X28/$R$28 -> 1.3067815 | Y29: =Y28/$R$28 -> 1.3579196 | ... AE29: =AE28/$R$28 -> 1.664701
