Workbook

Sheet CONTENIDO
B2: Hoja | C2: Contenido
B3: COBERTURA_BOSQUE | C3: Coberturas de bosque históricas y proyecciones en base a tasa de deforestación
B4: COBERTURA_HACIA_TF | C4: Cambios uso de suelo a tierras forestales
B5: COBERTURA_CAMBIOS_TF | C5: Cambio de tierras forestales a otros usos de suelo
B6: MEDIDAS_INCOND | C6: Medidas de mitigación de escenario incondicional
B7: MEDIDAS_COND | C7: Medidas de mitigación de escenario condicional
B8: FACTORES_EMISION | C8: Factores de emisión

Sheet COBERTURA_BOSQUE
A1: Referencia | B1: Ecuador | C1: 2010 | D1: 2011 | E1: 2012 | F1: 2013 | G1: 2014 | H1: 2015 | I1: 2016 | J1: 2017 | K1: 2018 | L1: 2019 | M1: 2020 | N1: 2021 | O1: 2022 | P1: 2023 | Q1: 2024 | R1: 2025 | S1: 2026 | T1: 2027 | U1: 2028 | V1: 2029 | W1: 2030 | X1: 2031 | Y1: 2032 | Z1: 2033 | AA1: 2034 | AB1: 2035
B3: DATOS PARA CALCULAR PROYECCIONES
B6: Cobertura bosque (Ha)
A7: Datos 2010-2022 5ta Comunicación | B7: B. Seco Andino | C7: 12348.32 | D7: =+(C7+E7)/2 -> 13402.625 | E7: 14456.93 | F7: =+(E7+G7)/2 -> 14584.46 | G7: 14711.99 | H7: =+(G7+I7)/2 -> 14755.53 | I7: 14799.07 | J7: =+(I7+K7)/2 -> 14779.865 | K7: 14760.66 | L7: 14760.66 | M7: 14760.66 | N7: 13635 | O7: 13635 | P7: =+$P35*P$24 -> 13628.319 | Q7: =+$P35*Q$24 -> 13621.641 | R7: =+$P35*R$24 -> 13614.966 | S7: =+$P35*S$24 -> 13608.295 | T7: =+$P35*T$24 -> 13601.627 | U7: =+$P35*U$24 -> 13594.962 | V7: =+$P35*V$24 -> 13588.301 | W7: =+$P35*W$24 -> 13581.642 | ... AB7: =+$P35*AB$24 -> 13548.4
B8: B. Seco Pluvioestacional | C8: 120583.64 | D8: =+(C8+E8)/2 -> 126215.03 | E8: 131846.42 | F8: =+(E8+G8)/2 -> 136010.5 | G8: 140174.58 | H8: =+(G8+I8)/2 -> 140004.62 | I8: 139834.67 | J8: =+(I8+K8)/2 -> 139853.84 | K8: 139873.01 | L8: 139873.01 | M8: 139873.01 | N8: 139386 | O8: 139386 | P8: =+$P36*P$24 -> 139317.7 | Q8: =+$P36*Q$24 -> 139249.44 | R8: =+$P36*R$24 -> 139181.2 | S8: =+$P36*S$24 -> 139113 | T8: =+$P36*T$24 -> 139044.84 | U8: =+$P36*U$24 -> 138976.71 | V8: =+$P36*V$24 -> 138908.61 | W8: =+$P36*W$24 -> 138840.54 | ... AB8: =+$P36*AB$24 -> 138500.72
B9: B. Siempre verde andino Montano | C9: 1153032.6 | D9: =+(C9+E9)/2 -> 1158742.6 | E9: 1164452.6 | F9: =+(E9+G9)/2 -> 1198650.2 | G9: 1232847.9 | H9: =+(G9+I9)/2 -> 1233796.5 | I9: 1234745.1 | J9: =+(I9+K9)/2 -> 1245530.5 | K9: 1256315.9 | L9: 1256315.9 | M9: 1256315.9 | N9: 1257518 | O9: 1257518 | P9: =+$P37*P$24 -> 1256901.8 | Q9: =+$P37*Q$24 -> 1256285.9 | R9: =+$P37*R$24 -> 1255670.4 | S9: =+$P37*S$24 -> 1255055.1 | T9: =+$P37*T$24 -> 1254440.1 | U9: =+$P37*U$24 -> 1253825.4 | V9: =+$P37*V$24 -> 1253211 | W9: =+$P37*W$24 -> 1252597 | ... AB9: =+$P37*AB$24 -> 1249531.1
B10: B. Siempre verde andino Pie montano | C10: 468700.3 | D10: =+(C10+E10)/2 -> 469707.92 | E10: 470715.55 | F10: =+(E10+G10)/2 -> 488975.63 | G10: 507235.71 | H10: =+(G10+I10)/2 -> 506690.36 | I10: 506145.02 | J10: =+(I10+K10)/2 -> 514642.34 | K10: 523139.65 | L10: 523139.65 | M10: 523139.65 | N10: 515144 | O10: 515144 | P10: =+$P38*P$24 -> 514891.58 | Q10: =+$P38*Q$24 -> 514639.28 | R10: =+$P38*R$24 -> 514387.11 | S10: =+$P38*S$24 -> 514135.06 | T10: =+$P38*T$24 -> 513883.13 | U10: =+$P38*U$24 -> 513631.33 | V10: =+$P38*V$24 -> 513379.65 | W10: =+$P38*W$24 -> 513128.1 | ... AB10: =+$P38*AB$24 -> 511872.16
B11: B. Siempre verde andino de Ceja Andina | C11: 322781.76 | D11: =+(C11+E11)/2 -> 325370.89 | E11: 327960.02 | F11: =+(E11+G11)/2 -> 333557.76 | G11: 339155.5 | H11: =+(G11+I11)/2 -> 340207.31 | I11: 341259.12 | J11: =+(I11+K11)/2 -> 357944.89 | K11: 374630.66 | L11: 374630.66 | M11: 374630.66 | N11: 375109 | O11: 375109 | P11: =+$P39*P$24 -> 374925.2 | Q11: =+$P39*Q$24 -> 374741.48 | R11: =+$P39*R$24 -> 374557.86 | S11: =+$P39*S$24 -> 374374.33 | T11: =+$P39*T$24 -> 374190.88 | U11: =+$P39*U$24 -> 374007.53 | V11: =+$P39*V$24 -> 373824.27 | W11: =+$P39*W$24 -> 373641.09 | ... AB11: =+$P39*AB$24 -> 372726.57
B12: B. Siempre verde de tierras bajas de la Amazonía | C12: 2361954.6 | D12: =+(C12+E12)/2 -> 2536303.8 | E12: 2710653 | F12: =+(E12+G12)/2 -> 2768583.4 | G12: 2826513.8 | H12: =+(G12+I12)/2 -> 2858758.2 | I12: 2891002.6 | J12: =+(I12+K12)/2 -> 2955726.3 | K12: 3020450 | L12: 3020450 | M12: 3020450 | N12: 2928882 | O12: 2928882 | P12: =+$P40*P$24 -> 2927446.8 | Q12: =+$P40*Q$24 -> 2926012.4 | R12: =+$P40*R$24 -> 2924578.7 | S12: =+$P40*S$24 -> 2923145.6 | T12: =+$P40*T$24 -> 2921713.3 | U12: =+$P40*U$24 -> 2920281.6 | V12: =+$P40*V$24 -> 2918850.7 | W12: =+$P40*W$24 -> 2917420.5 | ... AB12: =+$P40*AB$24 -> 2910279.8
B13: B. Siempre verde de tierras bajas del Chocó | C13: 261686.1 | D13: =+(C13+E13)/2 -> 263622.4 | E13: 265558.7 | F13: =+(E13+G13)/2 -> 269700.02 | G13: 273841.34 | H13: =+(G13+I13)/2 -> 268738.08 | I13: 263634.81 | J13: =+(I13+K13)/2 -> 262908.7 | K13: 262182.6 | L13: 262182.6 | M13: 262182.6 | N13: 240487 | O13: 240487 | P13: =+$P41*P$24 -> 240369.16 | Q13: =+$P41*Q$24 -> 240251.38 | R13: =+$P41*R$24 -> 240133.66 | S13: =+$P41*S$24 -> 240015.99 | T13: =+$P41*T$24 -> 239898.38 | U13: =+$P41*U$24 -> 239780.83 | V13: =+$P41*V$24 -> 239663.34 | W13: =+$P41*W$24 -> 239545.91 | ... AB13: =+$P41*AB$24 -> 238959.59
B14: Manglar | C14: 64990.3 | D14: =+(C14+E14)/2 -> 65335.185 | E14: 65680.07 | F14: =+(E14+G14)/2 -> 64106.675 | G14: 62533.28 | H14: =+(G14+I14)/2 -> 65738.85 | I14: 68944.42 | J14: =+(I14+K14)/2 -> 68628.94 | K14: 68313.46 | L14: 68313.46 | M14: 68313.46 | N14: 98087 | O14: 98087 | P14: =+$P42*P$24 -> 98038.937 | Q14: =+$P42*Q$24 -> 97990.898 | R14: =+$P42*R$24 -> 97942.883 | S14: =+$P42*S$24 -> 97894.891 | T14: =+$P42*T$24 -> 97846.922 | U14: =+$P42*U$24 -> 97798.977 | V14: =+$P42*V$24 -> 97751.056 | W14: =+$P42*W$24 -> 97703.158 | ... AB14: =+$P42*AB$24 -> 97464.019
B15: Moretal | C15: 271778.31 | D15: =+(C15+E15)/2 -> 272685.14 | E15: 273591.97 | F15: =+(E15+G15)/2 -> 278163.17 | G15: 282734.38 | H15: =+(G15+I15)/2 -> 289391.54 | I15: 296048.7 | J15: =+(I15+K15)/2 -> 298137.71 | K15: 300226.73 | L15: 300226.73 | M15: 300226.73 | N15: 272847 | O15: 272847 | P15: =+$P43*P$24 -> 272713.3 | Q15: =+$P43*Q$24 -> 272579.68 | R15: =+$P43*R$24 -> 272446.11 | S15: =+$P43*S$24 -> 272312.61 | T15: =+$P43*T$24 -> 272179.18 | U15: =+$P43*U$24 -> 272045.81 | V15: =+$P43*V$24 -> 271912.51 | W15: =+$P43*W$24 -> 271779.27 | ... AB15: =+$P43*AB$24 -> 271114.07
B16: Plantación forestal | C16: 38277.9 | D16: =+(C16+E16)/2 -> 38277.9 | E16: 38277.9 | F16: =+(E16+G16)/2 -> 38277.9 | G16: 38277.9 | H16: =+(G16+I16)/2 -> 72574.065 | I16: 106870.23 | J16: =+(I16+K16)/2 -> 101943.18 | K16: 97016.13 | L16: 97016.13 | M16: 97016.13 | N16: 115150 | O16: 115150 | P16: =+$P44*P$24 -> 115093.58 | Q16: =+$P44*Q$24 -> 115037.18 | R16: =+$P44*R$24 -> 114980.81 | S16: =+$P44*S$24 -> 114924.47 | T16: =+$P44*T$24 -> 114868.16 | U16: =+$P44*U$24 -> 114811.87 | V16: =+$P44*V$24 -> 114755.62 | W16: =+$P44*W$24 -> 114699.39 | ... AB16: =+$P44*AB$24 -> 114418.65
B17: Total bosque protegido | C17: =+SUM(C7:C16) -> 5076133.8 | D17: =+SUM(D7:D16) -> 5269663.5 | E17: =+SUM(E7:E16) -> 5463193.1 | F17: =+SUM(F7:F16) -> 5590609.7 | G17: =+SUM(G7:G16) -> 5718026.4 | H17: =+SUM(H7:H16) -> 5790655.1 | I17: =+SUM(I7:I16) -> 5863283.8 | J17: =+SUM(J7:J16) -> 5960096.3 | ... AB17: =+SUM(AB7:AB16) -> 5918415.1
B22: Datos para proyecciones
A23: Brindado en iniciativas | B23: Tasa de deforestación del bosque protegido [%] | P23: =0.049/100 -> 0.00049 | Q23: =0.049/100 -> 0.00049 | R23: =0.049/100 -> 0.00049 | S23: =0.049/100 -> 0.00049 | T23: =0.049/100 -> 0.00049 | U23: =0.049/100 -> 0.00049 | V23: =0.049/100 -> 0.00049 | W23: =0.049/100 -> 0.00049 | ... AB23: =0.049/100 -> 0.00049
B24: Total bosque protegido | C24: =+SUM(C7:C16) -> 5076133.8 | D24: =+SUM(D7:D16) -> 5269663.5 | E24: =+SUM(E7:E16) -> 5463193.1 | F24: =+SUM(F7:F16) -> 5590609.7 | G24: =+SUM(G7:G16) -> 5718026.4 | H24: =+SUM(H7:H16) -> 5790655.1 | I24: =+SUM(I7:I16) -> 5863283.8 | J24: =+SUM(J7:J16) -> 5960096.3 | ... O24: =+SUM(O7:O16) -> 5956245 | P24: =+O24-O24*P23 -> 5953326.4 | Q24: =+P24-P24*Q23 -> 5950409.3 | R24: =+Q24-Q24*R23 -> 5947493.6 | S24: =+R24-R24*S23 -> 5944579.3 | T24: =+S24-S24*T23 -> 5941666.5 | U24: =+T24-T24*U23 -> 5938755.1 | V24: =+U24-U24*V23 -> 5935845.1 | W24: =+V24-V24*W23 -> 5932936.5 | ... AB24: =+AA24-AA24*AB23 -> 5918415.1
B25: Tasa de deforestación del bosque sin proteger [%] | P25: =(((0.76/100)*O27-((0.049/100)*O24))/O26)*(0.992212) -> 0.014358672 | Q25: =(((0.76/100)*P27-((0.049/100)*P24))/P26)*(0.99221) -> 0.014454575 | R25: =(((0.76/100)*Q27-((0.049/100)*Q24))/Q26)*(0.992208) -> 0.014552509 | S25: =(((0.76/100)*R27-((0.049/100)*R24))/R26)*(0.992206) -> 0.014652538 | T25: =(((0.76/100)*S27-((0.049/100)*S24))/S26)*(0.992204) -> 0.014754727 | U25: =(((0.76/100)*T27-((0.049/100)*T24))/T26)*(0.992203) -> 0.014859159 | V25: =(((0.76/100)*U27-((0.049/100)*U24))/U26)*(0.9922) -> 0.014965859 | W25: =(((0.76/100)*V27-((0.049/100)*V24))/V26)*(0.992197) -> 0.015074932 | X25: =(((0.76/100)*W27-((0.049/100)*W24))/W26)*(0.992197) -> 0.0151865 | Y25: =(((0.76/100)*X27-((0.049/100)*X24))/X26)*(0.992195) -> 0.015300568 | Z25: =(((0.76/100)*Y27-((0.049/100)*Y24))/Y26)*(0.992193) -> 0.015417251 | AA25: =(((0.76/100)*Z27-((0.049/100)*Z24))/Z26)*(0.992191) -> 0.015536637 | AB25: =(((0.76/100)*AA27-((0.049/100)*AA24))/AA26)*(0.99219) -> 0.015658833
A26: INGEI | B26: Total bosque sin proteger | C26: 6163090.2 | D26: =+AVERAGE(C26,E26) -> 6163090.2 | E26: 6163090.2 | F26: =+AVERAGE(E26,G26) -> 6163090.2 | G26: 6163090.2 | H26: =+AVERAGE(G26,I26) -> 6163090.2 | I26: 6163090.2 | J26: =+AVERAGE(I26,K26) -> 6163090.2 | K26: 6163090.2 | L26: 6163090.2 | M26: 6163090.2 | N26: 6163090.2 | O26: 6163090.2 | P26: =+O26-O26*P25 -> 6074596.4 | Q26: =+P26-P26*Q25 -> 5986790.7 | R26: =+Q26-Q26*R25 -> 5899667.9 | S26: =+R26-R26*S25 -> 5813222.8 | T26: =+S26-S26*T25 -> 5727450.3 | U26: =+T26-T26*U25 -> 5642345.2 | V26: =+U26-U26*V25 -> 5557902.6 | W26: =+V26-V26*W25 -> 5474117.6 | ... AB26: =+AA26-AA26*AB25 -> 5064880.9
B27: Área de bosque total | C27: =+C24+C26 -> 11239224 | D27: =+D24+D26 -> 11432754 | E27: =+E24+E26 -> 11626283 | F27: =+F24+F26 -> 11753700 | G27: =+G24+G26 -> 11881117 | H27: =+H24+H26 -> 11953745 | I27: =+I24+I26 -> 12026374 | J27: =+J24+J26 -> 12123186 | ... AB27: =+AB24+AB26 -> 10983296
B28: Pérdida de área | P28: =+P27-O27 -> -91412.348 | Q28: =+Q27-P27 -> -90722.837 | R28: =+R27-Q27 -> -90038.528 | S28: =+S27-R27 -> -89359.382 | T28: =+T27-S27 -> -88685.359 | U28: =+U27-T27 -> -88016.508 | V28: =+V27-U27 -> -87352.532 | W28: =+W27-V27 -> -86693.567 | ... AB28: =+AB27-AA27 -> -83473.227
A29: PLANMICC | B29: Tasa de deforestación total [%] | P29: =P28/P27 -> -0.0076000112 | Q29: =Q28/Q27 -> -0.0076000098 | R29: =R28/R27 -> -0.0076000085 | S29: =S28/S27 -> -0.0076000073 | T29: =T28/T27 -> -0.0076000062 | U29: =U28/U27 -> -0.0076000127 | V29: =V28/V27 -> -0.0076000043 | W29: =W28/W27 -> -0.0075999961 | ... AB29: =AB28/AB27 -> -0.0076000162
B34: % por tipo de bosque | P34: FUTURE YEARS | R34: OPCION
B35: B. Seco Andino | C35: =+C7/C$24 -> 0.002432623 | D35: =+D7/D$24 -> 0.002543355 | E35: =+E7/E$24 -> 0.0026462418 | F35: =+F7/F$24 -> 0.0026087423 | G35: =+G7/G$24 -> 0.002572914 | H35: =+H7/H$24 -> 0.0025481625 | I35: =+I7/I$24 -> 0.0025240242 | J35: =+J7/J$24 -> 0.0024798031 | ... O35: =+O7/O$24 -> 0.0022891939 | P35: =IF(R35="CONSTANTE",O35,SUM(C7:O7)/SUM($C$17:$O$17)) -> 0.0022891939 | R35: CONSTANTE
B36: B. Seco Pluvioestacional | C36: =+C8/C$24 -> 0.023755016 | D36: =+D8/D$24 -> 0.023951251 | E36: =+E8/E$24 -> 0.024133582 | F36: =+F8/F$24 -> 0.024328384 | G36: =+G8/G$24 -> 0.024514504 | H36: =+H8/H$24 -> 0.024177683 | I36: =+I8/I$24 -> 0.023849207 | J36: =+J8/J$24 -> 0.02346503 | ... O36: =+O8/O$24 -> 0.023401657 | P36: =IF(R36="CONSTANTE",O36,SUM(C8:O8)/SUM($C$17:$O$17)) -> 0.023401657 | R36: CONSTANTE
B37: B. Siempre verde andino Montano | C37: =+C9/C$24 -> 0.22714779 | D37: =+D9/D$24 -> 0.21988929 | E37: =+E9/E$24 -> 0.21314505 | F37: =+F9/F$24 -> 0.21440421 | G37: =+G9/G$24 -> 0.21560725 | H37: =+H9/H$24 -> 0.21306683 | I37: =+I9/I$24 -> 0.21058935 | J37: =+J9/J$24 -> 0.20897825 | ... O37: =+O9/O$24 -> 0.21112597 | P37: =IF(R37="CONSTANTE",O37,SUM(C9:O9)/SUM($C$17:$O$17)) -> 0.21112597 | R37: CONSTANTE
B38: B. Siempre verde andino Pie montano | C38: =+C10/C$24 -> 0.092334111 | D38: =+D10/D$24 -> 0.089134331 | E38: =+E10/E$24 -> 0.086161251 | F38: =+F10/F$24 -> 0.087463739 | G38: =+G10/G$24 -> 0.08870818 | H38: =+H10/H$24 -> 0.087501389 | I38: =+I10/I$24 -> 0.086324496 | J38: =+J10/J$24 -> 0.08634799 | ... O38: =+O10/O$24 -> 0.086488047 | P38: =IF(R38="CONSTANTE",O38,SUM(C10:O10)/SUM($C$17:$O$17)) -> 0.086488047 | R38: CONSTANTE
B39: B. Siempre verde andino de Ceja Andina | C39: =+C11/C$24 -> 0.063588111 | D39: =+D11/D$24 -> 0.06174415 | E39: =+E11/E$24 -> 0.060030831 | F39: =+F11/F$24 -> 0.059663932 | G39: =+G11/G$24 -> 0.059313385 | H39: =+H11/H$24 -> 0.058751092 | I39: =+I11/I$24 -> 0.058202729 | J39: =+J11/J$24 -> 0.060056897 | ... O39: =+O11/O$24 -> 0.06297743 | P39: =IF(R39="CONSTANTE",O39,SUM(C11:O11)/SUM($C$17:$O$17)) -> 0.06297743 | R39: CONSTANTE
B40: B. Siempre verde de tierras bajas de la Amazonía | C40: =+C12/C$24 -> 0.46530582 | D40: =+D12/D$24 -> 0.4813028 | E40: =+E12/E$24 -> 0.49616642 | F40: =+F12/F$24 -> 0.49522029 | G40: =+G12/G$24 -> 0.49431632 | H40: =+H12/H$24 -> 0.49368477 | I40: =+I12/I$24 -> 0.49306886 | J40: =+J12/J$24 -> 0.49591922 | ... O40: =+O12/O$24 -> 0.49173296 | P40: =IF(R40="CONSTANTE",O40,SUM(C12:O12)/SUM($C$17:$O$17)) -> 0.49173296 | R40: CONSTANTE
B41: B. Siempre verde de tierras bajas del Chocó | C41: =+C13/C$24 -> 0.051552246 | D41: =+D13/D$24 -> 0.050026421 | E41: =+E13/E$24 -> 0.048608697 | F41: =+F13/F$24 -> 0.048241611 | G41: =+G13/G$24 -> 0.047890884 | H41: =+H13/H$24 -> 0.046408925 | I41: =+I13/I$24 -> 0.044963679 | J41: =+J13/J$24 -> 0.044111486 | ... O41: =+O13/O$24 -> 0.040375606 | P41: =IF(R41="CONSTANTE",O41,SUM(C13:O13)/SUM($C$17:$O$17)) -> 0.040375606 | R41: CONSTANTE
B42: Manglar | C42: =+C14/C$24 -> 0.01280311 | D42: =+D14/D$24 -> 0.01239836 | E42: =+E14/E$24 -> 0.012022286 | F42: =+F14/F$24 -> 0.011466849 | G42: =+G14/G$24 -> 0.010936165 | H42: =+H14/H$24 -> 0.011352576 | I42: =+I14/I$24 -> 0.01175867 | J42: =+J14/J$24 -> 0.011514737 | ... O42: =+O14/O$24 -> 0.016467926 | P42: =IF(R42="CONSTANTE",O42,SUM(C14:O14)/SUM($C$17:$O$17)) -> 0.016467926 | R42: CONSTANTE
B43: Moretal | C43: =+C15/C$24 -> 0.053540415 | D43: =+D15/D$24 -> 0.051746215 | E43: =+E15/E$24 -> 0.050079132 | F43: =+F15/F$24 -> 0.049755427 | G43: =+G15/G$24 -> 0.049446148 | H43: =+H15/H$24 -> 0.049975613 | I43: =+I15/I$24 -> 0.050491962 | J43: =+J15/J$24 -> 0.050022299 | ... O43: =+O15/O$24 -> 0.045808559 | P43: =IF(R43="CONSTANTE",O43,SUM(C15:O15)/SUM($C$17:$O$17)) -> 0.045808559 | R43: CONSTANTE
B44: Plantación forestal | C44: =+C16/C$24 -> 0.0075407587 | D44: =+D16/D$24 -> 0.0072638225 | E44: =+E16/E$24 -> 0.0070065069 | F44: =+F16/F$24 -> 0.0068468203 | G44: =+G16/G$24 -> 0.0066942503 | H44: =+H16/H$24 -> 0.012532963 | I44: =+I16/I$24 -> 0.018227027 | J44: =+J16/J$24 -> 0.017104284 | ... O44: =+O16/O$24 -> 0.01933265 | P44: =IF(R44="CONSTANTE",O44,SUM(C16:O16)/SUM($C$17:$O$17)) -> 0.01933265 | R44: CONSTANTE
B45: Total | C45: =+SUM(C35:C44) -> 1 | D45: =+SUM(D35:D44) -> 1 | E45: =+SUM(E35:E44) -> 1 | F45: =+SUM(F35:F44) -> 1 | G45: =+SUM(G35:G44) -> 1 | H45: =+SUM(H35:H44) -> 1 | I45: =+SUM(I35:I44) -> 1 | J45: =+SUM(J35:J44) -> 1 | ... P45: =+SUM(P35:P44) -> 1

Sheet COBERTURA_HACIA_TF
A1: Uso del suelo inicial | B1: Uso del suelo en el año del inventario | C1: 2010 | D1: 2011 | E1: 2012 | F1: 2013 | G1: 2014 | H1: 2015 | I1: 2016 | J1: 2017 | K1: 2018 | L1: 2019 | M1: 2020 | N1: 2021 | O1: 2022 | P1: 2023 | Q1: 2024 | R1: 2025 | S1: 2026 | T1: 2027 | U1: 2028 | V1: 2029 | W1: 2030 | X1: 2031 | Y1: 2032 | Z1: 2033 | AA1: 2034 | AB1: 2035 | AD1: OPCION
A2: Tierras de cultivo | B2: Tierras forestales | C2: 12650.5 | D2: =+(C2+E2)/2 -> 12650.5 | E2: 12650.5 | F2: =+(E2+G2)/2 -> 12650.5 | G2: 12650.5 | H2: =+(G2+I2)/2 -> 8941.5 | I2: 5232.5 | J2: =+(I2+K2)/2 -> 7404.86 | K2: 9577.22 | L2: 367.7 | M2: 367.7 | N2: 2315.79 | O2: 2315.79 | P2: =IF(AD2="CONSTANTE",O2,AVERAGE(C2:O2)) -> 2315.79 | Q2: =+P2 -> 2315.79 | R2: =+Q2 -> 2315.79 | S2: =+R2 -> 2315.79 | T2: =+S2 -> 2315.79 | U2: =+T2 -> 2315.79 | V2: =+U2 -> 2315.79 | W2: =+V2 -> 2315.79 | X2: =+W2 -> 2315.79 | ... AB2: =+AA2 -> 2315.79 | AD2: CONSTANTE
A3: Pastizales | B3: Tierras forestales | C3: 1811.66 | D3: =+(C3+E3)/2 -> 1811.66 | E3: 1811.66 | F3: =+(E3+G3)/2 -> 1811.66 | G3: 1811.66 | H3: =+(G3+I3)/2 -> 2469.83 | I3: 3128 | J3: =+(I3+K3)/2 -> 2948.515 | K3: 2769.03 | L3: 70.83 | M3: 70.83 | N3: 56.52 | O3: 56.52 | P3: =IF(AD3="CONSTANTE",O3,AVERAGE(C3:O3)) -> 56.52 | Q3: =+P3 -> 56.52 | R3: =+Q3 -> 56.52 | S3: =+R3 -> 56.52 | T3: =+S3 -> 56.52 | U3: =+T3 -> 56.52 | V3: =+U3 -> 56.52 | W3: =+V3 -> 56.52 | X3: =+W3 -> 56.52 | ... AB3: =+AA3 -> 56.52 | AD3: CONSTANTE
A4: Humedales | B4: Tierras forestales | C4: 37.16 | D4: =+(C4+E4)/2 -> 37.16 | E4: 37.16 | F4: =+(E4+G4)/2 -> 37.16 | G4: 37.16 | H4: =+(G4+I4)/2 -> 39.33 | I4: 41.5 | J4: =+(I4+K4)/2 -> 41.16 | K4: 40.82 | L4: 0.99 | M4: 0.99 | N4: 12.15 | O4: 12.15 | P4: =IF(AD4="CONSTANTE",O4,AVERAGE(C4:O4)) -> 12.15 | Q4: =+P4 -> 12.15 | R4: =+Q4 -> 12.15 | S4: =+R4 -> 12.15 | T4: =+S4 -> 12.15 | U4: =+T4 -> 12.15 | V4: =+U4 -> 12.15 | W4: =+V4 -> 12.15 | X4: =+W4 -> 12.15 | ... AB4: =+AA4 -> 12.15 | AD4: CONSTANTE
A5: Asentamientos | B5: Tierras forestales | C5: 0 | D5: =+(C5+E5)/2 -> 0 | E5: 0 | F5: =+(E5+G5)/2 -> 0 | G5: 0 | H5: =+(G5+I5)/2 -> 0 | I5: 0 | J5: =+(I5+K5)/2 -> 0 | K5: 0 | L5: 0 | M5: 0 | N5: 0 | O5: 0 | P5: =IF(AD5="CONSTANTE",O5,AVERAGE(C5:O5)) -> 0 | Q5: =+P5 -> 0 | R5: =+Q5 -> 0 | S5: =+R5 -> 0 | T5: =+S5 -> 0 | U5: =+T5 -> 0 | V5: =+U5 -> 0 | W5: =+V5 -> 0 | X5: =+W5 -> 0 | ... AB5: =+AA5 -> 0 | AD5: CONSTANTE
A6: Otras tierras | B6: Tierras forestales | C6: 7.83 | D6: =+(C6+E6)/2 -> 7.83 | E6: 7.83 | F6: =+(E6+G6)/2 -> 7.83 | G6: 7.83 | H6: =+(G6+I6)/2 -> 15.415 | I6: 23 | J6: =+(I6+K6)/2 -> 62.755 | K6: 102.51 | L6: 2.34 | M6: 2.34 | N6: 38.21 | O6: 38.21 | P6: =IF(AD6="CONSTANTE",O6,AVERAGE(C6:O6)) -> 38.21 | Q6: =+P6 -> 38.21 | R6: =+Q6 -> 38.21 | S6: =+R6 -> 38.21 | T6: =+S6 -> 38.21 | U6: =+T6 -> 38.21 | V6: =+U6 -> 38.21 | W6: =+V6 -> 38.21 | X6: =+W6 -> 38.21 | ... AB6: =+AA6 -> 38.21 | AD6: CONSTANTE
A8: Por tipo de bosque (hectáreas)
A9: Tieras de culvito a tierras forestales (hectáreas)
A10: Tierras de cultivo | B10: B. Seco Andino | C10: =+C$2*COBERTURA_BOSQUE!C35 -> 30.773898 | D10: =+D$2*COBERTURA_BOSQUE!D35 -> 32.174713 | E10: =+E$2*COBERTURA_BOSQUE!E35 -> 33.476282 | F10: =+F$2*COBERTURA_BOSQUE!F35 -> 33.001894 | G10: =+G$2*COBERTURA_BOSQUE!G35 -> 32.548648 | H10: =+H$2*COBERTURA_BOSQUE!H35 -> 22.784395 | I10: =+I$2*COBERTURA_BOSQUE!I35 -> 13.206956 | J10: =+J$2*COBERTURA_BOSQUE!J35 -> 18.362595 | ... N10: =+N$2*COBERTURA_BOSQUE!N35 -> 5.3012925 | O10: =+O$2*COBERTURA_BOSQUE!P35 -> 5.3012925 | P10: =+P$2*COBERTURA_BOSQUE!$P35 -> 5.3012925 | Q10: =+Q$2*COBERTURA_BOSQUE!$P35 -> 5.3012925 | R10: =+R$2*COBERTURA_BOSQUE!$P35 -> 5.3012925 | S10: =+S$2*COBERTURA_BOSQUE!$P35 -> 5.3012925 | T10: =+T$2*COBERTURA_BOSQUE!$P35 -> 5.3012925 | U10: =+U$2*COBERTURA_BOSQUE!$P35 -> 5.3012925 | V10: =+V$2*COBERTURA_BOSQUE!$P35 -> 5.3012925 | W10: =+W$2*COBERTURA_BOSQUE!$P35 -> 5.3012925 | ... AB10: =+AB$2*COBERTURA_BOSQUE!$P35 -> 5.3012925
A11: Tierras de cultivo | B11: B. Seco Pluvioestacional | C11: =+C$2*COBERTURA_BOSQUE!C36 -> 300.51283 | D11: =+D$2*COBERTURA_BOSQUE!D36 -> 302.9953 | E11: =+E$2*COBERTURA_BOSQUE!E36 -> 305.30188 | F11: =+F$2*COBERTURA_BOSQUE!F36 -> 307.76622 | G11: =+G$2*COBERTURA_BOSQUE!G36 -> 310.12073 | H11: =+H$2*COBERTURA_BOSQUE!H36 -> 216.18476 | I11: =+I$2*COBERTURA_BOSQUE!I36 -> 124.79098 | J11: =+J$2*COBERTURA_BOSQUE!J36 -> 173.75526 | ... N11: =+N$2*COBERTURA_BOSQUE!N36 -> 54.193322 | O11: =+O$2*COBERTURA_BOSQUE!P36 -> 54.193322 | P11: =+P$2*COBERTURA_BOSQUE!$P36 -> 54.193322 | Q11: =+Q$2*COBERTURA_BOSQUE!$P36 -> 54.193322 | R11: =+R$2*COBERTURA_BOSQUE!$P36 -> 54.193322 | S11: =+S$2*COBERTURA_BOSQUE!$P36 -> 54.193322 | T11: =+T$2*COBERTURA_BOSQUE!$P36 -> 54.193322 | U11: =+U$2*COBERTURA_BOSQUE!$P36 -> 54.193322 | V11: =+V$2*COBERTURA_BOSQUE!$P36 -> 54.193322 | W11: =+W$2*COBERTURA_BOSQUE!$P36 -> 54.193322 | ... AB11: =+AB$2*COBERTURA_BOSQUE!$P36 -> 54.193322
A12: Tierras de cultivo | B12: B. Siempre verde andino Montano | C12: =+C$2*COBERTURA_BOSQUE!C37 -> 2873.5331 | D12: =+D$2*COBERTURA_BOSQUE!D37 -> 2781.7095 | E12: =+E$2*COBERTURA_BOSQUE!E37 -> 2696.3915 | F12: =+F$2*COBERTURA_BOSQUE!F37 -> 2712.3204 | G12: =+G$2*COBERTURA_BOSQUE!G37 -> 2727.5395 | H12: =+H$2*COBERTURA_BOSQUE!H37 -> 1905.137 | I12: =+I$2*COBERTURA_BOSQUE!I37 -> 1101.9088 | J12: =+J$2*COBERTURA_BOSQUE!J37 -> 1547.4547 | ... N12: =+N$2*COBERTURA_BOSQUE!N37 -> 488.92341 | O12: =+O$2*COBERTURA_BOSQUE!P37 -> 488.92341 | P12: =+P$2*COBERTURA_BOSQUE!$P37 -> 488.92341 | Q12: =+Q$2*COBERTURA_BOSQUE!$P37 -> 488.92341 | R12: =+R$2*COBERTURA_BOSQUE!$P37 -> 488.92341 | S12: =+S$2*COBERTURA_BOSQUE!$P37 -> 488.92341 | T12: =+T$2*COBERTURA_BOSQUE!$P37 -> 488.92341 | U12: =+U$2*COBERTURA_BOSQUE!$P37 -> 488.92341 | V12: =+V$2*COBERTURA_BOSQUE!$P37 -> 488.92341 | W12: =+W$2*COBERTURA_BOSQUE!$P37 -> 488.92341 | ... AB12: =+AB$2*COBERTURA_BOSQUE!$P37 -> 488.92341
A13: Tierras de cultivo | B13: B. Siempre verde andino Pie montano | C13: =+C$2*COBERTURA_BOSQUE!C38 -> 1168.0727 | D13: =+D$2*COBERTURA_BOSQUE!D38 -> 1127.5939 | E13: =+E$2*COBERTURA_BOSQUE!E38 -> 1089.9829 | F13: =+F$2*COBERTURA_BOSQUE!F38 -> 1106.46 | G13: =+G$2*COBERTURA_BOSQUE!G38 -> 1122.2028 | H13: =+H$2*COBERTURA_BOSQUE!H38 -> 782.39367 | I13: =+I$2*COBERTURA_BOSQUE!I38 -> 451.69293 | J13: =+J$2*COBERTURA_BOSQUE!J38 -> 639.39478 | ... N13: =+N$2*COBERTURA_BOSQUE!N38 -> 200.28816 | O13: =+O$2*COBERTURA_BOSQUE!P38 -> 200.28816 | P13: =+P$2*COBERTURA_BOSQUE!$P38 -> 200.28816 | Q13: =+Q$2*COBERTURA_BOSQUE!$P38 -> 200.28816 | R13: =+R$2*COBERTURA_BOSQUE!$P38 -> 200.28816 | S13: =+S$2*COBERTURA_BOSQUE!$P38 -> 200.28816 | T13: =+T$2*COBERTURA_BOSQUE!$P38 -> 200.28816 | U13: =+U$2*COBERTURA_BOSQUE!$P38 -> 200.28816 | V13: =+V$2*COBERTURA_BOSQUE!$P38 -> 200.28816 | W13: =+W$2*COBERTURA_BOSQUE!$P38 -> 200.28816 | ... AB13: =+AB$2*COBERTURA_BOSQUE!$P38 -> 200.28816
A14: Tierras de cultivo | B14: B. Siempre verde andino de Ceja Andina | C14: =+C$2*COBERTURA_BOSQUE!C39 -> 804.4214 | D14: =+D$2*COBERTURA_BOSQUE!D39 -> 781.09437 | E14: =+E$2*COBERTURA_BOSQUE!E39 -> 759.42002 | F14: =+F$2*COBERTURA_BOSQUE!F39 -> 754.77857 | G14: =+G$2*COBERTURA_BOSQUE!G39 -> 750.34398 | H14: =+H$2*COBERTURA_BOSQUE!H39 -> 525.32289 | I14: =+I$2*COBERTURA_BOSQUE!I39 -> 304.54578 | J14: =+J$2*COBERTURA_BOSQUE!J39 -> 444.71292 | ... N14: =+N$2*COBERTURA_BOSQUE!N39 -> 145.8425 | O14: =+O$2*COBERTURA_BOSQUE!P39 -> 145.8425 | P14: =+P$2*COBERTURA_BOSQUE!$P39 -> 145.8425 | Q14: =+Q$2*COBERTURA_BOSQUE!$P39 -> 145.8425 | R14: =+R$2*COBERTURA_BOSQUE!$P39 -> 145.8425 | S14: =+S$2*COBERTURA_BOSQUE!$P39 -> 145.8425 | T14: =+T$2*COBERTURA_BOSQUE!$P39 -> 145.8425 | U14: =+U$2*COBERTURA_BOSQUE!$P39 -> 145.8425 | V14: =+V$2*COBERTURA_BOSQUE!$P39 -> 145.8425 | W14: =+W$2*COBERTURA_BOSQUE!$P39 -> 145.8425 | ... AB14: =+AB$2*COBERTURA_BOSQUE!$P39 -> 145.8425
A15: Tierras de cultivo | B15: B. Siempre verde de tierras bajas de la Amazonía | C15: =+C$2*COBERTURA_BOSQUE!C40 -> 5886.3513 | D15: =+D$2*COBERTURA_BOSQUE!D40 -> 6088.7211 | E15: =+E$2*COBERTURA_BOSQUE!E40 -> 6276.7533 | F15: =+F$2*COBERTURA_BOSQUE!F40 -> 6264.7843 | G15: =+G$2*COBERTURA_BOSQUE!G40 -> 6253.3486 | H15: =+H$2*COBERTURA_BOSQUE!H40 -> 4414.2823 | I15: =+I$2*COBERTURA_BOSQUE!I40 -> 2579.9828 | J15: =+J$2*COBERTURA_BOSQUE!J40 -> 3672.2124 | ... N15: =+N$2*COBERTURA_BOSQUE!N40 -> 1138.7503 | O15: =+O$2*COBERTURA_BOSQUE!P40 -> 1138.7503 | P15: =+P$2*COBERTURA_BOSQUE!$P40 -> 1138.7503 | Q15: =+Q$2*COBERTURA_BOSQUE!$P40 -> 1138.7503 | R15: =+R$2*COBERTURA_BOSQUE!$P40 -> 1138.7503 | S15: =+S$2*COBERTURA_BOSQUE!$P40 -> 1138.7503 | T15: =+T$2*COBERTURA_BOSQUE!$P40 -> 1138.7503 | U15: =+U$2*COBERTURA_BOSQUE!$P40 -> 1138.7503 | V15: =+V$2*COBERTURA_BOSQUE!$P40 -> 1138.7503 | W15: =+W$2*COBERTURA_BOSQUE!$P40 -> 1138.7503 | ... AB15: =+AB$2*COBERTURA_BOSQUE!$P40 -> 1138.7503
A16: Tierras de cultivo | B16: B. Siempre verde de tierras bajas del Chocó | C16: =+C$2*COBERTURA_BOSQUE!C41 -> 652.16169 | D16: =+D$2*COBERTURA_BOSQUE!D41 -> 632.85923 | E16: =+E$2*COBERTURA_BOSQUE!E41 -> 614.92433 | F16: =+F$2*COBERTURA_BOSQUE!F41 -> 610.2805 | G16: =+G$2*COBERTURA_BOSQUE!G41 -> 605.84363 | H16: =+H$2*COBERTURA_BOSQUE!H41 -> 414.9654 | I16: =+I$2*COBERTURA_BOSQUE!I41 -> 235.27245 | J16: =+J$2*COBERTURA_BOSQUE!J41 -> 326.63938 | ... N16: =+N$2*COBERTURA_BOSQUE!N41 -> 93.501424 | O16: =+O$2*COBERTURA_BOSQUE!P41 -> 93.501424 | P16: =+P$2*COBERTURA_BOSQUE!$P41 -> 93.501424 | Q16: =+Q$2*COBERTURA_BOSQUE!$P41 -> 93.501424 | R16: =+R$2*COBERTURA_BOSQUE!$P41 -> 93.501424 | S16: =+S$2*COBERTURA_BOSQUE!$P41 -> 93.501424 | T16: =+T$2*COBERTURA_BOSQUE!$P41 -> 93.501424 | U16: =+U$2*COBERTURA_BOSQUE!$P41 -> 93.501424 | V16: =+V$2*COBERTURA_BOSQUE!$P41 -> 93.501424 | W16: =+W$2*COBERTURA_BOSQUE!$P41 -> 93.501424 | ... AB16: =+AB$2*COBERTURA_BOSQUE!$P41 -> 93.501424
A17: Tierras de cultivo | B17: Manglar | C17: =+C$2*COBERTURA_BOSQUE!C42 -> 161.96574 | D17: =+D$2*COBERTURA_BOSQUE!D42 -> 156.84545 | E17: =+E$2*COBERTURA_BOSQUE!E42 -> 152.08793 | F17: =+F$2*COBERTURA_BOSQUE!F42 -> 145.06137 | G17: =+G$2*COBERTURA_BOSQUE!G42 -> 138.34796 | H17: =+H$2*COBERTURA_BOSQUE!H42 -> 101.50906 | I17: =+I$2*COBERTURA_BOSQUE!I42 -> 61.527241 | J17: =+J$2*COBERTURA_BOSQUE!J42 -> 85.265014 | ... N17: =+N$2*COBERTURA_BOSQUE!N42 -> 38.136258 | O17: =+O$2*COBERTURA_BOSQUE!P42 -> 38.136258 | P17: =+P$2*COBERTURA_BOSQUE!$P42 -> 38.136258 | Q17: =+Q$2*COBERTURA_BOSQUE!$P42 -> 38.136258 | R17: =+R$2*COBERTURA_BOSQUE!$P42 -> 38.136258 | S17: =+S$2*COBERTURA_BOSQUE!$P42 -> 38.136258 | T17: =+T$2*COBERTURA_BOSQUE!$P42 -> 38.136258 | U17: =+U$2*COBERTURA_BOSQUE!$P42 -> 38.136258 | V17: =+V$2*COBERTURA_BOSQUE!$P42 -> 38.136258 | W17: =+W$2*COBERTURA_BOSQUE!$P42 -> 38.136258 | ... AB17: =+AB$2*COBERTURA_BOSQUE!$P42 -> 38.136258
A18: Tierras de cultivo | B18: Moretal | C18: =+C$2*COBERTURA_BOSQUE!C43 -> 677.31302 | D18: =+D$2*COBERTURA_BOSQUE!D43 -> 654.6155 | E18: =+E$2*COBERTURA_BOSQUE!E43 -> 633.52606 | F18: =+F$2*COBERTURA_BOSQUE!F43 -> 629.43103 | G18: =+G$2*COBERTURA_BOSQUE!G43 -> 625.5185 | H18: =+H$2*COBERTURA_BOSQUE!H43 -> 446.85695 | I18: =+I$2*COBERTURA_BOSQUE!I43 -> 264.19919 | J18: =+J$2*COBERTURA_BOSQUE!J43 -> 370.40812 | ... N18: =+N$2*COBERTURA_BOSQUE!N43 -> 106.083 | O18: =+O$2*COBERTURA_BOSQUE!P43 -> 106.083 | P18: =+P$2*COBERTURA_BOSQUE!$P43 -> 106.083 | Q18: =+Q$2*COBERTURA_BOSQUE!$P43 -> 106.083 | R18: =+R$2*COBERTURA_BOSQUE!$P43 -> 106.083 | S18: =+S$2*COBERTURA_BOSQUE!$P43 -> 106.083 | T18: =+T$2*COBERTURA_BOSQUE!$P43 -> 106.083 | U18: =+U$2*COBERTURA_BOSQUE!$P43 -> 106.083 | V18: =+V$2*COBERTURA_BOSQUE!$P43 -> 106.083 | W18: =+W$2*COBERTURA_BOSQUE!$P43 -> 106.083 | ... AB18: =+AB$2*COBERTURA_BOSQUE!$P43 -> 106.083
A19: Tierras de cultivo | B19: Plantación forestal | C19: =+C$2*COBERTURA_BOSQUE!C44 -> 95.394368 | D19: =+D$2*COBERTURA_BOSQUE!D44 -> 91.890987 | E19: =+E$2*COBERTURA_BOSQUE!E44 -> 88.635815 | F19: =+F$2*COBERTURA_BOSQUE!F44 -> 86.6157 | G19: =+G$2*COBERTURA_BOSQUE!G44 -> 84.685614 | H19: =+H$2*COBERTURA_BOSQUE!H44 -> 112.06349 | I19: =+I$2*COBERTURA_BOSQUE!I44 -> 95.372917 | J19: =+J$2*COBERTURA_BOSQUE!J44 -> 126.65483 | ... N19: =+N$2*COBERTURA_BOSQUE!N44 -> 44.770358 | O19: =+O$2*COBERTURA_BOSQUE!P44 -> 44.770358 | P19: =+P$2*COBERTURA_BOSQUE!$P44 -> 44.770358 | Q19: =+Q$2*COBERTURA_BOSQUE!$P44 -> 44.770358 | R19: =+R$2*COBERTURA_BOSQUE!$P44 -> 44.770358 | S19: =+S$2*COBERTURA_BOSQUE!$P44 -> 44.770358 | T19: =+T$2*COBERTURA_BOSQUE!$P44 -> 44.770358 | U19: =+U$2*COBERTURA_BOSQUE!$P44 -> 44.770358 | V19: =+V$2*COBERTURA_BOSQUE!$P44 -> 44.770358 | W19: =+W$2*COBERTURA_BOSQUE!$P44 -> 44.770358 | ... AB19: =+AB$2*COBERTURA_BOSQUE!$P44 -> 44.770358
A20: Total | C20: =+SUM(C10:C19) -> 12650.5 | D20: =+SUM(D10:D19) -> 12650.5 | E20: =+SUM(E10:E19) -> 12650.5 | F20: =+SUM(F10:F19) -> 12650.5 | G20: =+SUM(G10:G19) -> 12650.5 | H20: =+SUM(H10:H19) -> 8941.5 | I20: =+SUM(I10:I19) -> 5232.5 | J20: =+SUM(J10:J19) -> 7404.86 | ... AB20: =+SUM(AB10:AB19) -> 2315.79
A22: Pastizales a tierras forestales (hectáreas)
A23: Pastizales | B23: B. Seco Andino | C23: =+C$3*COBERTURA_BOSQUE!C35 -> 4.4070858 | D23: =+D$3*COBERTURA_BOSQUE!D35 -> 4.6076946 | E23: =+E$3*COBERTURA_BOSQUE!E35 -> 4.7940904 | F23: =+F$3*COBERTURA_BOSQUE!F35 -> 4.726154 | G23: =+G$3*COBERTURA_BOSQUE!G35 -> 4.6612453 | H23: =+H$3*COBERTURA_BOSQUE!H35 -> 6.2935281 | I23: =+I$3*COBERTURA_BOSQUE!I35 -> 7.8951476 | J23: =+J$3*COBERTURA_BOSQUE!J35 -> 7.3117365 | ... N23: =+N$3*COBERTURA_BOSQUE!N35 -> 0.12938524 | O23: =+O$3*COBERTURA_BOSQUE!$P35 -> 0.12938524 | P23: =+P$3*COBERTURA_BOSQUE!$P35 -> 0.12938524 | Q23: =+Q$3*COBERTURA_BOSQUE!$P35 -> 0.12938524 | R23: =+R$3*COBERTURA_BOSQUE!$P35 -> 0.12938524 | S23: =+S$3*COBERTURA_BOSQUE!$P35 -> 0.12938524 | T23: =+T$3*COBERTURA_BOSQUE!$P35 -> 0.12938524 | U23: =+U$3*COBERTURA_BOSQUE!$P35 -> 0.12938524 | V23: =+V$3*COBERTURA_BOSQUE!$P35 -> 0.12938524 | ... AB23: =+AB$3*COBERTURA_BOSQUE!$P35 -> 0.12938524
A24: Pastizales | B24: B. Seco Pluvioestacional | C24: =+C$3*COBERTURA_BOSQUE!C36 -> 43.036012 | D24: =+D$3*COBERTURA_BOSQUE!D36 -> 43.391523 | E24: =+E$3*COBERTURA_BOSQUE!E36 -> 43.721846 | F24: =+F$3*COBERTURA_BOSQUE!F36 -> 44.07476 | G24: =+G$3*COBERTURA_BOSQUE!G36 -> 44.411946 | H24: =+H$3*COBERTURA_BOSQUE!H36 -> 59.714768 | I24: =+I$3*COBERTURA_BOSQUE!I36 -> 74.60032 | J24: =+J$3*COBERTURA_BOSQUE!J36 -> 69.186994 | ... N24: =+N$3*COBERTURA_BOSQUE!N36 -> 1.3226616 | O24: =+O$3*COBERTURA_BOSQUE!$P36 -> 1.3226616 | P24: =+P$3*COBERTURA_BOSQUE!$P36 -> 1.3226616 | Q24: =+Q$3*COBERTURA_BOSQUE!$P36 -> 1.3226616 | R24: =+R$3*COBERTURA_BOSQUE!$P36 -> 1.3226616 | S24: =+S$3*COBERTURA_BOSQUE!$P36 -> 1.3226616 | T24: =+T$3*COBERTURA_BOSQUE!$P36 -> 1.3226616 | U24: =+U$3*COBERTURA_BOSQUE!$P36 -> 1.3226616 | V24: =+V$3*COBERTURA_BOSQUE!$P36 -> 1.3226616 | ... AB24: =+AB$3*COBERTURA_BOSQUE!$P36 -> 1.3226616
A25: Pastizales | B25: B. Siempre verde andino Montano | C25: =+C$3*COBERTURA_BOSQUE!C37 -> 411.51456 | D25: =+D$3*COBERTURA_BOSQUE!D37 -> 398.36463 | E25: =+E$3*COBERTURA_BOSQUE!E37 -> 386.14636 | F25: =+F$3*COBERTURA_BOSQUE!F37 -> 388.42753 | G25: =+G$3*COBERTURA_BOSQUE!G37 -> 390.60702 | H25: =+H$3*COBERTURA_BOSQUE!H37 -> 526.23885 | I25: =+I$3*COBERTURA_BOSQUE!I37 -> 658.72348 | J25: =+J$3*COBERTURA_BOSQUE!J37 -> 616.17551 | ... N25: =+N$3*COBERTURA_BOSQUE!N37 -> 11.93284 | O25: =+O$3*COBERTURA_BOSQUE!$P37 -> 11.93284 | P25: =+P$3*COBERTURA_BOSQUE!$P37 -> 11.93284 | Q25: =+Q$3*COBERTURA_BOSQUE!$P37 -> 11.93284 | R25: =+R$3*COBERTURA_BOSQUE!$P37 -> 11.93284 | S25: =+S$3*COBERTURA_BOSQUE!$P37 -> 11.93284 | T25: =+T$3*COBERTURA_BOSQUE!$P37 -> 11.93284 | U25: =+U$3*COBERTURA_BOSQUE!$P37 -> 11.93284 | V25: =+V$3*COBERTURA_BOSQUE!$P37 -> 11.93284 | ... AB25: =+AB$3*COBERTURA_BOSQUE!$P37 -> 11.93284
A26: Pastizales | B26: B. Siempre verde andino Pie montano | C26: =+C$3*COBERTURA_BOSQUE!C38 -> 167.27801 | D26: =+D$3*COBERTURA_BOSQUE!D38 -> 161.4811 | E26: =+E$3*COBERTURA_BOSQUE!E38 -> 156.09489 | F26: =+F$3*COBERTURA_BOSQUE!F38 -> 158.45456 | G26: =+G$3*COBERTURA_BOSQUE!G38 -> 160.70906 | H26: =+H$3*COBERTURA_BOSQUE!H38 -> 216.11356 | I26: =+I$3*COBERTURA_BOSQUE!I38 -> 270.02302 | J26: =+J$3*COBERTURA_BOSQUE!J38 -> 254.59834 | ... N26: =+N$3*COBERTURA_BOSQUE!N38 -> 4.8883044 | O26: =+O$3*COBERTURA_BOSQUE!$P38 -> 4.8883044 | P26: =+P$3*COBERTURA_BOSQUE!$P38 -> 4.8883044 | Q26: =+Q$3*COBERTURA_BOSQUE!$P38 -> 4.8883044 | R26: =+R$3*COBERTURA_BOSQUE!$P38 -> 4.8883044 | S26: =+S$3*COBERTURA_BOSQUE!$P38 -> 4.8883044 | T26: =+T$3*COBERTURA_BOSQUE!$P38 -> 4.8883044 | U26: =+U$3*COBERTURA_BOSQUE!$P38 -> 4.8883044 | V26: =+V$3*COBERTURA_BOSQUE!$P38 -> 4.8883044 | ... AB26: =+AB$3*COBERTURA_BOSQUE!$P38 -> 4.8883044
A27: Pastizales | B27: B. Siempre verde andino de Ceja Andina | C27: =+C$3*COBERTURA_BOSQUE!C39 -> 115.20004 | D27: =+D$3*COBERTURA_BOSQUE!D39 -> 111.85941 | E27: =+E$3*COBERTURA_BOSQUE!E39 -> 108.75545 | F27: =+F$3*COBERTURA_BOSQUE!F39 -> 108.09076 | G27: =+G$3*COBERTURA_BOSQUE!G39 -> 107.45569 | H27: =+H$3*COBERTURA_BOSQUE!H39 -> 145.10521 | I27: =+I$3*COBERTURA_BOSQUE!I39 -> 182.05814 | J27: =+J$3*COBERTURA_BOSQUE!J39 -> 177.07866 | ... N27: =+N$3*COBERTURA_BOSQUE!N39 -> 3.5594843 | O27: =+O$3*COBERTURA_BOSQUE!$P39 -> 3.5594843 | P27: =+P$3*COBERTURA_BOSQUE!$P39 -> 3.5594843 | Q27: =+Q$3*COBERTURA_BOSQUE!$P39 -> 3.5594843 | R27: =+R$3*COBERTURA_BOSQUE!$P39 -> 3.5594843 | S27: =+S$3*COBERTURA_BOSQUE!$P39 -> 3.5594843 | T27: =+T$3*COBERTURA_BOSQUE!$P39 -> 3.5594843 | U27: =+U$3*COBERTURA_BOSQUE!$P39 -> 3.5594843 | V27: =+V$3*COBERTURA_BOSQUE!$P39 -> 3.5594843 | ... AB27: =+AB$3*COBERTURA_BOSQUE!$P39 -> 3.5594843
A28: Pastizales | B28: B. Siempre verde de tierras bajas de la Amazonía | C28: =+C$3*COBERTURA_BOSQUE!C40 -> 842.97595 | D28: =+D$3*COBERTURA_BOSQUE!D40 -> 871.95704 | E28: =+E$3*COBERTURA_BOSQUE!E40 -> 898.88486 | F28: =+F$3*COBERTURA_BOSQUE!F40 -> 897.17079 | G28: =+G$3*COBERTURA_BOSQUE!G40 -> 895.53311 | H28: =+H$3*COBERTURA_BOSQUE!H40 -> 1219.3174 | I28: =+I$3*COBERTURA_BOSQUE!I40 -> 1542.3194 | J28: =+J$3*COBERTURA_BOSQUE!J40 -> 1462.2253 | ... N28: =+N$3*COBERTURA_BOSQUE!N40 -> 27.792747 | O28: =+O$3*COBERTURA_BOSQUE!$P40 -> 27.792747 | P28: =+P$3*COBERTURA_BOSQUE!$P40 -> 27.792747 | Q28: =+Q$3*COBERTURA_BOSQUE!$P40 -> 27.792747 | R28: =+R$3*COBERTURA_BOSQUE!$P40 -> 27.792747 | S28: =+S$3*COBERTURA_BOSQUE!$P40 -> 27.792747 | T28: =+T$3*COBERTURA_BOSQUE!$P40 -> 27.792747 | U28: =+U$3*COBERTURA_BOSQUE!$P40 -> 27.792747 | V28: =+V$3*COBERTURA_BOSQUE!$P40 -> 27.792747 | ... AB28: =+AB$3*COBERTURA_BOSQUE!$P40 -> 27.792747
A29: Pastizales | B29: B. Siempre verde de tierras bajas del Chocó | C29: =+C$3*COBERTURA_BOSQUE!C41 -> 93.395143 | D29: =+D$3*COBERTURA_BOSQUE!D41 -> 90.630865 | E29: =+E$3*COBERTURA_BOSQUE!E41 -> 88.062433 | F29: =+F$3*COBERTURA_BOSQUE!F41 -> 87.397397 | G29: =+G$3*COBERTURA_BOSQUE!G41 -> 86.762 | H29: =+H$3*COBERTURA_BOSQUE!H41 -> 114.62215 | I29: =+I$3*COBERTURA_BOSQUE!I41 -> 140.64639 | J29: =+J$3*COBERTURA_BOSQUE!J41 -> 130.06338 | ... N29: =+N$3*COBERTURA_BOSQUE!N41 -> 2.2820292 | O29: =+O$3*COBERTURA_BOSQUE!$P41 -> 2.2820292 | P29: =+P$3*COBERTURA_BOSQUE!$P41 -> 2.2820292 | Q29: =+Q$3*COBERTURA_BOSQUE!$P41 -> 2.2820292 | R29: =+R$3*COBERTURA_BOSQUE!$P41 -> 2.2820292 | S29: =+S$3*COBERTURA_BOSQUE!$P41 -> 2.2820292 | T29: =+T$3*COBERTURA_BOSQUE!$P41 -> 2.2820292 | U29: =+U$3*COBERTURA_BOSQUE!$P41 -> 2.2820292 | V29: =+V$3*COBERTURA_BOSQUE!$P41 -> 2.2820292 | ... AB29: =+AB$3*COBERTURA_BOSQUE!$P41 -> 2.2820292
A30: Pastizales | B30: Manglar | C30: =+C$3*COBERTURA_BOSQUE!C42 -> 23.194882 | D30: =+D$3*COBERTURA_BOSQUE!D42 -> 22.461613 | E30: =+E$3*COBERTURA_BOSQUE!E42 -> 21.780295 | F30: =+F$3*COBERTURA_BOSQUE!F42 -> 20.774031 | G30: =+G$3*COBERTURA_BOSQUE!G42 -> 19.812613 | H30: =+H$3*COBERTURA_BOSQUE!H42 -> 28.038932 | I30: =+I$3*COBERTURA_BOSQUE!I42 -> 36.78112 | J30: =+J$3*COBERTURA_BOSQUE!J42 -> 33.951374 | ... N30: =+N$3*COBERTURA_BOSQUE!N42 -> 0.93076716 | O30: =+O$3*COBERTURA_BOSQUE!$P42 -> 0.93076716 | P30: =+P$3*COBERTURA_BOSQUE!$P42 -> 0.93076716 | Q30: =+Q$3*COBERTURA_BOSQUE!$P42 -> 0.93076716 | R30: =+R$3*COBERTURA_BOSQUE!$P42 -> 0.93076716 | S30: =+S$3*COBERTURA_BOSQUE!$P42 -> 0.93076716 | T30: =+T$3*COBERTURA_BOSQUE!$P42 -> 0.93076716 | U30: =+U$3*COBERTURA_BOSQUE!$P42 -> 0.93076716 | V30: =+V$3*COBERTURA_BOSQUE!$P42 -> 0.93076716 | ... AB30: =+AB$3*COBERTURA_BOSQUE!$P42 -> 0.93076716
A31: Pastizales | B31: Moretal | C31: =+C$3*COBERTURA_BOSQUE!C43 -> 96.997028 | D31: =+D$3*COBERTURA_BOSQUE!D43 -> 93.746549 | E31: =+E$3*COBERTURA_BOSQUE!E43 -> 90.726361 | F31: =+F$3*COBERTURA_BOSQUE!F43 -> 90.139917 | G31: =+G$3*COBERTURA_BOSQUE!G43 -> 89.579609 | H31: =+H$3*COBERTURA_BOSQUE!H43 -> 123.43127 | I31: =+I$3*COBERTURA_BOSQUE!I43 -> 157.93886 | J31: =+J$3*COBERTURA_BOSQUE!J43 -> 147.4915 | ... N31: =+N$3*COBERTURA_BOSQUE!N43 -> 2.5890997 | O31: =+O$3*COBERTURA_BOSQUE!$P43 -> 2.5890997 | P31: =+P$3*COBERTURA_BOSQUE!$P43 -> 2.5890997 | Q31: =+Q$3*COBERTURA_BOSQUE!$P43 -> 2.5890997 | R31: =+R$3*COBERTURA_BOSQUE!$P43 -> 2.5890997 | S31: =+S$3*COBERTURA_BOSQUE!$P43 -> 2.5890997 | T31: =+T$3*COBERTURA_BOSQUE!$P43 -> 2.5890997 | U31: =+U$3*COBERTURA_BOSQUE!$P43 -> 2.5890997 | V31: =+V$3*COBERTURA_BOSQUE!$P43 -> 2.5890997 | ... AB31: =+AB$3*COBERTURA_BOSQUE!$P43 -> 2.5890997
A32: Pastizales | B32: Plantación forestal | C32: =+C$3*COBERTURA_BOSQUE!C44 -> 13.661291 | D32: =+D$3*COBERTURA_BOSQUE!D44 -> 13.159577 | E32: =+E$3*COBERTURA_BOSQUE!E44 -> 12.693408 | F32: =+F$3*COBERTURA_BOSQUE!F44 -> 12.40411 | G32: =+G$3*COBERTURA_BOSQUE!G44 -> 12.127706 | H32: =+H$3*COBERTURA_BOSQUE!H44 -> 30.954288 | I32: =+I$3*COBERTURA_BOSQUE!I44 -> 57.014139 | J32: =+J$3*COBERTURA_BOSQUE!J44 -> 50.432238 | ... N32: =+N$3*COBERTURA_BOSQUE!N44 -> 1.0926814 | O32: =+O$3*COBERTURA_BOSQUE!$P44 -> 1.0926814 | P32: =+P$3*COBERTURA_BOSQUE!$P44 -> 1.0926814 | Q32: =+Q$3*COBERTURA_BOSQUE!$P44 -> 1.0926814 | R32: =+R$3*COBERTURA_BOSQUE!$P44 -> 1.0926814 | S32: =+S$3*COBERTURA_BOSQUE!$P44 -> 1.0926814 | T32: =+T$3*COBERTURA_BOSQUE!$P44 -> 1.0926814 | U32: =+U$3*COBERTURA_BOSQUE!$P44 -> 1.0926814 | V32: =+V$3*COBERTURA_BOSQUE!$P44 -> 1.0926814 | ... AB32: =+AB$3*COBERTURA_BOSQUE!$P44 -> 1.0926814
A33: Total | C33: =+SUM(C23:C32) -> 1811.66 | D33: =+SUM(D23:D32) -> 1811.66 | E33: =+SUM(E23:E32) -> 1811.66 | F33: =+SUM(F23:F32) -> 1811.66 | G33: =+SUM(G23:G32) -> 1811.66 | H33: =+SUM(H23:H32) -> 2469.83 | I33: =+SUM(I23:I32) -> 3128 | J33: =+SUM(J23:J32) -> 2948.515 | ... AB33: =+SUM(AB23:AB32) -> 56.52
A35: Humedales a tierras forestales (hectáreas)
A36: Humedales | B36: B. Seco Andino | C36: =+C$4*COBERTURA_BOSQUE!C35 -> 0.090396272 | D36: =+D$4*COBERTURA_BOSQUE!D35 -> 0.094511073 | E36: =+E$4*COBERTURA_BOSQUE!E35 -> 0.098334346 | F36: =+F$4*COBERTURA_BOSQUE!F35 -> 0.096940863 | G36: =+G$4*COBERTURA_BOSQUE!G35 -> 0.095609484 | H36: =+H$4*COBERTURA_BOSQUE!H35 -> 0.10021923 | I36: =+I$4*COBERTURA_BOSQUE!I35 -> 0.104747 | J36: =+J$4*COBERTURA_BOSQUE!J35 -> 0.10206869 | ... N36: =+N$4*COBERTURA_BOSQUE!N35 -> 0.027813706 | O36: =+O$4*COBERTURA_BOSQUE!$P35 -> 0.027813706 | P36: =+P$4*COBERTURA_BOSQUE!$P35 -> 0.027813706 | Q36: =+Q$4*COBERTURA_BOSQUE!$P35 -> 0.027813706 | R36: =+R$4*COBERTURA_BOSQUE!$P35 -> 0.027813706 | S36: =+S$4*COBERTURA_BOSQUE!$P35 -> 0.027813706 | T36: =+T$4*COBERTURA_BOSQUE!$P35 -> 0.027813706 | U36: =+U$4*COBERTURA_BOSQUE!$P35 -> 0.027813706 | V36: =+V$4*COBERTURA_BOSQUE!$P35 -> 0.027813706 | ... AB36: =+AB$4*COBERTURA_BOSQUE!$P35 -> 0.027813706
A37: Humedales | B37: B. Seco Pluvioestacional | C37: =+C$4*COBERTURA_BOSQUE!C36 -> 0.8827364 | D37: =+D$4*COBERTURA_BOSQUE!D36 -> 0.89002847 | E37: =+E$4*COBERTURA_BOSQUE!E36 -> 0.89680392 | F37: =+F$4*COBERTURA_BOSQUE!F36 -> 0.90404275 | G37: =+G$4*COBERTURA_BOSQUE!G36 -> 0.91095897 | H37: =+H$4*COBERTURA_BOSQUE!H36 -> 0.95090829 | I37: =+I$4*COBERTURA_BOSQUE!I36 -> 0.9897421 | J37: =+J$4*COBERTURA_BOSQUE!J36 -> 0.96582065 | ... N37: =+N$4*COBERTURA_BOSQUE!N36 -> 0.28433013 | O37: =+O$4*COBERTURA_BOSQUE!$P36 -> 0.28433013 | P37: =+P$4*COBERTURA_BOSQUE!$P36 -> 0.28433013 | Q37: =+Q$4*COBERTURA_BOSQUE!$P36 -> 0.28433013 | R37: =+R$4*COBERTURA_BOSQUE!$P36 -> 0.28433013 | S37: =+S$4*COBERTURA_BOSQUE!$P36 -> 0.28433013 | T37: =+T$4*COBERTURA_BOSQUE!$P36 -> 0.28433013 | U37: =+U$4*COBERTURA_BOSQUE!$P36 -> 0.28433013 | V37: =+V$4*COBERTURA_BOSQUE!$P36 -> 0.28433013 | ... AB37: =+AB$4*COBERTURA_BOSQUE!$P36 -> 0.28433013
A38: Humedales | B38: B. Siempre verde andino Montano | C38: =+C$4*COBERTURA_BOSQUE!C37 -> 8.4408118 | D38: =+D$4*COBERTURA_BOSQUE!D37 -> 8.1710861 | E38: =+E$4*COBERTURA_BOSQUE!E37 -> 7.9204701 | F38: =+F$4*COBERTURA_BOSQUE!F37 -> 7.9672603 | G38: =+G$4*COBERTURA_BOSQUE!G37 -> 8.0119653 | H38: =+H$4*COBERTURA_BOSQUE!H37 -> 8.3799184 | I38: =+I$4*COBERTURA_BOSQUE!I37 -> 8.7394579 | J38: =+J$4*COBERTURA_BOSQUE!J37 -> 8.6015448 | ... N38: =+N$4*COBERTURA_BOSQUE!N37 -> 2.5651805 | O38: =+O$4*COBERTURA_BOSQUE!$P37 -> 2.5651805 | P38: =+P$4*COBERTURA_BOSQUE!$P37 -> 2.5651805 | Q38: =+Q$4*COBERTURA_BOSQUE!$P37 -> 2.5651805 | R38: =+R$4*COBERTURA_BOSQUE!$P37 -> 2.5651805 | S38: =+S$4*COBERTURA_BOSQUE!$P37 -> 2.5651805 | T38: =+T$4*COBERTURA_BOSQUE!$P37 -> 2.5651805 | U38: =+U$4*COBERTURA_BOSQUE!$P37 -> 2.5651805 | V38: =+V$4*COBERTURA_BOSQUE!$P37 -> 2.5651805 | ... AB38: =+AB$4*COBERTURA_BOSQUE!$P37 -> 2.5651805
A39: Humedales | B39: B. Siempre verde andino Pie montano | C39: =+C$4*COBERTURA_BOSQUE!C38 -> 3.4311356 | D39: =+D$4*COBERTURA_BOSQUE!D38 -> 3.3122317 | E39: =+E$4*COBERTURA_BOSQUE!E38 -> 3.2017521 | F39: =+F$4*COBERTURA_BOSQUE!F38 -> 3.2501525 | G39: =+G$4*COBERTURA_BOSQUE!G38 -> 3.296396 | H39: =+H$4*COBERTURA_BOSQUE!H38 -> 3.4414296 | I39: =+I$4*COBERTURA_BOSQUE!I38 -> 3.5824666 | J39: =+J$4*COBERTURA_BOSQUE!J38 -> 3.5540833 | ... N39: =+N$4*COBERTURA_BOSQUE!N38 -> 1.0508298 | O39: =+O$4*COBERTURA_BOSQUE!$P38 -> 1.0508298 | P39: =+P$4*COBERTURA_BOSQUE!$P38 -> 1.0508298 | Q39: =+Q$4*COBERTURA_BOSQUE!$P38 -> 1.0508298 | R39: =+R$4*COBERTURA_BOSQUE!$P38 -> 1.0508298 | S39: =+S$4*COBERTURA_BOSQUE!$P38 -> 1.0508298 | T39: =+T$4*COBERTURA_BOSQUE!$P38 -> 1.0508298 | U39: =+U$4*COBERTURA_BOSQUE!$P38 -> 1.0508298 | V39: =+V$4*COBERTURA_BOSQUE!$P38 -> 1.0508298 | ... AB39: =+AB$4*COBERTURA_BOSQUE!$P38 -> 1.0508298
A40: Humedales | B40: B. Siempre verde andino de Ceja Andina | C40: =+C$4*COBERTURA_BOSQUE!C39 -> 2.3629342 | D40: =+D$4*COBERTURA_BOSQUE!D39 -> 2.2944126 | E40: =+E$4*COBERTURA_BOSQUE!E39 -> 2.2307457 | F40: =+F$4*COBERTURA_BOSQUE!F39 -> 2.2171117 | G40: =+G$4*COBERTURA_BOSQUE!G39 -> 2.2040854 | H40: =+H$4*COBERTURA_BOSQUE!H39 -> 2.3106805 | I40: =+I$4*COBERTURA_BOSQUE!I39 -> 2.4154133 | J40: =+J$4*COBERTURA_BOSQUE!J39 -> 2.4719419 | ... N40: =+N$4*COBERTURA_BOSQUE!N39 -> 0.76517577 | O40: =+O$4*COBERTURA_BOSQUE!$P39 -> 0.76517577 | P40: =+P$4*COBERTURA_BOSQUE!$P39 -> 0.76517577 | Q40: =+Q$4*COBERTURA_BOSQUE!$P39 -> 0.76517577 | R40: =+R$4*COBERTURA_BOSQUE!$P39 -> 0.76517577 | S40: =+S$4*COBERTURA_BOSQUE!$P39 -> 0.76517577 | T40: =+T$4*COBERTURA_BOSQUE!$P39 -> 0.76517577 | U40: =+U$4*COBERTURA_BOSQUE!$P39 -> 0.76517577 | V40: =+V$4*COBERTURA_BOSQUE!$P39 -> 0.76517577 | ... AB40: =+AB$4*COBERTURA_BOSQUE!$P39 -> 0.76517577
A41: Humedales | B41: B. Siempre verde de tierras bajas de la Amazonía | C41: =+C$4*COBERTURA_BOSQUE!C40 -> 17.290764 | D41: =+D$4*COBERTURA_BOSQUE!D40 -> 17.885212 | E41: =+E$4*COBERTURA_BOSQUE!E40 -> 18.437544 | F41: =+F$4*COBERTURA_BOSQUE!F40 -> 18.402386 | G41: =+G$4*COBERTURA_BOSQUE!G40 -> 18.368795 | H41: =+H$4*COBERTURA_BOSQUE!H40 -> 19.416622 | I41: =+I$4*COBERTURA_BOSQUE!I40 -> 20.462358 | J41: =+J$4*COBERTURA_BOSQUE!J40 -> 20.412035 | ... N41: =+N$4*COBERTURA_BOSQUE!N40 -> 5.9745555 | O41: =+O$4*COBERTURA_BOSQUE!$P40 -> 5.9745555 | P41: =+P$4*COBERTURA_BOSQUE!$P40 -> 5.9745555 | Q41: =+Q$4*COBERTURA_BOSQUE!$P40 -> 5.9745555 | R41: =+R$4*COBERTURA_BOSQUE!$P40 -> 5.9745555 | S41: =+S$4*COBERTURA_BOSQUE!$P40 -> 5.9745555 | T41: =+T$4*COBERTURA_BOSQUE!$P40 -> 5.9745555 | U41: =+U$4*COBERTURA_BOSQUE!$P40 -> 5.9745555 | V41: =+V$4*COBERTURA_BOSQUE!$P40 -> 5.9745555 | ... AB41: =+AB$4*COBERTURA_BOSQUE!$P40 -> 5.9745555
A42: Humedales | B42: B. Siempre verde de tierras bajas del Chocó | C42: =+C$4*COBERTURA_BOSQUE!C41 -> 1.9156815 | D42: =+D$4*COBERTURA_BOSQUE!D41 -> 1.8589818 | E42: =+E$4*COBERTURA_BOSQUE!E41 -> 1.8062992 | F42: =+F$4*COBERTURA_BOSQUE!F41 -> 1.7926583 | G42: =+G$4*COBERTURA_BOSQUE!G41 -> 1.7796253 | H42: =+H$4*COBERTURA_BOSQUE!H41 -> 1.825263 | I42: =+I$4*COBERTURA_BOSQUE!I41 -> 1.8659927 | J42: =+J$4*COBERTURA_BOSQUE!J41 -> 1.8156288 | ... N42: =+N$4*COBERTURA_BOSQUE!N41 -> 0.49056361 | O42: =+O$4*COBERTURA_BOSQUE!$P41 -> 0.49056361 | P42: =+P$4*COBERTURA_BOSQUE!$P41 -> 0.49056361 | Q42: =+Q$4*COBERTURA_BOSQUE!$P41 -> 0.49056361 | R42: =+R$4*COBERTURA_BOSQUE!$P41 -> 0.49056361 | S42: =+S$4*COBERTURA_BOSQUE!$P41 -> 0.49056361 | T42: =+T$4*COBERTURA_BOSQUE!$P41 -> 0.49056361 | U42: =+U$4*COBERTURA_BOSQUE!$P41 -> 0.49056361 | V42: =+V$4*COBERTURA_BOSQUE!$P41 -> 0.49056361 | ... AB42: =+AB$4*COBERTURA_BOSQUE!$P41 -> 0.49056361
A43: Humedales | B43: Manglar | C43: =+C$4*COBERTURA_BOSQUE!C42 -> 0.47576357 | D43: =+D$4*COBERTURA_BOSQUE!D42 -> 0.46072306 | E43: =+E$4*COBERTURA_BOSQUE!E42 -> 0.44674815 | F43: =+F$4*COBERTURA_BOSQUE!F42 -> 0.42610809 | G43: =+G$4*COBERTURA_BOSQUE!G42 -> 0.40638789 | H43: =+H$4*COBERTURA_BOSQUE!H42 -> 0.4464968 | I43: =+I$4*COBERTURA_BOSQUE!I42 -> 0.48798481 | J43: =+J$4*COBERTURA_BOSQUE!J42 -> 0.47394657 | ... N43: =+N$4*COBERTURA_BOSQUE!N42 -> 0.2000853 | O43: =+O$4*COBERTURA_BOSQUE!$P42 -> 0.2000853 | P43: =+P$4*COBERTURA_BOSQUE!$P42 -> 0.2000853 | Q43: =+Q$4*COBERTURA_BOSQUE!$P42 -> 0.2000853 | R43: =+R$4*COBERTURA_BOSQUE!$P42 -> 0.2000853 | S43: =+S$4*COBERTURA_BOSQUE!$P42 -> 0.2000853 | T43: =+T$4*COBERTURA_BOSQUE!$P42 -> 0.2000853 | U43: =+U$4*COBERTURA_BOSQUE!$P42 -> 0.2000853 | V43: =+V$4*COBERTURA_BOSQUE!$P42 -> 0.2000853 | ... AB43: =+AB$4*COBERTURA_BOSQUE!$P42 -> 0.2000853
...

Sheet COBERTURA_CAMBIOS_TF
B1: % de cambio según tipo de cambio | C1: Uso del suelo inicial (Ha) | D1: Uso del suelo en el año del inventario | E1: 2010 | F1: 2011 | G1: 2012 | H1: 2013 | I1: 2014 | J1: 2015 | K1: 2016 | L1: 2017 | M1: 2018 | N1: 2019 | O1: 2020 | P1: 2021 | Q1: 2022 | R1: 2023 | S1: 2024 | T1: 2025 | U1: 2026 | V1: 2027 | W1: 2028 | X1: 2029 | Y1: 2030 | Z1: 2031 | AA1: 2032 | AB1: 2033 | AC1: 2034 | AD1: 2035
B2: Tierras de cultivo
B3: =+SUM(Q4:Q13)/(SUM(Q4:Q13)+SUM(Q22:Q31)+SUM(Q39:Q48)+SUM(Q56:Q65)+SUM(Q74:Q83)) -> 0.89929396 | F3: =+SUM(F4:F13,F22:F31,F39:F48,F56:F65,F74:F83) -> 101112.44 | G3: =+SUM(G4:G13,G22:G31,G39:G48,G56:G65,G74:G83) -> 101112.44 | H3: =+SUM(H4:H13,H22:H31,H39:H48,H56:H65,H74:H83) -> 101112.44 | I3: =+SUM(I4:I13,I22:I31,I39:I48,I56:I65,I74:I83) -> 101112.44 | J3: =+SUM(J4:J13,J22:J31,J39:J48,J56:J65,J74:J83) -> 103530.94 | K3: =+SUM(K4:K13,K22:K31,K39:K48,K56:K65,K74:K83) -> 105949.44 | L3: =+SUM(L4:L13,L22:L31,L39:L48,L56:L65,L74:L83) -> 100894.4 | M3: =+SUM(M4:M13,M22:M31,M39:M48,M56:M65,M74:M83) -> 95839.355 | ... Q3: =+SUM(Q4:Q13,Q22:Q31,Q39:Q48,Q56:Q65,Q74:Q83) -> 107333.28 | R3: =-COBERTURA_BOSQUE!P28 -> 91412.348 | S3: =-COBERTURA_BOSQUE!Q28 -> 90722.837 | T3: =-COBERTURA_BOSQUE!R28 -> 90038.528 | U3: =-COBERTURA_BOSQUE!S28 -> 89359.382 | V3: =-COBERTURA_BOSQUE!T28 -> 88685.359 | W3: =-COBERTURA_BOSQUE!U28 -> 88016.508 | X3: =-COBERTURA_BOSQUE!V28 -> 87352.532 | Y3: =-COBERTURA_BOSQUE!W28 -> 86693.567 | ... AD3: =-COBERTURA_BOSQUE!AB28 -> 83473.227
B4: =+Q4/SUM(Q$4:Q$13) -> 0.024790941 | C4: B. Seco Andino | D4: Tierras de cultivo | E4: 2921.655 | F4: =+(E4+G4)/2 -> 2921.655 | G4: 2921.655 | H4: =+(G4+I4)/2 -> 2921.655 | I4: 2921.655 | J4: =+(I4+K4)/2 -> 2044.4325 | K4: 1167.21 | L4: =+(K4+M4)/2 -> 1052.55 | M4: 937.89 | N4: =1988.64+1394.28 -> 3382.92 | O4: =1988.64+1394.28 -> 3382.92 | P4: =865.755+1527.17 -> 2392.925 | Q4: =865.755+1527.17 -> 2392.925 | R4: =$B$3*R$3*$B4 -> 2037.9783 | S4: =$B$3*S$3*$B4 -> 2022.6061 | T4: =$B$3*T$3*$B4 -> 2007.3499 | U4: =$B$3*U$3*$B4 -> 1992.2087 | V4: =$B$3*V$3*$B4 -> 1977.1819 | W4: =$B$3*W$3*$B4 -> 1962.2703 | X4: =$B$3*X$3*$B4 -> 1947.4673 | Y4: =$B$3*Y$3*$B4 -> 1932.7761 | ... AD4: =$B$3*AD$3*$B4 -> 1860.9808
B5: =+Q5/SUM(Q$4:Q$13) -> 0.14961434 | C5: B. Seco Pluvioestacional | D5: Tierras de cultivo | E5: 14129.01 | F5: =+(E5+G5)/2 -> 14129.01 | G5: 14129.01 | H5: =+(G5+I5)/2 -> 14129.01 | I5: 14129.01 | J5: =+(I5+K5)/2 -> 13915.643 | K5: 13702.275 | L5: =+(K5+M5)/2 -> 11872.007 | M5: 10041.74 | N5: =7752.825+3440.39 -> 11193.215 | O5: =7752.825+3440.39 -> 11193.215 | P5: =9551.7+4889.7 -> 14441.4 | Q5: =9551.7+4889.7 -> 14441.4 | R5: =$B$3*R$3*$B5 -> 12299.282 | S5: =$B$3*S$3*$B5 -> 12206.51 | T5: =$B$3*T$3*$B5 -> 12114.438 | U5: =$B$3*U$3*$B5 -> 12023.061 | V5: =$B$3*V$3*$B5 -> 11932.373 | W5: =$B$3*W$3*$B5 -> 11842.381 | X5: =$B$3*X$3*$B5 -> 11753.045 | Y5: =$B$3*Y$3*$B5 -> 11664.383 | ... AD5: =$B$3*AD$3*$B5 -> 11231.095
B6: =+Q6/SUM(Q$4:Q$13) -> 0.090691689 | C6: B. Siempre verde andino Montano | D6: Tierras de cultivo | E6: 13631.91 | F6: =+(E6+G6)/2 -> 13631.91 | G6: 13631.91 | H6: =+(G6+I6)/2 -> 13631.91 | I6: 13631.91 | J6: =+(I6+K6)/2 -> 13444.095 | K6: 13256.28 | L6: =+(K6+M6)/2 -> 12232.395 | M6: 11208.51 | N6: =7882.965+3207.69 -> 11090.655 | O6: =7882.965+3207.69 -> 11090.655 | P6: =5354.01+3399.93 -> 8753.94 | Q6: =5354.01+3399.93 -> 8753.94 | R6: =$B$3*R$3*$B6 -> 7455.4529 | S6: =$B$3*S$3*$B6 -> 7399.2174 | T6: =$B$3*T$3*$B6 -> 7343.4062 | U6: =$B$3*U$3*$B6 -> 7288.016 | V6: =$B$3*V$3*$B6 -> 7233.0438 | W6: =$B$3*W$3*$B6 -> 7178.4933 | X6: =$B$3*X$3*$B6 -> 7124.3404 | Y6: =$B$3*Y$3*$B6 -> 7070.5962 | ... AD6: =$B$3*AD$3*$B6 -> 6807.9501
B7: =+Q7/SUM(Q$4:Q$13) -> 0.11556323 | C7: B. Siempre verde andino Pie montano | D7: Tierras de cultivo | E7: 19148.415 | F7: =+(E7+G7)/2 -> 19148.415 | G7: 19148.415 | H7: =+(G7+I7)/2 -> 19148.415 | I7: 19148.415 | J7: =+(I7+K7)/2 -> 15017.678 | K7: 10886.94 | L7: =+(K7+M7)/2 -> 10514.34 | M7: 10141.74 | N7: =6491.565+2369.97 -> 8861.535 | O7: =6491.565+2369.97 -> 8861.535 | P7: =5004.225+6150.42 -> 11154.645 | Q7: =5004.225+6150.42 -> 11154.645 | R7: =$B$3*R$3*$B7 -> 9500.0572 | S7: =$B$3*S$3*$B7 -> 9428.3995 | T7: =$B$3*T$3*$B7 -> 9357.2824 | U7: =$B$3*U$3*$B7 -> 9286.7019 | V7: =$B$3*V$3*$B7 -> 9216.654 | W7: =$B$3*W$3*$B7 -> 9147.1434 | X7: =$B$3*X$3*$B7 -> 9078.1395 | Y7: =$B$3*Y$3*$B7 -> 9009.6563 | ... AD7: =$B$3*AD$3*$B7 -> 8674.9814
B8: =+Q8/SUM(Q$4:Q$13) -> 0.014061659 | C8: B. Siempre verde andino de Ceja Andina | D8: Tierras de cultivo | E8: 2543.955 | F8: =+(E8+G8)/2 -> 2543.955 | G8: 2543.955 | H8: =+(G8+I8)/2 -> 2543.955 | I8: 2543.955 | J8: =+(I8+K8)/2 -> 2740.395 | K8: 2936.835 | L8: =+(K8+M8)/2 -> 2619.4975 | M8: 2302.16 | N8: =1523.34+1645.79 -> 3169.13 | O8: =1523.34+1645.79 -> 3169.13 | P8: =974.61+382.68 -> 1357.29 | Q8: =974.61+382.68 -> 1357.29 | R8: =$B$3*R$3*$B8 -> 1155.9608 | S8: =$B$3*S$3*$B8 -> 1147.2416 | T8: =$B$3*T$3*$B8 -> 1138.5881 | U8: =$B$3*U$3*$B8 -> 1129.9999 | V8: =$B$3*V$3*$B8 -> 1121.4765 | W8: =$B$3*W$3*$B8 -> 1113.0185 | X8: =$B$3*X$3*$B8 -> 1104.6221 | Y8: =$B$3*Y$3*$B8 -> 1096.2892 | ... AD8: =$B$3*AD$3*$B8 -> 1055.5661
B9: =+Q9/SUM(Q$4:Q$13) -> 0.29989774 | C9: B. Siempre verde de tierras bajas de la Amazonía | D9: Tierras de cultivo | E9: 22227.495 | F9: =+(E9+G9)/2 -> 22227.495 | G9: 22227.495 | H9: =+(G9+I9)/2 -> 22227.495 | I9: 22227.495 | J9: =+(I9+K9)/2 -> 24651.503 | K9: 27075.51 | L9: =+(K9+M9)/2 -> 25636.365 | M9: 24197.22 | N9: =20167.74+6831 -> 26998.74 | O9: =20167.74+6831 -> 26998.74 | P9: =5325.3+23622.08 -> 28947.38 | Q9: =5325.3+23622.08 -> 28947.38 | R9: =$B$3*R$3*$B9 -> 24653.565 | S9: =$B$3*S$3*$B9 -> 24467.606 | T9: =$B$3*T$3*$B9 -> 24283.051 | U9: =$B$3*U$3*$B9 -> 24099.888 | V9: =$B$3*V$3*$B9 -> 23918.106 | W9: =$B$3*W$3*$B9 -> 23737.72 | X9: =$B$3*X$3*$B9 -> 23558.648 | Y9: =$B$3*Y$3*$B9 -> 23380.927 | ... AD9: =$B$3*AD$3*$B9 -> 22512.414
B10: =+Q10/SUM(Q$4:Q$13) -> 0.24163891 | C10: B. Siempre verde de tierras bajas del Chocó | D10: Tierras de cultivo | E10: 19344.36 | F10: =+(E10+G10)/2 -> 19344.36 | G10: 19344.36 | H10: =+(G10+I10)/2 -> 19344.36 | I10: 19344.36 | J10: =+(I10+K10)/2 -> 19871.79 | K10: 20399.22 | L10: =+(K10+M10)/2 -> 19175.94 | M10: 17952.66 | N10: =8753.31+7859.07 -> 16612.38 | O10: =8753.31+7859.07 -> 16612.38 | P10: =15645.735+7678.26 -> 23323.995 | Q10: =15645.735+7678.26 -> 23323.995 | R10: =$B$3*R$3*$B10 -> 19864.306 | S10: =$B$3*S$3*$B10 -> 19714.472 | T10: =$B$3*T$3*$B10 -> 19565.769 | U10: =$B$3*U$3*$B10 -> 19418.188 | V10: =$B$3*V$3*$B10 -> 19271.72 | W10: =$B$3*W$3*$B10 -> 19126.375 | X10: =$B$3*X$3*$B10 -> 18982.09 | Y10: =$B$3*Y$3*$B10 -> 18838.894 | ... AD10: =$B$3*AD$3*$B10 -> 18139.1
B11: =+Q11/SUM(Q$4:Q$13) -> 0.0034144816 | C11: Manglar | D11: Tierras de cultivo | E11: 363.525 | F11: =+(E11+G11)/2 -> 363.525 | G11: 363.525 | H11: =+(G11+I11)/2 -> 363.525 | I11: 363.525 | J11: =+(I11+K11)/2 -> 561.315 | K11: 759.105 | L11: =+(K11+M11)/2 -> 538.2475 | M11: 317.39 | N11: =117.495+20.48 -> 137.975 | O11: =117.495+20.48 -> 137.975 | P11: =301.14+28.44 -> 329.58 | Q11: =301.14+28.44 -> 329.58 | R11: =$B$3*R$3*$B11 -> 280.69283 | S11: =$B$3*S$3*$B11 -> 278.5756 | T11: =$B$3*T$3*$B11 -> 276.47434 | U11: =$B$3*U$3*$B11 -> 274.38894 | V11: =$B$3*V$3*$B11 -> 272.31927 | W11: =$B$3*W$3*$B11 -> 270.26548 | X11: =$B$3*X$3*$B11 -> 268.22666 | Y11: =$B$3*Y$3*$B11 -> 266.20323 | ... AD11: =$B$3*AD$3*$B11 -> 256.31478
B12: =+Q12/SUM(Q$4:Q$13) -> 0.0069194586 | C12: Moretal | D12: Tierras de cultivo | E12: 423.675 | F12: =+(E12+G12)/2 -> 423.675 | G12: 423.675 | H12: =+(G12+I12)/2 -> 423.675 | I12: 423.675 | J12: =+(I12+K12)/2 -> 506.655 | K12: 589.635 | L12: =+(K12+M12)/2 -> 463.275 | M12: 336.915 | N12: =501.12+119.93 -> 621.05 | O12: =501.12+119.93 -> 621.05 | P12: =131.445+536.45 -> 667.895 | Q12: =131.445+536.45 -> 667.895 | R12: =$B$3*R$3*$B12 -> 568.82498 | S12: =$B$3*S$3*$B12 -> 564.5344 | T12: =$B$3*T$3*$B12 -> 560.2762 | U12: =$B$3*U$3*$B12 -> 556.05013 | V12: =$B$3*V$3*$B12 -> 551.85594 | W12: =$B$3*W$3*$B12 -> 547.69393 | X12: =$B$3*X$3*$B12 -> 543.56225 | Y12: =$B$3*Y$3*$B12 -> 539.46176 | ... AD12: =$B$3*AD$3*$B12 -> 519.42278
B13: =+Q13/SUM(Q$4:Q$13) -> 0.053407556 | C13: Plantación forestal | D13: Tierras de cultivo | E13: =794.7+1506.29 -> 2300.99 | F13: =+(E13+G13)/2 -> 2300.99 | G13: =794.7+1506.29 -> 2300.99 | H13: =+(G13+I13)/2 -> 2300.99 | I13: =794.7+1506.29 -> 2300.99 | J13: =+(I13+K13)/2 -> 6718.84 | K13: 11136.69 | L13: =+(K13+M13)/2 -> 9869.0625 | M13: 8601.435 | N13: =1787.94+115.79 -> 1903.73 | O13: =1787.94+115.79 -> 1903.73 | P13: =4917.56+237.56 -> 5155.12 | Q13: =4917.56+237.56 -> 5155.12 | R13: =$B$3*R$3*$B13 -> 4390.4521 | S13: =$B$3*S$3*$B13 -> 4357.3355 | T13: =$B$3*T$3*$B13 -> 4324.4688 | U13: =$B$3*U$3*$B13 -> 4291.85 | V13: =$B$3*V$3*$B13 -> 4259.4773 | W13: =$B$3*W$3*$B13 -> 4227.353 | X13: =$B$3*X$3*$B13 -> 4195.4628 | Y13: =$B$3*Y$3*$B13 -> 4163.8133 | ... AD13: =$B$3*AD$3*$B13 -> 4009.1433
C14: Pastizales | D14: Tierras de cultivo | E14: 24386 | F14: 24386 | G14: 24386 | H14: 24386 | I14: 24386 | J14: 38966.81 | K14: 53547.62 | L14: 34203.54 | M14: 14859.46 | N14: 32440.42 | O14: 32440.42 | P14: 23216.04 | Q14: 23216.04 | R14: 23216.04 | S14: 23216.04 | T14: 23216.04 | U14: 23216.04 | V14: 23216.04 | W14: 23216.04 | X14: 23216.04 | Y14: 23216.04 | Z14: 23216.04 | AA14: 23216.04 | AB14: 23216.04 | AC14: 23216.04 | AD14: 23216.04
C15: Humedales | D15: Tierras de cultivo | E15: 8320 | F15: 8320 | G15: 8320 | H15: 8320 | I15: 8320 | J15: 9268.21 | K15: 10216.42 | L15: 8473.63 | M15: 6730.84 | N15: 795.38 | O15: 795.38 | P15: 2562.975 | Q15: 2562.975 | R15: 2562.975 | S15: 2562.975 | T15: 2562.975 | U15: 2562.975 | V15: 2562.975 | W15: 2562.975 | X15: 2562.975 | Y15: 2562.975 | Z15: 2562.975 | AA15: 2562.975 | AB15: 2562.975 | AC15: 2562.975 | AD15: 2562.975
C16: Asentamientos | D16: Tierras de cultivo | E16: 0 | F16: =+(E16+G16)/2 -> 0 | G16: 0 | H16: =+(G16+I16)/2 -> 0 | I16: 0 | J16: =+(I16+K16)/2 -> 0 | K16: 0 | L16: =+(K16+M16)/2 -> 0 | M16: 0 | N16: 0 | O16: 0 | P16: 262.35 | Q16: 262.35 | R16: 262.35 | S16: 262.35 | T16: 262.35 | U16: 262.35 | V16: 262.35 | W16: 262.35 | X16: 262.35 | Y16: 262.35 | Z16: 262.35 | AA16: 262.35 | AB16: 262.35 | AC16: 262.35 | AD16: 262.35
C17: Otras tierras | D17: Tierras de cultivo | E17: =467.79+812.73 -> 1280.52 | F17: =+(E17+G17)/2 -> 1280.52 | G17: =467.79+812.73 -> 1280.52 | H17: =+(G17+I17)/2 -> 1280.52 | I17: =467.79+812.73 -> 1280.52 | J17: =+(I17+K17)/2 -> 5254.8525 | K17: 9229.185 | L17: =+(K17+M17)/2 -> 5389.7875 | M17: 1550.39 | N17: =533.61+75.11 -> 608.72 | O17: =533.61+75.11 -> 608.72 | P17: =1376.415+1986.75 -> 3363.165 | Q17: =1376.415+1986.75 -> 3363.165 | R17: =1376.415+1986.75 -> 3363.165 | S17: =1376.415+1986.75 -> 3363.165 | T17: =1376.415+1986.75 -> 3363.165 | U17: =1376.415+1986.75 -> 3363.165 | V17: =1376.415+1986.75 -> 3363.165 | W17: =1376.415+1986.75 -> 3363.165 | ... AD17: =1376.415+1986.75 -> 3363.165
C18: Tierras de cultivo | D18: Tierras de cultivo | E18: =583926.83+738244.33 -> 1322171.2 | F18: =+(E18+G18)/2 -> 1322171.2 | G18: =583926.83+738244.33 -> 1322171.2 | H18: =+(G18+I18)/2 -> 1322171.2 | I18: =583926.83+738244.33 -> 1322171.2 | J18: =+(I18+K18)/2 -> 2807097.8 | K18: 4292024.5 | L18: =+(K18+M18)/2 -> 4341301.7 | M18: 4390578.9 | N18: =4019308.83+459293.445 -> 4478602.3 | O18: =4019308.83+459293.445 -> 4478602.3 | P18: =3995904.69+571453.38 -> 4567358.1 | Q18: =3995904.69+571453.38 -> 4567358.1 | R18: =3995904.69+571453.38 -> 4567358.1 | S18: =3995904.69+571453.38 -> 4567358.1 | T18: =3995904.69+571453.38 -> 4567358.1 | U18: =3995904.69+571453.38 -> 4567358.1 | V18: =3995904.69+571453.38 -> 4567358.1 | W18: =3995904.69+571453.38 -> 4567358.1 | ... AD18: =3995904.69+571453.38 -> 4567358.1
B20: Pastizales
B21: =+SUM(Q22:Q31)/(SUM(Q22:Q31)+SUM(Q39:Q48)+SUM(Q56:Q65)+SUM(Q74:Q83)+SUM(Q4:Q13)) -> 0.011528251
B22: =+Q22/SUM(Q$22:Q$31) -> 0.0013092337 | C22: B. Seco Andino | D22: Pastizales | E22: 0 | F22: =+(E22+G22)/2 -> 0 | G22: 0 | H22: =+(G22+I22)/2 -> 0 | I22: 0 | J22: =+(I22+K22)/2 -> 0 | K22: 0 | L22: =+(K22+M22)/2 -> 80.8875 | M22: 161.775 | N22: 23.94 | O22: 23.94 | P22: 1.62 | Q22: 1.62 | R22: =$B$21*R$3*$B22 -> 1.3797026 | S22: =$B$21*S$3*$B22 -> 1.3692957 | T22: =$B$21*T$3*$B22 -> 1.3589673 | U22: =$B$21*U$3*$B22 -> 1.3487168 | V22: =$B$21*V$3*$B22 -> 1.3385437 | W22: =$B$21*W$3*$B22 -> 1.3284486 | X22: =$B$21*X$3*$B22 -> 1.3184271 | Y22: =$B$21*Y$3*$B22 -> 1.3084812 | ... AD22: =$B$21*AD$3*$B22 -> 1.259876
B23: =+Q23/SUM(Q$22:Q$31) -> 0.3765138 | C23: B. Seco Pluvioestacional | D23: Pastizales | E23: 0 | F23: =+(E23+G23)/2 -> 0 | G23: 0 | H23: =+(G23+I23)/2 -> 0 | I23: 0 | J23: =+(I23+K23)/2 -> 0 | K23: 0 | L23: =+(K23+M23)/2 -> 303.0975 | M23: 606.195 | N23: 194.535 | O23: 194.535 | P23: 465.885 | Q23: 465.885 | R23: =$B$21*R$3*$B23 -> 396.77947 | S23: =$B$21*S$3*$B23 -> 393.78661 | T23: =$B$21*T$3*$B23 -> 390.81634 | U23: =$B$21*U$3*$B23 -> 387.86847 | V23: =$B$21*V$3*$B23 -> 384.94285 | W23: =$B$21*W$3*$B23 -> 382.03967 | X23: =$B$21*X$3*$B23 -> 379.15765 | Y23: =$B$21*Y$3*$B23 -> 376.29738 | ... AD23: =$B$21*AD$3*$B23 -> 362.31935
B24: =+Q24/SUM(Q$22:Q$31) -> 0.063934247 | C24: B. Siempre verde andino Montano | D24: Pastizales | E24: 0 | F24: =+(E24+G24)/2 -> 0 | G24: 0 | H24: =+(G24+I24)/2 -> 0 | I24: 0 | J24: =+(I24+K24)/2 -> 0 | K24: 0 | L24: =+(K24+M24)/2 -> 195.885 | M24: 391.77 | N24: 846.225 | O24: 846.225 | P24: 79.11 | Q24: 79.11 | R24: =$B$21*R$3*$B24 -> 67.375476 | S24: =$B$21*S$3*$B24 -> 66.867272 | T24: =$B$21*T$3*$B24 -> 66.362902 | U24: =$B$21*U$3*$B24 -> 65.862337 | V24: =$B$21*V$3*$B24 -> 65.365549 | W24: =$B$21*W$3*$B24 -> 64.872572 | X24: =$B$21*X$3*$B24 -> 64.383189 | Y24: =$B$21*Y$3*$B24 -> 63.897498 | ... AD24: =$B$21*AD$3*$B24 -> 61.523946
B25: =+Q25/SUM(Q$22:Q$31) -> 0.016910936 | C25: B. Siempre verde andino Pie montano | D25: Pastizales | E25: 0 | F25: =+(E25+G25)/2 -> 0 | G25: 0 | H25: =+(G25+I25)/2 -> 0 | I25: 0 | J25: =+(I25+K25)/2 -> 0 | K25: 0 | L25: =+(K25+M25)/2 -> 34.0425 | M25: 68.085 | N25: 149.94 | O25: 149.94 | P25: 20.925 | Q25: 20.925 | R25: =$B$21*R$3*$B25 -> 17.821158 | S25: =$B$21*S$3*$B25 -> 17.686736 | T25: =$B$21*T$3*$B25 -> 17.553327 | U25: =$B$21*U$3*$B25 -> 17.420925 | V25: =$B$21*V$3*$B25 -> 17.289522 | W25: =$B$21*W$3*$B25 -> 17.159128 | X25: =$B$21*X$3*$B25 -> 17.029683 | Y25: =$B$21*Y$3*$B25 -> 16.901215 | ... AD25: =$B$21*AD$3*$B25 -> 16.273399
