Workbook

Sheet Indice
B2: NOMENCLATURA | E2: INDICE
B4: T | C4: Tendencial | E4: Metas
B5: Ini | C5: Iniciativas | E5: Gases
B6: Act | C6: Actividad | E6: T_INGEI_5CN
B7: Emi | C7: Emisiones | E7: T_5A1
B8: I | C8: Incondicional de la 2da NDC | E8: T_5A2
B9: I+C | C9: Incondicional + Condicional de 2da NDC | E9: T_Compostaje
B10: PTAR | C10: Plantas de Tratamiento de Aguas Residuales | E10: T_Incineracion
B11: ARI | C11: Aguas residuales inductriales | E11: T_5D1
B12: PPC | C12: Producción per cápita de residuos sólidos | E12: T_5D2
B13: 5CN | C13: Quinta Comunicación Nacional | E13: Ini_I+C_CapturaMetano
B14: INGEI | C14: Inventario Nacional de Gases de Efecto Invernadero | E14: Ini_I+C_Reduccion
B15: 5A1 | C15: Categoría IPCC Sitios de disposición de residuos sólidos gestionados | E15: Ini_I_Compostaje
... B18: 5D2 | C18: Categoría IPCC Aguas residuales industriales | E18: Ini_I+C_PTAR
E19: Ini_I+C_PTAR_ARI
E20: Act_T_Solidos
E21: Act_T_Poblacion_PPC
E22: Act_I_Solidos
E23: Act_I+C_Solidos
E24: Act_T_Aguas
E25: Act_I_Aguas
E26: Act_I+C_Aguas
E27: Ajuste_T_Iniciativas1eraNDC
E28: Emi_T_ajustado
E29: Emi_I
E30: Emi_I+C

Sheet Metas
C1: 2010 | D1: 2011 | E1: 2012 | F1: 2013 | G1: 2014 | H1: 2015 | I1: 2016 | J1: 2017 | K1: 2018 | L1: 2019 | M1: 2020 | N1: 2021 | O1: 2022 | P1: 2023 | Q1: 2024 | R1: 2025 | S1: 2026 | T1: 2027 | U1: 2028 | V1: 2029 | W1: 2030 | X1: 2031 | Y1: 2032 | Z1: 2033 | AA1: 2034 | AB1: 2035
B4: Emisiones [GgCO2e]
B7: Nuevo Tendencial 1era NDC = Tendencial 5ta Comunicación y PLANMICC - Iniciativas Condicionales 1era NDC | C7: =SUM(C8:C13) -> 2271.8591 | D7: =SUM(D8:D13) -> 2629.2208 | E7: =SUM(E8:E13) -> 2987.2011 | F7: =SUM(F8:F13) -> 3064.3062 | G7: =SUM(G8:G13) -> 3141.9913 | H7: =SUM(H8:H13) -> 3540.6 | I7: =SUM(I8:I13) -> 3939.5088 | J7: =SUM(J8:J13) -> 4157.2022 | ... AB7: =SUM(AB8:AB13) -> 14533.24
B8: 5.A.1. Sitios de disposición de residuos sólidos gestionados | C8: =Emi_T_ajustado!G7 -> 892.3716 | D8: =Emi_T_ajustado!H7 -> 1032.8312 | E8: =Emi_T_ajustado!I7 -> 1173.3316 | F8: =Emi_T_ajustado!J7 -> 1229.7626 | G8: =Emi_T_ajustado!K7 -> 1286.3505 | H8: =Emi_T_ajustado!L7 -> 1720.1571 | I8: =Emi_T_ajustado!M7 -> 2154.1216 | J8: =Emi_T_ajustado!N7 -> 2435.0344 | ... AB8: =Emi_T_ajustado!AF7 -> 10502.095
B9: 5.A.2. Sitios de disposición de residuos sólidos no gestionados | C9: =Emi_T_ajustado!G8 -> 806.15385 | D9: =Emi_T_ajustado!H8 -> 843.58052 | E9: =Emi_T_ajustado!I8 -> 881.17352 | F9: =Emi_T_ajustado!J8 -> 1020.9232 | G9: =Emi_T_ajustado!K8 -> 1160.8584 | H9: =Emi_T_ajustado!L8 -> 926.8017 | I9: =Emi_T_ajustado!M8 -> 692.75696 | J9: =Emi_T_ajustado!N8 -> 596.70116 | ... AB9: =Emi_T_ajustado!AF8 -> 1469.5414
B10: 5.B.1. Compostaje | C10: =Emi_T_ajustado!G9 -> 1.05325 | D10: =Emi_T_ajustado!H9 -> 1.2256 | E10: =Emi_T_ajustado!I9 -> 1.39795 | F10: =Emi_T_ajustado!J9 -> 4.2513 | G10: =Emi_T_ajustado!K9 -> 7.1238 | H10: =Emi_T_ajustado!L9 -> 6.1663 | I10: =Emi_T_ajustado!M9 -> 5.2088 | J10: =Emi_T_ajustado!N9 -> 5.84075 | ... AB10: =Emi_T_ajustado!AF9 -> 10.55165
B11: 5.C.1. Incineración de residuos | C11: =Emi_T_ajustado!G10 -> 13.36608 | D11: =Emi_T_ajustado!H10 -> 13.87682 | E11: =Emi_T_ajustado!I10 -> 14.482 | F11: =Emi_T_ajustado!J10 -> 14.79708 | G11: =Emi_T_ajustado!K10 -> 15.23014 | H11: =Emi_T_ajustado!L10 -> 15.12672 | I11: =Emi_T_ajustado!M10 -> 15.1592 | J11: =Emi_T_ajustado!N10 -> 15.3273 | ... AB11: =Emi_T_ajustado!AF10 -> 25.39264
B12: 5.D.1. Aguas residuales domesticas | C12: =Emi_T_ajustado!G11+Emi_T_ajustado!G12 -> 405.33434 | D12: =Emi_T_ajustado!H11+Emi_T_ajustado!H12 -> 439.78666 | E12: =Emi_T_ajustado!I11+Emi_T_ajustado!I12 -> 474.55598 | F12: =Emi_T_ajustado!J11+Emi_T_ajustado!J12 -> 480.97206 | G12: =Emi_T_ajustado!K11+Emi_T_ajustado!K12 -> 487.4184 | H12: =Emi_T_ajustado!L11+Emi_T_ajustado!L12 -> 490.00818 | I12: =Emi_T_ajustado!M11+Emi_T_ajustado!M12 -> 492.59226 | J12: =Emi_T_ajustado!N11+Emi_T_ajustado!N12 -> 499.28854 | ... AB12: =Emi_T_ajustado!AF11+Emi_T_ajustado!AF12 -> 1256.3494
B13: 5.D.2. Aguas residuales industriales | C13: =Emi_T_ajustado!G13 -> 153.58 | D13: =Emi_T_ajustado!H13 -> 297.92 | E13: =Emi_T_ajustado!I13 -> 442.26 | F13: =Emi_T_ajustado!J13 -> 313.6 | G13: =Emi_T_ajustado!K13 -> 185.01 | H13: =Emi_T_ajustado!L13 -> 382.34 | I13: =Emi_T_ajustado!M13 -> 579.67 | J13: =Emi_T_ajustado!N13 -> 605.01 | ... AB13: =Emi_T_ajustado!AF13 -> 1269.31
B14: NDC Incondicional de la 2da NDC (5ta Comunicación) | C14: =SUM(C15:C20) -> 2271.8591 | D14: =SUM(D15:D20) -> 2629.2208 | E14: =SUM(E15:E20) -> 2987.2011 | F14: =SUM(F15:F20) -> 3064.3062 | G14: =SUM(G15:G20) -> 3141.9913 | H14: =SUM(H15:H20) -> 3540.6 | I14: =SUM(I15:I20) -> 3939.5088 | J14: =SUM(J15:J20) -> 4157.2022 | ... AB14: =SUM(AB15:AB20) -> 14426.244
B15: 5.A.1. Sitios de disposición de residuos sólidos gestionados | C15: =Emi_I!G7 -> 892.3716 | D15: =Emi_I!H7 -> 1032.8312 | E15: =Emi_I!I7 -> 1173.3316 | F15: =Emi_I!J7 -> 1229.7626 | G15: =Emi_I!K7 -> 1286.3505 | H15: =Emi_I!L7 -> 1720.1571 | I15: =Emi_I!M7 -> 2154.1216 | J15: =Emi_I!N7 -> 2435.0344 | ... AB15: =Emi_I!AF7 -> 10488.495
B16: 5.A.2. Sitios de disposición de residuos sólidos no gestionados | C16: =Emi_I!G8 -> 806.15385 | D16: =Emi_I!H8 -> 843.58052 | E16: =Emi_I!I8 -> 881.17352 | F16: =Emi_I!J8 -> 1020.9232 | G16: =Emi_I!K8 -> 1160.8584 | H16: =Emi_I!L8 -> 926.8017 | I16: =Emi_I!M8 -> 692.75696 | J16: =Emi_I!N8 -> 596.70116 | ... AB16: =Emi_I!AF8 -> 1469.5414
B17: 5.B.1. Compostaje | C17: =Emi_I!G9 -> 1.05325 | D17: =Emi_I!H9 -> 1.2256 | E17: =Emi_I!I9 -> 1.39795 | F17: =Emi_I!J9 -> 4.2513 | G17: =Emi_I!K9 -> 7.1238 | H17: =Emi_I!L9 -> 6.1663 | I17: =Emi_I!M9 -> 5.2088 | J17: =Emi_I!N9 -> 5.84075 | ... AB17: =Emi_I!AF9 -> 13.15605
B18: 5.C.1. Incineración de residuos | C18: =Emi_I!G10 -> 13.36608 | D18: =Emi_I!H10 -> 13.87682 | E18: =Emi_I!I10 -> 14.482 | F18: =Emi_I!J10 -> 14.79708 | G18: =Emi_I!K10 -> 15.23014 | H18: =Emi_I!L10 -> 15.12672 | I18: =Emi_I!M10 -> 15.1592 | J18: =Emi_I!N10 -> 15.3273 | ... AB18: =Emi_I!AF10 -> 25.39264
B19: 5.D.1. Aguas residuales domesticas | C19: =Emi_I!G11+Emi_I!G12 -> 405.33434 | D19: =Emi_I!H11+Emi_I!H12 -> 439.78666 | E19: =Emi_I!I11+Emi_I!I12 -> 474.55598 | F19: =Emi_I!J11+Emi_I!J12 -> 480.97206 | G19: =Emi_I!K11+Emi_I!K12 -> 487.4184 | H19: =Emi_I!L11+Emi_I!L12 -> 490.00818 | I19: =Emi_I!M11+Emi_I!M12 -> 492.59226 | J19: =Emi_I!N11+Emi_I!N12 -> 499.28854 | ... AB19: =Emi_I!AF11+Emi_I!AF12 -> 1168.3494
B20: 5.D.2. Aguas residuales industriales | C20: =Emi_I!G13 -> 153.58 | D20: =Emi_I!H13 -> 297.92 | E20: =Emi_I!I13 -> 442.26 | F20: =Emi_I!J13 -> 313.6 | G20: =Emi_I!K13 -> 185.01 | H20: =Emi_I!L13 -> 382.34 | I20: =Emi_I!M13 -> 579.67 | J20: =Emi_I!N13 -> 605.01 | ... AB20: =Emi_I!AF13 -> 1261.31
B21: NDC Incondicional + Condicional de la 2da NDC (5ta Comunicación) | C21: =SUM(C22:C27) -> 2271.8591 | D21: =SUM(D22:D27) -> 2629.2208 | E21: =SUM(E22:E27) -> 2987.2011 | F21: =SUM(F22:F27) -> 3064.3062 | G21: =SUM(G22:G27) -> 3141.9913 | H21: =SUM(H22:H27) -> 3540.6 | I21: =SUM(I22:I27) -> 3939.5088 | J21: =SUM(J22:J27) -> 4157.2022 | ... AB21: =SUM(AB22:AB27) -> 14214.816
B22: 5.A.1. Sitios de disposición de residuos sólidos gestionados | C22: ='Emi_I+C'!G7 -> 892.3716 | D22: ='Emi_I+C'!H7 -> 1032.8312 | E22: ='Emi_I+C'!I7 -> 1173.3316 | F22: ='Emi_I+C'!J7 -> 1229.7626 | G22: ='Emi_I+C'!K7 -> 1286.3505 | H22: ='Emi_I+C'!L7 -> 1720.1571 | I22: ='Emi_I+C'!M7 -> 2154.1216 | J22: ='Emi_I+C'!N7 -> 2435.0344 | ... AB22: ='Emi_I+C'!AF7 -> 10335.305
B23: 5.A.2. Sitios de disposición de residuos sólidos no gestionados | C23: ='Emi_I+C'!G8 -> 806.15385 | D23: ='Emi_I+C'!H8 -> 843.58052 | E23: ='Emi_I+C'!I8 -> 881.17352 | F23: ='Emi_I+C'!J8 -> 1020.9232 | G23: ='Emi_I+C'!K8 -> 1160.8584 | H23: ='Emi_I+C'!L8 -> 926.8017 | I23: ='Emi_I+C'!M8 -> 692.75696 | J23: ='Emi_I+C'!N8 -> 596.70116 | ... AB23: ='Emi_I+C'!AF8 -> 1469.5414
B24: 5.B.1. Compostaje | C24: ='Emi_I+C'!G9 -> 1.05325 | D24: ='Emi_I+C'!H9 -> 1.2256 | E24: ='Emi_I+C'!I9 -> 1.39795 | F24: ='Emi_I+C'!J9 -> 4.2513 | G24: ='Emi_I+C'!K9 -> 7.1238 | H24: ='Emi_I+C'!L9 -> 6.1663 | I24: ='Emi_I+C'!M9 -> 5.2088 | J24: ='Emi_I+C'!N9 -> 5.84075 | ... AB24: ='Emi_I+C'!AF9 -> 14.91785
B25: 5.C.1. Incineración de residuos | C25: ='Emi_I+C'!G10 -> 13.36608 | D25: ='Emi_I+C'!H10 -> 13.87682 | E25: ='Emi_I+C'!I10 -> 14.482 | F25: ='Emi_I+C'!J10 -> 14.79708 | G25: ='Emi_I+C'!K10 -> 15.23014 | H25: ='Emi_I+C'!L10 -> 15.12672 | I25: ='Emi_I+C'!M10 -> 15.1592 | J25: ='Emi_I+C'!N10 -> 15.3273 | ... AB25: ='Emi_I+C'!AF10 -> 25.39264
B26: 5.D.1. Aguas residuales domesticas | C26: ='Emi_I+C'!G11+'Emi_I+C'!G12 -> 405.33434 | D26: ='Emi_I+C'!H11+'Emi_I+C'!H12 -> 439.78666 | E26: ='Emi_I+C'!I11+'Emi_I+C'!I12 -> 474.55598 | F26: ='Emi_I+C'!J11+'Emi_I+C'!J12 -> 480.97206 | G26: ='Emi_I+C'!K11+'Emi_I+C'!K12 -> 487.4184 | H26: ='Emi_I+C'!L11+'Emi_I+C'!L12 -> 490.00818 | I26: ='Emi_I+C'!M11+'Emi_I+C'!M12 -> 492.59226 | J26: ='Emi_I+C'!N11+'Emi_I+C'!N12 -> 499.28854 | ... AB26: ='Emi_I+C'!AF11+'Emi_I+C'!AF12 -> 1108.3494
B27: 5.D.2. Aguas residuales industriales | C27: ='Emi_I+C'!G13 -> 153.58 | D27: ='Emi_I+C'!H13 -> 297.92 | E27: ='Emi_I+C'!I13 -> 442.26 | F27: ='Emi_I+C'!J13 -> 313.6 | G27: ='Emi_I+C'!K13 -> 185.01 | H27: ='Emi_I+C'!L13 -> 382.34 | I27: ='Emi_I+C'!M13 -> 579.67 | J27: ='Emi_I+C'!N13 -> 605.01 | ... AB27: ='Emi_I+C'!AF13 -> 1261.31
B30: Meta 2da NDC [GgCO2e]
B32: NDC Incondicional de la 2da NDC (5ta Comunicación) | C32: =C14-C7 -> 0 | D32: =D14-D7 -> 0 | E32: =E14-E7 -> 0 | F32: =F14-F7 -> 0 | G32: =G14-G7 -> 0 | H32: =H14-H7 -> 0 | I32: =I14-I7 -> 0 | J32: =J14-J7 -> 0 | ... AB32: =AB14-AB7 -> -106.9956
B33: NDC Incondicional + Condicional de la 2da NDC (5ta Comunicación) | C33: =C21-C7 -> 0 | D33: =D21-D7 -> 0 | E33: =E21-E7 -> 0 | F33: =F21-F7 -> 0 | G33: =G21-G7 -> 0 | H33: =H21-H7 -> 0 | I33: =I21-I7 -> 0 | J33: =J21-J7 -> 0 | ... AB33: =AB21-AB7 -> -318.42364
B36: Meta 2da NDC [%]
B38: NDC Incondicional de la 2da NDC (5ta Comunicación) | C38: =(C14-C7)/C7 -> 0 | D38: =(D14-D7)/D7 -> 0 | E38: =(E14-E7)/E7 -> 0 | F38: =(F14-F7)/F7 -> 0 | G38: =(G14-G7)/G7 -> 0 | H38: =(H14-H7)/H7 -> 0 | I38: =(I14-I7)/I7 -> 0 | J38: =(J14-J7)/J7 -> 0 | ... AB38: =(AB14-AB7)/AB7 -> -0.0073621298
B39: NDC Incondicional + Condicional de la 2da NDC (5ta Comunicación) | C39: =(C21-C7)/C7 -> 0 | D39: =(D21-D7)/D7 -> 0 | E39: =(E21-E7)/E7 -> 0 | F39: =(F21-F7)/F7 -> 0 | G39: =(G21-G7)/G7 -> 0 | H39: =(H21-H7)/H7 -> 0 | I39: =(I21-I7)/I7 -> 0 | J39: =(J21-J7)/J7 -> 0 | ... AB39: =(AB21-AB7)/AB7 -> -0.021910024

Sheet Gases
C6: GgCO2e
D7: 2010 | E7: 2011 | F7: 2012 | G7: 2013 | H7: 2014 | I7: 2015 | J7: 2016 | K7: 2017 | L7: 2018 | M7: 2019 | N7: 2020 | O7: 2021 | P7: 2022 | Q7: 2023 | R7: 2024 | S7: 2025 | T7: 2026 | U7: 2027 | V7: 2028 | W7: 2029 | X7: 2030 | Y7: 2031 | Z7: 2032 | AA7: 2033 | AB7: 2034 | AC7: 2035
C8: Nuevo Tendencial 1era NDC = Tendencial 5ta Comunicación y PLANMICC - Iniciativas Condicionales 1era NDC | D8: =SUM(D9:D11) -> 2275.5036 | E8: =SUM(E9:E11) -> 2626.8409 | F8: =SUM(F9:F11) -> 2985.2394 | G8: =SUM(G9:G11) -> 3066.0798 | H8: =SUM(H9:H11) -> 3147.0403 | I8: =SUM(I9:I11) -> 3544.354 | J8: =SUM(J9:J11) -> 3941.8452 | K8: =SUM(K9:K11) -> 4155.283 | ... AC8: =SUM(AC9:AC11) -> 14533.262
C9: GgCO2e por CO2 | D9: =SUM(Emi_T_ajustado!G23:G29)*1 -> 13.18135 | E9: =SUM(Emi_T_ajustado!H23:H29)*1 -> 13.68088 | F9: =SUM(Emi_T_ajustado!I23:I29)*1 -> 14.27192 | G9: =SUM(Emi_T_ajustado!J23:J29)*1 -> 14.57892 | H9: =SUM(Emi_T_ajustado!K23:K29)*1 -> 15.00075 | I9: =SUM(Emi_T_ajustado!L23:L29)*1 -> 14.90048 | J9: =SUM(Emi_T_ajustado!M23:M29)*1 -> 14.93184 | K9: =SUM(Emi_T_ajustado!N23:N29)*1 -> 15.09588 | ... AC9: =SUM(Emi_T_ajustado!AF23:AF29)*1 -> 24.79904
C10: GgCO2e por CH4 | D10: =SUM(Emi_T_ajustado!G39:G45)*28 -> 2081.6029 | E10: =SUM(Emi_T_ajustado!H39:H45)*28 -> 2429.4222 | F10: =SUM(Emi_T_ajustado!I39:I45)*28 -> 2785.8835 | G10: =SUM(Emi_T_ajustado!J39:J45)*28 -> 2861.8722 | H10: =SUM(Emi_T_ajustado!K39:K45)*28 -> 2937.8555 | I10: =SUM(Emi_T_ajustado!L39:L45)*28 -> 3337.5538 | J10: =SUM(Emi_T_ajustado!M39:M45)*28 -> 3737.2952 | K10: =SUM(Emi_T_ajustado!N39:N45)*28 -> 3949.8827 | ... AC10: =SUM(Emi_T_ajustado!AF39:AF45)*28 -> 14090.65
C11: GgCO2e por N20 | D11: =SUM(Emi_T_ajustado!G55:G61)*265 -> 180.7194 | E11: =SUM(Emi_T_ajustado!H55:H61)*265 -> 183.73775 | F11: =SUM(Emi_T_ajustado!I55:I61)*265 -> 185.08395 | G11: =SUM(Emi_T_ajustado!J55:J61)*265 -> 189.6287 | H11: =SUM(Emi_T_ajustado!K55:K61)*265 -> 194.18405 | I11: =SUM(Emi_T_ajustado!L55:L61)*265 -> 191.89975 | J11: =SUM(Emi_T_ajustado!M55:M61)*265 -> 189.6181 | K11: =SUM(Emi_T_ajustado!N55:N61)*265 -> 190.30445 | ... AC11: =SUM(Emi_T_ajustado!AF55:AF61)*265 -> 417.81225
C12: NDC Incondicional de la 2da NDC (5ta Comunicación) | D12: =SUM(D13:D15) -> 2273.3803 | E12: =SUM(E13:E15) -> 2627.9548 | F12: =SUM(F13:F15) -> 2986.179 | G12: =SUM(G13:G15) -> 3064.6357 | H12: =SUM(H13:H15) -> 3144.0684 | I12: =SUM(I13:I15) -> 3541.6387 | J12: =SUM(J13:J15) -> 3939.8636 | K12: =SUM(K13:K15) -> 4156.5825 | ... AC12: =SUM(AC13:AC15) -> 14425.163
C13: GgCO2e por CO2 | D13: =SUM(Emi_I!G22:G28)*1 -> 13.18135 | E13: =SUM(Emi_I!H22:H28)*1 -> 13.68088 | F13: =SUM(Emi_I!I22:I28)*1 -> 14.27192 | G13: =SUM(Emi_I!J22:J28)*1 -> 14.57892 | H13: =SUM(Emi_I!K22:K28)*1 -> 15.00075 | I13: =SUM(Emi_I!L22:L28)*1 -> 14.90048 | J13: =SUM(Emi_I!M22:M28)*1 -> 14.93184 | K13: =SUM(Emi_I!N22:N28)*1 -> 15.09588 | ... AC13: =SUM(Emi_I!AF22:AF28)*1 -> 24.79904
C14: GgCO2e por CH4 | D14: =SUM(Emi_I!G37:G43)*28 -> 2080.4599 | E14: =SUM(Emi_I!H37:H43)*28 -> 2431.5326 | F14: =SUM(Emi_I!I37:I43)*28 -> 2787.8263 | G14: =SUM(Emi_I!J37:J43)*28 -> 2861.4495 | H14: =SUM(Emi_I!K37:K43)*28 -> 2935.9233 | I14: =SUM(Emi_I!L37:L43)*28 -> 3335.8679 | J14: =SUM(Emi_I!M37:M43)*28 -> 3736.3328 | K14: =SUM(Emi_I!N37:N43)*28 -> 3952.2036 | ... AC14: =SUM(Emi_I!AF37:AF43)*28 -> 14011.469
C15: GgCO2e por N20 | D15: =SUM(Emi_I!G52:G58)*265 -> 179.739 | E15: =SUM(Emi_I!H52:H58)*265 -> 182.74139 | F15: =SUM(Emi_I!I52:I58)*265 -> 184.08075 | G15: =SUM(Emi_I!J52:J58)*265 -> 188.60726 | H15: =SUM(Emi_I!K52:K58)*265 -> 193.14437 | I15: =SUM(Emi_I!L52:L58)*265 -> 190.87033 | J15: =SUM(Emi_I!M52:M58)*265 -> 188.59894 | K15: =SUM(Emi_I!N52:N58)*265 -> 189.28301 | ... AC15: =SUM(Emi_I!AF52:AF58)*265 -> 388.89532
C16: NDC Incondicional + Condicional de la 2da NDC (5ta Comunicación) | D16: =SUM(D17:D19) -> 2273.3803 | E16: =SUM(E17:E19) -> 2627.9548 | F16: =SUM(F17:F19) -> 2986.179 | G16: =SUM(G17:G19) -> 3064.6357 | H16: =SUM(H17:H19) -> 3144.0684 | I16: =SUM(I17:I19) -> 3541.6387 | J16: =SUM(J17:J19) -> 3939.8636 | K16: =SUM(K17:K19) -> 4156.5825 | ... AC16: =SUM(AC17:AC19) -> 14213.004
C17: GgCO2e por CO2 | D17: =SUM('Emi_I+C'!G22:G28)*1 -> 13.18135 | E17: =SUM('Emi_I+C'!H22:H28)*1 -> 13.68088 | F17: =SUM('Emi_I+C'!I22:I28)*1 -> 14.27192 | G17: =SUM('Emi_I+C'!J22:J28)*1 -> 14.57892 | H17: =SUM('Emi_I+C'!K22:K28)*1 -> 15.00075 | I17: =SUM('Emi_I+C'!L22:L28)*1 -> 14.90048 | J17: =SUM('Emi_I+C'!M22:M28)*1 -> 14.93184 | K17: =SUM('Emi_I+C'!N22:N28)*1 -> 15.09588 | ... AC17: =SUM('Emi_I+C'!AF22:AF28)*1 -> 24.79904
C18: GgCO2e por CH4 | D18: =SUM('Emi_I+C'!G37:G43)*28 -> 2080.4599 | E18: =SUM('Emi_I+C'!H37:H43)*28 -> 2431.5326 | F18: =SUM('Emi_I+C'!I37:I43)*28 -> 2787.8263 | G18: =SUM('Emi_I+C'!J37:J43)*28 -> 2861.4495 | H18: =SUM('Emi_I+C'!K37:K43)*28 -> 2935.9233 | I18: =SUM('Emi_I+C'!L37:L43)*28 -> 3335.8679 | J18: =SUM('Emi_I+C'!M37:M43)*28 -> 3736.3328 | K18: =SUM('Emi_I+C'!N37:N43)*28 -> 3952.2036 | ... AC18: =SUM('Emi_I+C'!AF37:AF43)*28 -> 13819.025
C19: GgCO2e por N20 | D19: =SUM('Emi_I+C'!G52:G58)*265 -> 179.739 | E19: =SUM('Emi_I+C'!H52:H58)*265 -> 182.74139 | F19: =SUM('Emi_I+C'!I52:I58)*265 -> 184.08075 | G19: =SUM('Emi_I+C'!J52:J58)*265 -> 188.60726 | H19: =SUM('Emi_I+C'!K52:K58)*265 -> 193.14437 | I19: =SUM('Emi_I+C'!L52:L58)*265 -> 190.87033 | J19: =SUM('Emi_I+C'!M52:M58)*265 -> 188.59894 | K19: =SUM('Emi_I+C'!N52:N58)*265 -> 189.28301 | ... AC19: =SUM('Emi_I+C'!AF52:AF58)*265 -> 369.17924
C21: %
D22: 2010 | E22: 2011 | F22: 2012 | G22: 2013 | H22: 2014 | I22: 2015 | J22: 2016 | K22: 2017 | L22: 2018 | M22: 2019 | N22: 2020 | O22: 2021 | P22: 2022 | Q22: 2023 | R22: 2024 | S22: 2025 | T22: 2026 | U22: 2027 | V22: 2028 | W22: 2029 | X22: 2030 | Y22: 2031 | Z22: 2032 | AA22: 2033 | AB22: 2034 | AC22: 2035
C23: Nuevo Tendencial 1era NDC = Tendencial 5ta Comunicación y PLANMICC - Iniciativas Condicionales 1era NDC | D23: =D8/D8 -> 1 | E23: =E8/E8 -> 1 | F23: =F8/F8 -> 1 | G23: =G8/G8 -> 1 | H23: =H8/H8 -> 1 | I23: =I8/I8 -> 1 | J23: =J8/J8 -> 1 | K23: =K8/K8 -> 1 | ... AC23: =AC8/AC8 -> 1
C24: GgCO2e por CO2 | D24: =D9/D8 -> 0.0057927176 | E24: =E9/E8 -> 0.0052081114 | F24: =F9/F8 -> 0.0047808293 | G24: =G9/G8 -> 0.0047549056 | H24: =H9/H8 -> 0.0047666215 | I24: =I9/I8 -> 0.0042040044 | J24: =J9/J8 -> 0.0037880331 | K24: =K9/K8 -> 0.0036329366 | ... AC24: =AC9/AC8 -> 0.0017063644
C25: GgCO2e por CH4 | D25: =D10/D8 -> 0.91478777 | E25: =E10/E8 -> 0.92484561 | F25: =F10/F8 -> 0.93321947 | G25: =G10/G8 -> 0.93339781 | H25: =H10/H8 -> 0.93352967 | I25: =I10/I8 -> 0.94165362 | J25: =J10/J8 -> 0.94810807 | K25: =K10/K8 -> 0.95056887 | ... AC25: =AC10/AC8 -> 0.96954494
C26: GgCO2e por N20 | D26: =D11/D8 -> 0.079419517 | E26: =E11/E8 -> 0.069946281 | F26: =F11/F8 -> 0.061999701 | G26: =G11/G8 -> 0.061847282 | H26: =H11/H8 -> 0.061703707 | I26: =I11/I8 -> 0.054142376 | J26: =J11/J8 -> 0.048103893 | K26: =K11/K8 -> 0.045798192 | ... AC26: =AC11/AC8 -> 0.028748691
C27: NDC Incondicional de la 2da NDC (5ta Comunicación) | D27: =D12/D12 -> 1 | E27: =E12/E12 -> 1 | F27: =F12/F12 -> 1 | G27: =G12/G12 -> 1 | H27: =H12/H12 -> 1 | I27: =I12/I12 -> 1 | J27: =J12/J12 -> 1 | K27: =K12/K12 -> 1 | ... AC27: =AC12/AC12 -> 1
C28: GgCO2e por CO2 | D28: =D13/D12 -> 0.0057981281 | E28: =E13/E12 -> 0.0052059038 | F28: =F13/F12 -> 0.004779325 | G28: =G13/G12 -> 0.0047571461 | H28: =H13/H12 -> 0.0047711271 | I28: =I13/I12 -> 0.0042072275 | J28: =J13/J12 -> 0.0037899383 | K28: =K13/K12 -> 0.0036318009 | ... AC28: =AC13/AC12 -> 0.0017191514
C29: GgCO2e por CH4 | D29: =D14/D12 -> 0.91513943 | E29: =E14/E12 -> 0.9252566 | F29: =F14/F12 -> 0.93357643 | G29: =G14/G12 -> 0.93369973 | H29: =H14/H12 -> 0.93379752 | I29: =I14/I12 -> 0.94189955 | J29: =J14/J12 -> 0.94834065 | K29: =K14/K12 -> 0.95083007 | ... AC29: =AC14/AC12 -> 0.97132134
C30: GgCO2e por N20 | D30: =D15/D12 -> 0.079062445 | E30: =E15/E12 -> 0.069537493 | F30: =F15/F12 -> 0.061644245 | G30: =G15/G12 -> 0.061543125 | H30: =H15/H12 -> 0.061431351 | I30: =I15/I12 -> 0.053893224 | J30: =J15/J12 -> 0.047869409 | K30: =K15/K12 -> 0.045538134 | ... AC30: =AC15/AC12 -> 0.02695951
C31: NDC Incondicional + Condicional de la 2da NDC (5ta Comunicación) | D31: =D16/D16 -> 1 | E31: =E16/E16 -> 1 | F31: =F16/F16 -> 1 | G31: =G16/G16 -> 1 | H31: =H16/H16 -> 1 | I31: =I16/I16 -> 1 | J31: =J16/J16 -> 1 | K31: =K16/K16 -> 1 | ... AC31: =AC16/AC16 -> 1
C32: GgCO2e por CO2 | D32: =D17/D16 -> 0.0057981281 | E32: =E17/E16 -> 0.0052059038 | F32: =F17/F16 -> 0.004779325 | G32: =G17/G16 -> 0.0047571461 | H32: =H17/H16 -> 0.0047711271 | I32: =I17/I16 -> 0.0042072275 | J32: =J17/J16 -> 0.0037899383 | K32: =K17/K16 -> 0.0036318009 | ... AC32: =AC17/AC16 -> 0.0017448134
C33: GgCO2e por CH4 | D33: =D18/D16 -> 0.91513943 | E33: =E18/E16 -> 0.9252566 | F33: =F18/F16 -> 0.93357643 | G33: =G18/G16 -> 0.93369973 | H33: =H18/H16 -> 0.93379752 | I33: =I18/I16 -> 0.94189955 | J33: =J18/J16 -> 0.94834065 | K33: =K18/K16 -> 0.95083007 | ... AC33: =AC18/AC16 -> 0.97228044
C34: GgCO2e por N20 | D34: =D19/D16 -> 0.079062445 | E34: =E19/E16 -> 0.069537493 | F34: =F19/F16 -> 0.061644245 | G34: =G19/G16 -> 0.061543125 | H34: =H19/H16 -> 0.061431351 | I34: =I19/I16 -> 0.053893224 | J34: =J19/J16 -> 0.047869409 | K34: =K19/K16 -> 0.045538134 | ... AC34: =AC19/AC16 -> 0.025974751

Sheet T_INGEI_5CN
B3: Original
B4: GgCO2e | C4: 2010 | D4: 2011 | E4: 2012 | F4: 2013 | G4: 2014 | H4: 2015 | I4: 2016 | J4: 2017 | K4: 2018 | L4: 2019 | M4: 2020 | N4: 2021 | O4: 2022
B5: 5. Residuos | C5: 2271.9 | E5: 2987.0601 | G5: 3141.8463 | I5: 3853.3445 | K5: 4092.4937 | M5: 4450.4578 | N5: 4526.7615 | O5: 4790.54
B6: 5.A. Disposición de residuos solidos | C6: 1698.598 | E6: 2054.4701 | G6: 2447.1187 | I6: 2760.6934 | K6: 2934.3884 | M6: 3335.8732 | N6: 3496.885 | O6: 3665.9319
B7: 5.A.1. Sitios de disposición de residuos sólidos gestionados | C7: 892.43222 | E7: 1173.3147 | G7: 1286.3125 | I7: 2067.9211 | K7: 2433.744 | M7: 2796.3571 | N7: 3028.8829 | O7: 3183.2121 | P7: Netas
B8: 5.A.2. Sitios de disposición de residuos sólidos no gestionados | C8: 806.1658 | E8: 881.15542 | G8: 1160.8061 | I8: 692.77238 | K8: 500.64433 | M8: 539.51612 | N8: 468.00217 | O8: 482.71985
B9: 5.B. Tratamiento Biológico de residuos solidos | C9: 1.0625676 | E9: 1.4055142 | G9: 7.1154774 | I9: 5.2039248 | K9: 6.4633359 | M9: 7.0399622 | N9: 7.3797023 | O9: 6.4519188
B10: 5.B.1. Compostaje | C10: 1.0625676 | E10: 1.4055142 | G10: 7.1154774 | I10: 5.2039248 | K10: 6.4633359 | M10: 7.0399622 | N10: 7.3797023 | O10: 6.4519188
B11: 5.C. Incineración y quema abierta de residuos | C11: 13.36686 | E11: 14.441346 | G11: 15.224293 | I11: 15.116414 | K11: 15.464941 | M11: 21.81834 | N11: 13.342577 | O11: 17.204674
B12: 5.C.1. Incineración de residuos | C12: 13.36686 | E12: 14.441346 | G12: 15.224293 | I12: 15.116414 | K12: 15.464941 | M12: 21.81834 | N12: 13.342577 | O12: 17.204674
B13: 5.D. Eliminación y tratamiento de aguas residuales | C13: 558.87253 | E13: 916.74315 | G13: 672.38786 | I13: 1072.3308 | K13: 1136.1771 | M13: 1085.7262 | N13: 1009.1542 | O13: 1100.9514
B14: 5.D.1. Aguas residuales domesticas | C14: 405.26496 | E14: 474.50609 | G14: 487.37141 | I14: 492.64169 | K14: 505.78156 | M14: 511.49266 | N14: 518.66483 | O14: 505.68739
B15: 5.D.2. Aguas residuales industriales | C15: 153.60757 | E15: 442.23707 | G15: 185.01644 | I15: 579.68907 | K15: 630.39552 | M15: 574.23356 | N15: 490.48939 | O15: 595.26405
B19: Interpolado
B21: GgCO2e | C21: 2010 | D21: 2011 | E21: 2012 | F21: 2013 | G21: 2014 | H21: 2015 | I21: 2016 | J21: 2017 | K21: 2018 | L21: 2019 | M21: 2020 | N21: 2021 | O21: 2022
B22: 5. Residuos | C22: =C23+C26+C28+C30 -> 2271.9 | D22: =D23+D26+D28+D30 -> 2629.48 | E22: =E23+E26+E28+E30 -> 2987.0601 | F22: =F23+F26+F28+F30 -> 3064.4532 | G22: =G23+G26+G28+G30 -> 3141.8463 | H22: =H23+H26+H28+H30 -> 3497.5954 | I22: =I23+I26+I28+I30 -> 3853.3445 | J22: =J23+J26+J28+J30 -> 3972.9191 | ... O22: =O23+O26+O28+O30 -> 4790.54
B23: 5.A. Disposición de residuos solidos | C23: =C24+C25 -> 1698.598 | D23: =D24+D25 -> 1876.5341 | E23: =E24+E25 -> 2054.4701 | F23: =F24+F25 -> 2250.7944 | G23: =G24+G25 -> 2447.1187 | H23: =H24+H25 -> 2603.9061 | I23: =I24+I25 -> 2760.6934 | J23: =J24+J25 -> 2847.5409 | ... O23: =O24+O25 -> 3665.9319
B24: 5.A.1. Sitios de disposición de residuos sólidos gestionados | C24: 892.43222 | D24: 1032.8734 | E24: 1173.3147 | F24: 1229.8136 | G24: 1286.3125 | H24: 1677.1168 | I24: 2067.9211 | J24: 2250.8325 | K24: 2433.744 | L24: 2615.0506 | M24: 2796.3571 | N24: 3028.8829 | O24: 3183.2121 | P24: Netas
B25: 5.A.2. Sitios de disposición de residuos sólidos no gestionados | C25: 806.1658 | D25: 843.66061 | E25: 881.15542 | F25: 1020.9808 | G25: 1160.8061 | H25: 926.78925 | I25: 692.77238 | J25: 596.70835 | K25: 500.64433 | L25: 520.08022 | M25: 539.51612 | N25: 468.00217 | O25: 482.71985
B26: 5.B. Tratamiento Biológico de residuos solidos | C26: =C27 -> 1.0625676 | D26: =D27 -> 1.2340409 | E26: =E27 -> 1.4055142 | F26: =F27 -> 4.2604958 | G26: =G27 -> 7.1154774 | H26: =H27 -> 6.1597011 | I26: =I27 -> 5.2039248 | J26: =J27 -> 5.8336303 | ... O26: =O27 -> 6.4519188
B27: 5.B.1. Compostaje | C27: 1.0625676 | D27: 1.2340409 | E27: 1.4055142 | F27: 4.2604958 | G27: 7.1154774 | H27: 6.1597011 | I27: 5.2039248 | J27: 5.8336303 | K27: 6.4633359 | L27: 6.7516491 | M27: 7.0399622 | N27: 7.3797023 | O27: 6.4519188
B28: 5.C. Incineración y quema abierta de residuos | C28: =C29 -> 13.36686 | D28: =D29 -> 13.904103 | E28: =E29 -> 14.441346 | F28: =F29 -> 14.83282 | G28: =G29 -> 15.224293 | H28: =H29 -> 15.170354 | I28: =I29 -> 15.116414 | J28: =J29 -> 15.290677 | ... O28: =O29 -> 17.204674
B29: 5.C.1. Incineración de residuos | C29: 13.36686 | D29: 13.904103 | E29: 14.441346 | F29: 14.83282 | G29: 15.224293 | H29: 15.170354 | I29: 15.116414 | J29: 15.290677 | K29: 15.464941 | L29: 18.64164 | M29: 21.81834 | N29: 13.342577 | O29: 17.204674
B30: 5.D. Eliminación y tratamiento de aguas residuales | C30: =C31+C32 -> 558.87253 | D30: =D31+D32 -> 737.80784 | E30: =E31+E32 -> 916.74315 | F30: =F31+F32 -> 794.56551 | G30: =G31+G32 -> 672.38786 | H30: =H31+H32 -> 872.35931 | I30: =I31+I32 -> 1072.3308 | J30: =J31+J32 -> 1104.2539 | ... O30: =O31+O32 -> 1100.9514
B31: 5.D.1. Aguas residuales domesticas | C31: 405.26496 | D31: 439.88552 | E31: 474.50609 | F31: 480.93875 | G31: 487.37141 | H31: 490.00655 | I31: 492.64169 | J31: 499.21163 | K31: 505.78156 | L31: 508.63711 | M31: 511.49266 | N31: 518.66483 | O31: 505.68739
B32: 5.D.2. Aguas residuales industriales | C32: 153.60757 | D32: 297.92232 | E32: 442.23707 | F32: 313.62676 | G32: 185.01644 | H32: 382.35276 | I32: 579.68907 | J32: 605.0423 | K32: 630.39552 | L32: 602.31454 | M32: 574.23356 | N32: 490.48939 | O32: 595.26405

Sheet T_5A1
D5: NOTA IMPORTANTE: (4) Si las emisiones de CH4 recuperadas se utilizan para obtener energía, las emisiones procedentes del proceso de combustión deben notificarse en la categoría 1.A y se facilitan aquí únicamente a título informativo.
C9: 5.A.1. Sitios de disposición final de residuos solidos gestionados
E14: 2010 | F14: 2011 | G14: 2012 | H14: 2013 | I14: 2014 | J14: 2015 | K14: 2016 | L14: 2017 | M14: 2018 | N14: 2019 | O14: 2020 | P14: 2021 | Q14: 2022
D15: Datos de actividad (kt) | E15: 1247.2264 | G15: 1448.2413 | I15: 1710.8245 | K15: 2217.9568 | M15: 2461.8405 | O15: 2492.1224 | P15: 2639.8994 | Q15: 2749.1917
D16: FE neto [ktCH4/kt] | E16: 0.025554767 | G16: 0.02893447 | I16: 0.026852394 | K16: 0.03329836 | M16: 0.035306686 | O16: 0.040074235 | P16: 0.040976709 | Q16: 0.041352571
D17: Emisiones netas [ktCH4] | E17: 31.872579 | G17: 41.904095 | I17: 45.939733 | K17: 73.854324 | M17: 86.91943 | O17: 99.869897 | P17: 108.17439 | Q17: 113.68615
D18: Metano recuperado [ktCH4] | E18: 0 | F18: 0 | G18: 0 | H18: 0 | I18: 0 | J18: 0 | K18: 3.0756572 | M18: 10.0849 | O18: 10.123647 | P18: 9.6484388 | Q18: 9.5143395
D19: Emisiones netas [ktCO2e] | E19: =E17*E25 -> 892.43222 | F19: =F17*F25 -> 0 | G19: =G17*G25 -> 1173.3147 | H19: =H17*H25 -> 0 | I19: =I17*I25 -> 1286.3125 | J19: =J17*J25 -> 0 | K19: =K17*K25 -> 2067.9211 | L19: =L17*L25 -> 0 | ... Q19: =Q17*Q25 -> 3183.2121
D20: Metano recuperado [ktCO2e] | E20: =E18*E25 -> 0 | F20: =F18*F25 -> 0 | G20: =G18*G25 -> 0 | H20: =H18*H25 -> 0 | I20: =I18*I25 -> 0 | J20: =J18*J25 -> 0 | K20: =K18*K25 -> 86.118403 | L20: =L18*L25 -> 0 | ... Q20: =Q18*Q25 -> 266.40151
D21: FE bruto [ktCH4/kt] | E21: =(E17+E18)/E15 -> 0.025554767 | G21: =(G17+G18)/G15 -> 0.02893447 | I21: =(I17+I18)/I15 -> 0.026852394 | K21: =(K17+K18)/K15 -> 0.034685067 | M21: =(M17+M18)/M15 -> 0.039403174 | O21: =(O17+O18)/O15 -> 0.044136494 | P21: =(P17+P18)/P15 -> 0.04463156 | Q21: =(Q17+Q18)/Q15 -> 0.044813348
D22: Emisiones brutas [ktCH4] | E22: =E17+E18 -> 31.872579 | G22: =G17+G18 -> 41.904095 | I22: =I17+I18 -> 45.939733 | K22: =K17+K18 -> 76.929981 | M22: =M17+M18 -> 97.00433 | O22: =O17+O18 -> 109.99354 | P22: =P17+P18 -> 117.82283 | Q22: =Q17+Q18 -> 123.20048
D24: PCG
D25: CH4 | E25: 28 | F25: 28 | G25: 28 | H25: 28 | I25: 28 | J25: 28 | K25: 28 | L25: 28 | M25: 28 | N25: 28 | O25: 28 | P25: 28 | Q25: 28
D27: Emisiones 5CN
B28: netas | C28: ktCO2e | D28: 5.A.1. Sitios de disposición de residuos sólidos gestionados | E28: 892.43222 | F28: 1032.8734 | G28: 1173.3147 | H28: 1229.8136 | I28: 1286.3125 | J28: 1677.1168 | K28: 2067.9211 | L28: 2250.8325 | M28: 2433.744 | N28: 2615.0506 | O28: 2796.3571 | P28: 3028.8829 | Q28: 3183.2121
B29: brutas | C29: ktCO2e | D29: 5.A.1. Sitios de disposición de residuos sólidos gestionados | E29: 892.43222 | F29: 1032.8734 | G29: 1173.3147 | H29: 1229.8136 | I29: 1286.3125 | J29: 1720.176 | K29: 2154.0395 | L29: 2435.0804 | M29: 2716.1212 | N29: 2897.9702 | O29: 3079.8192 | P29: =P19+P20 -> 3299.0392 | Q29: =Q19+Q20 -> 3449.6136
D30: Interpolar FE
D31: FE neto [ktCH4/kt] | E31: 0.025554767 | F31: 0.027244619 | G31: 0.02893447 | H31: 0.027893432 | I31: 0.026852394 | J31: 0.030075377 | K31: 0.03329836 | L31: 0.034302523 | M31: 0.035306686 | N31: 0.03769046 | O31: 0.040074235 | P31: 0.040976709 | Q31: 0.041352571
D32: FE bruto [ktCH4/kt] | E32: 0.025554767 | F32: 0.027244619 | G32: 0.02893447 | H32: 0.027893432 | I32: 0.026852394 | J32: 0.030768731 | K32: 0.034685067 | L32: 0.037044121 | M32: 0.039403174 | N32: 0.041769834 | O32: 0.044136494 | P32: 0.04463156 | Q32: 0.044813348
D33: Cálculo de actividad [Emisiones/Factor de emisión]
D34: Datos de actividad netas (kt) | E34: 1247.2264 | F34: =F28/(F31*F25) -> 1353.9678 | G34: 1448.2413 | H34: =H28/(H31*H25) -> 1574.6328 | I34: 1710.8245 | J34: =J28/(J31*J25) -> 1991.5637 | K34: 2217.9568 | L34: =L28/(L31*L25) -> 2343.4684 | M34: 2461.8405 | N34: =N28/(N31*N25) -> 2477.9391 | O34: 2492.1224 | P34: 2639.8994 | Q34: 2749.1917
D35: Datos de actividad brutas (kt) | E35: =E29/(E32*28) -> 1247.2264 | F35: =F29/(F32*28) -> 1353.9678 | G35: =G29/(G32*28) -> 1448.2413 | H35: =H29/(H32*28) -> 1574.6328 | I35: =I29/(I32*28) -> 1710.8245 | J35: =J29/(J32*28) -> 1996.6653 | K35: =K29/(K32*28) -> 2217.9568 | L35: =L29/(L32*28) -> 2347.6642 | ... Q35: =Q29/(Q32*28) -> 2749.1917
C38: NETAS
E39: 2010 | F39: 2011 | G39: 2012 | H39: 2013 | I39: 2014 | J39: 2015 | K39: 2016 | L39: 2017 | M39: 2018 | N39: 2019 | O39: 2020 | P39: 2021 | Q39: 2022
D40: Actividad [Mt residuos] | E40: =ROUND(E34/1000,4) -> 1.2472 | F40: =ROUND(F34/1000,4) -> 1.354 | G40: =ROUND(G34/1000,4) -> 1.4482 | H40: =ROUND(H34/1000,4) -> 1.5746 | I40: =ROUND(I34/1000,4) -> 1.7108 | J40: =ROUND(J34/1000,4) -> 1.9916 | K40: =ROUND(K34/1000,4) -> 2.218 | L40: =ROUND(L34/1000,4) -> 2.3435 | ... Q40: =ROUND(Q34/1000,4) -> 2.7492
D41: FE neto [MtCO2e/Mt residuos] | E41: =ROUND(E28/E34,4) -> 0.7155 | F41: =ROUND(F28/F34,4) -> 0.7628 | G41: =ROUND(G28/G34,4) -> 0.8102 | H41: =ROUND(H28/H34,4) -> 0.781 | I41: =ROUND(I28/I34,4) -> 0.7519 | J41: =ROUND(J28/J34,4) -> 0.8421 | K41: =ROUND(K28/K34,4) -> 0.9324 | L41: =ROUND(L28/L34,4) -> 0.9605 | ... Q41: =ROUND(Q28/Q34,4) -> 1.1579
D42: FE neto [MtCO2e por CO2/Mt residuos] | E42: 0 | F42: 0 | G42: 0 | H42: 0 | I42: 0 | J42: 0 | K42: 0 | L42: 0 | M42: 0 | N42: 0 | O42: 0 | P42: 0 | Q42: 0
D43: FE neto [MtCO2e por CH4/Mt residuos] | E43: =ROUND(E16*E25,4) -> 0.7155 | F43: =ROUND(F31*F25,4) -> 0.7628 | G43: =ROUND(G16*G25,4) -> 0.8102 | H43: =ROUND(H31*H25,4) -> 0.781 | I43: =ROUND(I16*I25,4) -> 0.7519 | J43: =ROUND(J31*J25,4) -> 0.8421 | K43: =ROUND(K16*K25,4) -> 0.9324 | L43: =ROUND(L31*L25,4) -> 0.9605 | M43: =ROUND(M16*M25,4) -> 0.9886 | N43: =ROUND(N31*N25,4) -> 1.0553 | O43: =ROUND(O16*O25,4) -> 1.1221 | P43: =ROUND(P16*P25,4) -> 1.1473 | Q43: =ROUND(Q16*Q25,4) -> 1.1579
D44: FE neto [MtCO2e por N2O/Mt residuos] | E44: 0 | F44: 0 | G44: 0 | H44: 0 | I44: 0 | J44: 0 | K44: 0 | L44: 0 | M44: 0 | N44: 0 | O44: 0 | P44: 0 | Q44: 0
D45: Emisiones netas [MtCO2e] | E45: =E40*E41 -> 0.8923716 | F45: =F40*F41 -> 1.0328312 | G45: =G40*G41 -> 1.1733316 | H45: =H40*H41 -> 1.2297626 | I45: =I40*I41 -> 1.2863505 | J45: =J40*J41 -> 1.6771264 | K45: =K40*K41 -> 2.0680632 | L45: =L40*L41 -> 2.2509318 | ... Q45: =Q40*Q41 -> 3.1832987
D46: Emisiones netas [MtCO2e por CO2] | E46: =E40*E42 -> 0 | F46: =F40*F42 -> 0 | G46: =G40*G42 -> 0 | H46: =H40*H42 -> 0 | I46: =I40*I42 -> 0 | J46: =J40*J42 -> 0 | K46: =K40*K42 -> 0 | L46: =L40*L42 -> 0 | ... Q46: =Q40*Q42 -> 0
D47: Emisiones netas [MtCO2e por CH4] | E47: =E40*E43 -> 0.8923716 | F47: =F40*F43 -> 1.0328312 | G47: =G40*G43 -> 1.1733316 | H47: =H40*H43 -> 1.2297626 | I47: =I40*I43 -> 1.2863505 | J47: =J40*J43 -> 1.6771264 | K47: =K40*K43 -> 2.0680632 | L47: =L40*L43 -> 2.2509318 | ... Q47: =Q40*Q43 -> 3.1832987
D48: Emisiones netas [MtCO2e por N2O] | E48: =E40*E44 -> 0 | F48: =F40*F44 -> 0 | G48: =G40*G44 -> 0 | H48: =H40*H44 -> 0 | I48: =I40*I44 -> 0 | J48: =J40*J44 -> 0 | K48: =K40*K44 -> 0 | L48: =L40*L44 -> 0 | ... Q48: =Q40*Q44 -> 0
D49: Comprobación | E49: =E45-E46-E47-E48 -> 0 | F49: =F45-F46-F47-F48 -> 0 | G49: =G45-G46-G47-G48 -> 0 | H49: =H45-H46-H47-H48 -> 0 | I49: =I45-I46-I47-I48 -> 0 | J49: =J45-J46-J47-J48 -> 0 | K49: =K45-K46-K47-K48 -> 0 | L49: =L45-L46-L47-L48 -> 0 | ... Q49: =Q45-Q46-Q47-Q48 -> 0
C52: NETAS FINAL
E53: 2010 | F53: 2011 | G53: 2012 | H53: 2013 | I53: 2014 | J53: 2015 | K53: 2016 | L53: 2017 | M53: 2018 | N53: 2019 | O53: 2020 | P53: 2021 | Q53: 2022 | R53: 2023 | S53: 2024 | T53: 2025 | U53: 2026 | V53: 2027 | W53: 2028 | X53: 2029 | Y53: 2030 | Z53: 2031 | AA53: 2032 | AB53: 2033 | AC53: 2034 | AD53: 2035
D54: Actividad [Mt residuos] | E54: =E40 -> 1.2472 | F54: =F40 -> 1.354 | G54: =G40 -> 1.4482 | H54: =H40 -> 1.5746 | I54: =I40 -> 1.7108 | J54: =J40 -> 1.9916 | K54: =K40 -> 2.218 | L54: =L40 -> 2.3435 | ... Q54: =Q40 -> 2.7492 | R54: 2.9082 | S54: 3.0701 | T54: 3.2348 | U54: 3.4022 | V54: 3.5721 | W54: 3.7446 | X54: 3.9197 | Y54: 4.097 | Z54: 4.177 | AA54: 4.2571 | AB54: 4.3372 | AC54: 4.4173 | AD54: 4.4973
D55: FE neto [MtCO2e/Mt residuos] | E55: =E41 -> 0.7155 | F55: =F41 -> 0.7628 | G55: =G41 -> 0.8102 | H55: =H41 -> 0.781 | I55: =I41 -> 0.7519 | J55: =J41 -> 0.8421 | K55: =K41 -> 0.9324 | L55: =L41 -> 0.9605 | ... Q55: =Q41 -> 1.1579 | R55: =ROUND(R57*$Q$25,4) -> 1.2068 | S55: =ROUND(S57*$Q$25,4) -> 1.2572 | T55: =ROUND(T57*$Q$25,4) -> 1.3104 | U55: =ROUND(U57*$Q$25,4) -> 1.3664 | V55: =ROUND(V57*$Q$25,4) -> 1.4224 | W55: =ROUND(W57*$Q$25,4) -> 1.4812 | X55: =ROUND(X57*$Q$25,4) -> 1.5428 | Y55: =ROUND(Y57*$Q$25,4) -> 1.6072 | ... AD55: =ROUND(AD57*$Q$25,4) -> 1.9712
D56: FE neto [MtCO2/Mt residuos] | E56: =E42 -> 0 | F56: =F42 -> 0 | G56: =G42 -> 0 | H56: =H42 -> 0 | I56: =I42 -> 0 | J56: =J42 -> 0 | K56: =K42 -> 0 | L56: =L42 -> 0 | ... Q56: =Q42 -> 0 | R56: 0 | S56: 0 | T56: 0 | U56: 0 | V56: 0 | W56: 0 | X56: 0 | Y56: 0 | Z56: 0 | AA56: 0 | AB56: 0 | AC56: 0 | AD56: 0
D57: FE neto [MtCH4/Mt residuos] | E57: =ROUND(E16,4) -> 0.0256 | F57: =ROUND(F31,4) -> 0.0272 | G57: =ROUND(G16,4) -> 0.0289 | H57: =ROUND(H31,4) -> 0.0279 | I57: =ROUND(I16,4) -> 0.0269 | J57: =ROUND(J31,4) -> 0.0301 | K57: =ROUND(K16,4) -> 0.0333 | L57: =ROUND(L31,4) -> 0.0343 | M57: =ROUND(M16,4) -> 0.0353 | N57: =ROUND(N31,4) -> 0.0377 | O57: =ROUND(O16,4) -> 0.0401 | P57: =ROUND(P16,4) -> 0.041 | Q57: =ROUND(Q16,4) -> 0.0414 | R57: =ROUND(Q57*(1+$Q$67),4) -> 0.0431 | S57: =ROUND(R57*(1+$Q$67),4) -> 0.0449 | T57: =ROUND(S57*(1+$Q$67),4) -> 0.0468 | U57: =ROUND(T57*(1+$Q$67),4) -> 0.0488 | V57: =ROUND(U57*(1+$Q$67),4) -> 0.0508 | W57: =ROUND(V57*(1+$Q$67),4) -> 0.0529 | X57: =ROUND(W57*(1+$Q$67),4) -> 0.0551 | Y57: =ROUND(X57*(1+$Q$67),4) -> 0.0574 | ... AD57: =ROUND(AC57*(1+$Q$67),4) -> 0.0704
...

Sheet T_5A2
D9: 5.A.2. Sitios de disposición final de residuos solidos no gestionados
E13: 2010 | F13: 2011 | G13: 2012 | H13: 2013 | I13: 2014 | J13: 2015 | K13: 2016 | L13: 2017 | M13: 2018 | N13: 2019 | O13: 2020 | P13: 2021 | Q13: 2022
D14: Datos de actividad (kt) | E14: 1126.664 | G14: 1087.6244 | I14: 1543.8982 | K14: 713.32918 | M14: 453.77448 | O14: 436.56465 | P14: 374.4965 | Q14: 384.70669
D15: FE [ktCH4/kt] | E15: 0.025554767 | G15: 0.02893447 | I15: 0.026852394 | K15: 0.034685067 | M15: 0.039403174 | O15: 0.044136494 | P15: 0.04463156 | Q15: 0.044813348
D16: Emisiones [ktCH4] | E16: 28.791636 | G16: 31.469836 | I16: 41.457362 | K16: 24.741871 | M16: 17.880155 | O16: 19.268433 | P16: 16.714363 | Q16: 17.239995
D17: Emisiones [ktCO2e] | E17: =E16*E22 -> 806.1658 | F17: =F16*F22 -> 0 | G17: =G16*G22 -> 881.15542 | H17: =H16*H22 -> 0 | I17: =I16*I22 -> 1160.8061 | J17: =J16*J22 -> 0 | K17: =K16*K22 -> 692.77238 | L17: =L16*L22 -> 0 | ... Q17: =Q16*Q22 -> 482.71985
D21: PCG
D22: CH4 | E22: 28 | F22: 28 | G22: 28 | H22: 28 | I22: 28 | J22: 28 | K22: 28 | L22: 28 | M22: 28 | N22: 28 | O22: 28 | P22: 28 | Q22: 28
D24: 5ta CN interpolada
D25: 5.A.2. Sitios de disposición de residuos sólidos no gestionados | E25: 806.1658 | F25: 843.66061 | G25: 881.15542 | H25: 1020.9808 | I25: 1160.8061 | J25: 926.78925 | K25: 692.77238 | L25: 596.70835 | M25: 500.64433 | N25: 520.08022 | O25: 539.51612 | P25: 468.00217 | Q25: 482.71985
D27: Interpolar FE
D28: FE [ktCH4/kt] | E28: 0.025554767 | F28: 0.027244619 | G28: 0.02893447 | H28: 0.027893432 | I28: 0.026852394 | J28: 0.030768731 | K28: 0.034685067 | L28: 0.037044121 | M28: 0.039403174 | N28: 0.041769834 | O28: 0.044136494 | P28: 0.04463156 | Q28: 0.044813348
D30: Cálculo de actividad [Emisiones/Factor de emisión]
D31: Datos de actividad (kt) | E31: 1126.664 | F31: =F25/(F28*F22) -> 1105.9335 | G31: 1087.6244 | H31: =H25/(H28*H22) -> 1307.2468 | I31: 1543.8982 | J31: =J25/(J28*J22) -> 1075.755 | K31: 713.32918 | L31: =L25/(L28*L22) -> 575.28731 | M31: 453.77448 | N31: =N25/(N28*N22) -> 444.68201 | O31: 436.56465 | P31: 374.4965 | Q31: 384.70669
E36: 2010 | F36: 2011 | G36: 2012 | H36: 2013 | I36: 2014 | J36: 2015 | K36: 2016 | L36: 2017 | M36: 2018 | N36: 2019 | O36: 2020 | P36: 2021 | Q36: 2022
D37: Actividad [Mt residuos] | E37: =ROUND(E31/1000,4) -> 1.1267 | F37: =ROUND(F31/1000,4) -> 1.1059 | G37: =ROUND(G31/1000,4) -> 1.0876 | H37: =ROUND(H31/1000,4) -> 1.3072 | I37: =ROUND(I31/1000,4) -> 1.5439 | J37: =ROUND(J31/1000,4) -> 1.0758 | K37: =ROUND(K31/1000,4) -> 0.7133 | L37: =ROUND(L31/1000,4) -> 0.5753 | ... Q37: =ROUND(Q31/1000,4) -> 0.3847
D38: FE [MtCO2e/Mt residuos] | E38: =ROUND(E25/E31,4) -> 0.7155 | F38: =ROUND(F25/F31,4) -> 0.7628 | G38: =ROUND(G25/G31,4) -> 0.8102 | H38: =ROUND(H25/H31,4) -> 0.781 | I38: =ROUND(I25/I31,4) -> 0.7519 | J38: =ROUND(J25/J31,4) -> 0.8615 | K38: =ROUND(K25/K31,4) -> 0.9712 | L38: =ROUND(L25/L31,4) -> 1.0372 | ... Q38: =ROUND(Q25/Q31,4) -> 1.2548
D39: FE [MtCO2e por CO2/Mt residuos] | E39: 0 | F39: 0 | G39: 0 | H39: 0 | I39: 0 | J39: 0 | K39: 0 | L39: 0 | M39: 0 | N39: 0 | O39: 0 | P39: 0 | Q39: 0
D40: FE [MtCO2e por CH4/Mt residuos] | E40: =ROUND(E15*E22,4) -> 0.7155 | F40: =ROUND(F28*F22,4) -> 0.7628 | G40: =ROUND(G15*G22,4) -> 0.8102 | H40: =ROUND(H28*H22,4) -> 0.781 | I40: =ROUND(I15*I22,4) -> 0.7519 | J40: =ROUND(J28*J22,4) -> 0.8615 | K40: =ROUND(K15*K22,4) -> 0.9712 | L40: =ROUND(L28*L22,4) -> 1.0372 | M40: =ROUND(M15*M22,4) -> 1.1033 | N40: =ROUND(N28*N22,4) -> 1.1696 | O40: =ROUND(O15*O22,4) -> 1.2358 | P40: =ROUND(P15*P22,4) -> 1.2497 | Q40: =ROUND(Q15*Q22,4) -> 1.2548
D41: FE [MtCO2e por N2O/Mt residuos] | E41: 0 | F41: 0 | G41: 0 | H41: 0 | I41: 0 | J41: 0 | K41: 0 | L41: 0 | M41: 0 | N41: 0 | O41: 0 | P41: 0 | Q41: 0
D42: Emisiones [MtCO2e] | E42: =E37*E38 -> 0.80615385 | F42: =F37*F38 -> 0.84358052 | G42: =G37*G38 -> 0.88117352 | H42: =H37*H38 -> 1.0209232 | I42: =I37*I38 -> 1.1608584 | J42: =J37*J38 -> 0.9268017 | K42: =K37*K38 -> 0.69275696 | L42: =L37*L38 -> 0.59670116 | ... Q42: =Q37*Q38 -> 0.48272156
D43: Emisiones [MtCO2e por CO2] | E43: =E37*E39 -> 0 | F43: =F37*F39 -> 0 | G43: =G37*G39 -> 0 | H43: =H37*H39 -> 0 | I43: =I37*I39 -> 0 | J43: =J37*J39 -> 0 | K43: =K37*K39 -> 0 | L43: =L37*L39 -> 0 | ... Q43: =Q37*Q39 -> 0
D44: Emisiones [MtCO2e por CH4] | E44: =E37*E40 -> 0.80615385 | F44: =F37*F40 -> 0.84358052 | G44: =G37*G40 -> 0.88117352 | H44: =H37*H40 -> 1.0209232 | I44: =I37*I40 -> 1.1608584 | J44: =J37*J40 -> 0.9268017 | K44: =K37*K40 -> 0.69275696 | L44: =L37*L40 -> 0.59670116 | ... Q44: =Q37*Q40 -> 0.48272156
D45: Emisiones [MtCO2e por N2O] | E45: =E37*E41 -> 0 | F45: =F37*F41 -> 0 | G45: =G37*G41 -> 0 | H45: =H37*H41 -> 0 | I45: =I37*I41 -> 0 | J45: =J37*J41 -> 0 | K45: =K37*K41 -> 0 | L45: =L37*L41 -> 0 | ... Q45: =Q37*Q41 -> 0
D46: Comprobación | E46: =E42-E43-E44-E45 -> 0 | F46: =F42-F43-F44-F45 -> 0 | G46: =G42-G43-G44-G45 -> 0 | H46: =H42-H43-H44-H45 -> 0 | I46: =I42-I43-I44-I45 -> 0 | J46: =J42-J43-J44-J45 -> 0 | K46: =K42-K43-K44-K45 -> 0 | L46: =L42-L43-L44-L45 -> 0 | ... Q46: =Q42-Q43-Q44-Q45 -> 0
C49: FINAL
E50: 2010 | F50: 2011 | G50: 2012 | H50: 2013 | I50: 2014 | J50: 2015 | K50: 2016 | L50: 2017 | M50: 2018 | N50: 2019 | O50: 2020 | P50: 2021 | Q50: 2022 | R50: 2023 | S50: 2024 | T50: 2025 | U50: 2026 | V50: 2027 | W50: 2028 | X50: 2029 | Y50: 2030 | Z50: 2031 | AA50: 2032 | AB50: 2033 | AC50: 2034 | AD50: 2035
D51: Actividad [Mt residuos] | E51: =E37 -> 1.1267 | F51: =F37 -> 1.1059 | G51: =G37 -> 1.0876 | H51: =H37 -> 1.3072 | I51: =I37 -> 1.5439 | J51: =J37 -> 1.0758 | K51: =K37 -> 0.7133 | L51: =L37 -> 0.5753 | ... Q51: =Q37 -> 0.3847 | R51: 0.4069 | S51: 0.4296 | T51: 0.4526 | U51: 0.476 | V51: 0.4998 | W51: 0.5239 | X51: 0.5484 | Y51: 0.5733 | Z51: 0.5844 | AA51: 0.5957 | AB51: 0.6069 | AC51: 0.6181 | AD51: 0.6293
D52: FE [MtCO2e/Mt residuos] | E52: =E38 -> 0.7155 | F52: =F38 -> 0.7628 | G52: =G38 -> 0.8102 | H52: =H38 -> 0.781 | I52: =I38 -> 0.7519 | J52: =J38 -> 0.8615 | K52: =K38 -> 0.9712 | L52: =L38 -> 1.0372 | ... Q52: =Q38 -> 1.2548 | R52: =ROUND(R54*$Q$22,4) -> 1.316 | S52: =ROUND(S54*$Q$22,4) -> 1.3804 | T52: =ROUND(T54*$Q$22,4) -> 1.4476 | U52: =ROUND(U54*$Q$22,4) -> 1.5176 | V52: =ROUND(V54*$Q$22,4) -> 1.5932 | W52: =ROUND(W54*$Q$22,4) -> 1.6716 | X52: =ROUND(X54*$Q$22,4) -> 1.7528 | Y52: =ROUND(Y54*$Q$22,4) -> 1.8396 | ... AD52: =ROUND(AD54*$Q$22,4) -> 2.3352
D53: FE [MtCO2/Mt residuos] | E53: =E39 -> 0 | F53: =F39 -> 0 | G53: =G39 -> 0 | H53: =H39 -> 0 | I53: =I39 -> 0 | J53: =J39 -> 0 | K53: =K39 -> 0 | L53: =L39 -> 0 | ... Q53: =Q39 -> 0 | R53: 0 | S53: 0 | T53: 0 | U53: 0 | V53: 0 | W53: 0 | X53: 0 | Y53: 0 | Z53: 0 | AA53: 0 | AB53: 0 | AC53: 0 | AD53: 0
D54: FE [MtCH4/Mt residuos] | E54: =ROUND(E15,4) -> 0.0256 | F54: =ROUND(F28,4) -> 0.0272 | G54: =ROUND(G15,4) -> 0.0289 | H54: =ROUND(H28,4) -> 0.0279 | I54: =ROUND(I15,4) -> 0.0269 | J54: =ROUND(J28,4) -> 0.0308 | K54: =ROUND(K15,4) -> 0.0347 | L54: =ROUND(L28,4) -> 0.037 | M54: =ROUND(M15,4) -> 0.0394 | N54: =ROUND(N28,4) -> 0.0418 | O54: =ROUND(O15,4) -> 0.0441 | P54: =ROUND(P15,4) -> 0.0446 | Q54: =ROUND(Q15,4) -> 0.0448 | R54: =ROUND(Q54*(1+$Q$67),4) -> 0.047 | S54: =ROUND(R54*(1+$Q$67),4) -> 0.0493 | T54: =ROUND(S54*(1+$Q$67),4) -> 0.0517 | U54: =ROUND(T54*(1+$Q$67),4) -> 0.0542 | V54: =ROUND(U54*(1+$Q$67),4) -> 0.0569 | W54: =ROUND(V54*(1+$Q$67),4) -> 0.0597 | X54: =ROUND(W54*(1+$Q$67),4) -> 0.0626 | Y54: =ROUND(X54*(1+$Q$67),4) -> 0.0657 | ... AD54: =ROUND(AC54*(1+$Q$67),4) -> 0.0834
D55: FE [MtN2O/Mt residuos] | E55: =E41 -> 0 | F55: =F41 -> 0 | G55: =G41 -> 0 | H55: =H41 -> 0 | I55: =I41 -> 0 | J55: =J41 -> 0 | K55: =K41 -> 0 | L55: =L41 -> 0 | ... Q55: =Q41 -> 0 | R55: 0 | S55: 0 | T55: 0 | U55: 0 | V55: 0 | W55: 0 | X55: 0 | Y55: 0 | Z55: 0 | AA55: 0 | AB55: 0 | AC55: 0 | AD55: 0
D56: Emisiones [MtCO2e] | E56: =E51*E52 -> 0.80615385 | F56: =F51*F52 -> 0.84358052 | G56: =G51*G52 -> 0.88117352 | H56: =H51*H52 -> 1.0209232 | I56: =I51*I52 -> 1.1608584 | J56: =J51*J52 -> 0.9268017 | K56: =K51*K52 -> 0.69275696 | L56: =L51*L52 -> 0.59670116 | ... AD56: =AD51*AD52 -> 1.4695414
D57: Emisiones [MtCO2] | E57: =E51*E53 -> 0 | F57: =F51*F53 -> 0 | G57: =G51*G53 -> 0 | H57: =H51*H53 -> 0 | I57: =I51*I53 -> 0 | J57: =J51*J53 -> 0 | K57: =K51*K53 -> 0 | L57: =L51*L53 -> 0 | ... Q57: =Q51*Q53 -> 0 | R57: 0 | S57: 0 | T57: 0 | U57: 0 | V57: 0 | W57: 0 | X57: 0 | Y57: 0 | Z57: 0 | AA57: 0 | AB57: 0 | AC57: 0 | AD57: 0
D58: Emisiones [MtCH4] | E58: =E51*E54 -> 0.02884352 | F58: =F51*F54 -> 0.03008048 | G58: =G51*G54 -> 0.03143164 | H58: =H51*H54 -> 0.03647088 | I58: =I51*I54 -> 0.04153091 | J58: =J51*J54 -> 0.03313464 | K58: =K51*K54 -> 0.02475151 | L58: =L51*L54 -> 0.0212861 | ... AD58: =AD51*AD54 -> 0.05248362
D59: Emisiones [MtN2O] | E59: =E51*E55 -> 0 | F59: =F51*F55 -> 0 | G59: =G51*G55 -> 0 | H59: =H51*H55 -> 0 | I59: =I51*I55 -> 0 | J59: =J51*J55 -> 0 | K59: =K51*K55 -> 0 | L59: =L51*L55 -> 0 | ... Q59: =Q51*Q55 -> 0 | R59: 0 | S59: 0 | T59: 0 | U59: 0 | V59: 0 | W59: 0 | X59: 0 | Y59: 0 | Z59: 0 | AA59: 0 | AB59: 0 | AC59: 0 | AD59: 0
E65: =(F54-E54)/(E54) -> 0.0625 | F65: =(G54-F54)/(F54) -> 0.0625 | G65: =(H54-G54)/(G54) -> -0.034602076 | H65: =(I54-H54)/(H54) -> -0.035842294 | I65: =(J54-I54)/(I54) -> 0.14498141 | J65: =(K54-J54)/(J54) -> 0.12662338 | K65: =(L54-K54)/(K54) -> 0.066282421 | L65: =(M54-L54)/(L54) -> 0.064864865 | ... P65: =(Q54-P54)/(P54) -> 0.0044843049
P67: Promedio | Q67: =AVERAGE(E65:P65) -> 0.049088959

Sheet T_Compostaje
D4: Compostaje por año | G4: 2010 | H4: 2011 | I4: 2012 | J4: 2013 | K4: 2014 | L4: 2015 | M4: 2016 | N4: 2017 | O4: 2018 | P4: 2019 | Q4: 2020 | R4: 2021 | S4: 2022 | T4: 2023 | U4: 2024 | V4: 2025 | W4: 2026 | X4: 2027 | Y4: 2028 | Z4: 2029 | AA4: 2030 | AB4: 2031 | AC4: 2032 | AD4: 2033 | AE4: 2034 | AF4: 2035
D5: Gg | G5: 5.548656 | H5: =H11/$G$14 -> 6.444078 | I5: 7.3395 | J5: =J11/$G$14 -> 22.24802 | K5: 37.15654 | L5: =L11/$G$14 -> 32.165541 | M5: 27.174542 | N5: =N11/$G$14 -> 30.462822 | O5: 33.751101 | P5: =P11/$G$14 -> 35.256653 | Q5: 36.762205 | R5: 38.536305 | S5: 33.691482
D6: Fuente: 5ta Comu
D7: Hoja: TABLA 2. 5B
D11: Emisiones compostaje 5CN [GgCO2e] | G11: 1.0625676 | H11: 1.2340409 | I11: 1.4055142 | J11: 4.2604958 | K11: 7.1154774 | L11: 6.1597011 | M11: 5.2039248 | N11: 5.8336303 | O11: 6.4633359 | P11: 6.7516491 | Q11: 7.0399622 | R11: 7.3797023 | S11: 6.4519188
D14: Factor de emisión calculado [GgCO2e/Gg] o MtCO2e/Mt | G14: =G11/G5 -> 0.1915 | I14: =I11/I5 -> 0.1915 | K14: =K11/K5 -> 0.1915 | M14: =M11/M5 -> 0.1915 | O14: =O11/O5 -> 0.1915 | Q14: =Q11/Q5 -> 0.1915 | R14: =R11/R5 -> 0.1915 | S14: =S11/S5 -> 0.1915
D15: kgN2O/kg | G15: =0.3/1000 -> 0.0003 | H15: =0.3/1000 -> 0.0003 | I15: =0.3/1000 -> 0.0003 | J15: =0.3/1000 -> 0.0003 | K15: =0.3/1000 -> 0.0003 | L15: =0.3/1000 -> 0.0003 | M15: =0.3/1000 -> 0.0003 | N15: =0.3/1000 -> 0.0003 | ... S15: =0.3/1000 -> 0.0003
D16: kgCH4/kg | G16: =4/1000 -> 0.004 | H16: =4/1000 -> 0.004 | I16: =4/1000 -> 0.004 | J16: =4/1000 -> 0.004 | K16: =4/1000 -> 0.004 | L16: =4/1000 -> 0.004 | M16: =4/1000 -> 0.004 | N16: =4/1000 -> 0.004 | ... S16: =4/1000 -> 0.004
D18: PCG
D19: N2O | G19: 265 | H19: 265 | I19: 265 | J19: 265 | K19: 265 | L19: 265 | M19: 265 | N19: 265 | O19: 265 | P19: 265 | Q19: 265 | R19: 265 | S19: 265
D20: CH4 | G20: 28 | H20: 28 | I20: 28 | J20: 28 | K20: 28 | L20: 28 | M20: 28 | N20: 28 | O20: 28 | P20: 28 | Q20: 28 | R20: 28 | S20: 28
D21: Fuente: TABLA 4. 5B y PCG de PCG 1
D23: Factores de emisión finales
D24: GgCO2e por N2O/Gg | G24: =G15*G19 -> 0.0795 | H24: =H15*H19 -> 0.0795 | I24: =I15*I19 -> 0.0795 | J24: =J15*J19 -> 0.0795 | K24: =K15*K19 -> 0.0795 | L24: =L15*L19 -> 0.0795 | M24: =M15*M19 -> 0.0795 | N24: =N15*N19 -> 0.0795 | ... S24: =S15*S19 -> 0.0795
D25: GgCO2e por CH4/Gg | G25: =G16*G20 -> 0.112 | H25: =H16*H20 -> 0.112 | I25: =I16*I20 -> 0.112 | J25: =J16*J20 -> 0.112 | K25: =K16*K20 -> 0.112 | L25: =L16*L20 -> 0.112 | M25: =M16*M20 -> 0.112 | N25: =N16*N20 -> 0.112 | ... S25: =S16*S20 -> 0.112
D26: GgCO2e total/Gg | G26: =G24+G25 -> 0.1915 | H26: =H24+H25 -> 0.1915 | I26: =I24+I25 -> 0.1915 | J26: =J24+J25 -> 0.1915 | K26: =K24+K25 -> 0.1915 | L26: =L24+L25 -> 0.1915 | M26: =M24+M25 -> 0.1915 | N26: =N24+N25 -> 0.1915 | ... S26: =S24+S25 -> 0.1915
G31: 2010 | H31: 2011 | I31: 2012 | J31: 2013 | K31: 2014 | L31: 2015 | M31: 2016 | N31: 2017 | O31: 2018 | P31: 2019 | Q31: 2020 | R31: 2021 | S31: 2022
D32: Actividad [Mt residuos] | G32: =ROUND(G5/1000,4) -> 0.0055 | H32: =ROUND(H5/1000,4) -> 0.0064 | I32: =ROUND(I5/1000,4) -> 0.0073 | J32: =ROUND(J5/1000,4) -> 0.0222 | K32: =ROUND(K5/1000,4) -> 0.0372 | L32: =ROUND(L5/1000,4) -> 0.0322 | M32: =ROUND(M5/1000,4) -> 0.0272 | N32: =ROUND(N5/1000,4) -> 0.0305 | ... S32: =ROUND(S5/1000,4) -> 0.0337
D33: FE [MtCO2e/Mt residuos] | G33: =ROUND(G26,4) -> 0.1915 | H33: =ROUND(H26,4) -> 0.1915 | I33: =ROUND(I26,4) -> 0.1915 | J33: =ROUND(J26,4) -> 0.1915 | K33: =ROUND(K26,4) -> 0.1915 | L33: =ROUND(L26,4) -> 0.1915 | M33: =ROUND(M26,4) -> 0.1915 | N33: =ROUND(N26,4) -> 0.1915 | ... S33: =ROUND(S26,4) -> 0.1915
D34: FE [MtCO2e por CO2/Mt residuos] | G34: 0 | H34: 0 | I34: 0 | J34: 0 | K34: 0 | L34: 0 | M34: 0 | N34: 0 | O34: 0 | P34: 0 | Q34: 0 | R34: 0 | S34: 0
D35: FE [MtCO2e por CH4/Mt residuos] | G35: =ROUND(G25,4) -> 0.112 | H35: =ROUND(H25,4) -> 0.112 | I35: =ROUND(I25,4) -> 0.112 | J35: =ROUND(J25,4) -> 0.112 | K35: =ROUND(K25,4) -> 0.112 | L35: =ROUND(L25,4) -> 0.112 | M35: =ROUND(M25,4) -> 0.112 | N35: =ROUND(N25,4) -> 0.112 | ... S35: =ROUND(S25,4) -> 0.112
D36: FE [MtCO2e por N2O/Mt residuos] | G36: =ROUND(G24,4) -> 0.0795 | H36: =ROUND(H24,4) -> 0.0795 | I36: =ROUND(I24,4) -> 0.0795 | J36: =ROUND(J24,4) -> 0.0795 | K36: =ROUND(K24,4) -> 0.0795 | L36: =ROUND(L24,4) -> 0.0795 | M36: =ROUND(M24,4) -> 0.0795 | N36: =ROUND(N24,4) -> 0.0795 | ... S36: =ROUND(S24,4) -> 0.0795
D37: Emisiones [MtCO2e] | G37: =G32*G33 -> 0.00105325 | H37: =H32*H33 -> 0.0012256 | I37: =I32*I33 -> 0.00139795 | J37: =J32*J33 -> 0.0042513 | K37: =K32*K33 -> 0.0071238 | L37: =L32*L33 -> 0.0061663 | M37: =M32*M33 -> 0.0052088 | N37: =N32*N33 -> 0.00584075 | ... S37: =S32*S33 -> 0.00645355
D38: Emisiones [MtCO2e por CO2] | G38: =G32*G34 -> 0 | H38: =H32*H34 -> 0 | I38: =I32*I34 -> 0 | J38: =J32*J34 -> 0 | K38: =K32*K34 -> 0 | L38: =L32*L34 -> 0 | M38: =M32*M34 -> 0 | N38: =N32*N34 -> 0 | ... S38: =S32*S34 -> 0
D39: Emisiones [MtCO2e por CH4] | G39: =G32*G35 -> 0.000616 | H39: =H32*H35 -> 0.0007168 | I39: =I32*I35 -> 0.0008176 | J39: =J32*J35 -> 0.0024864 | K39: =K32*K35 -> 0.0041664 | L39: =L32*L35 -> 0.0036064 | M39: =M32*M35 -> 0.0030464 | N39: =N32*N35 -> 0.003416 | ... S39: =S32*S35 -> 0.0037744
D40: Emisiones [MtCO2e por N2O] | G40: =G32*G36 -> 0.00043725 | H40: =H32*H36 -> 0.0005088 | I40: =I32*I36 -> 0.00058035 | J40: =J32*J36 -> 0.0017649 | K40: =K32*K36 -> 0.0029574 | L40: =L32*L36 -> 0.0025599 | M40: =M32*M36 -> 0.0021624 | N40: =N32*N36 -> 0.00242475 | ... S40: =S32*S36 -> 0.00267915
D41: Comprobación | G41: =G37-G38-G39-G40 -> 0 | H41: =H37-H38-H39-H40 -> 0 | I41: =I37-I38-I39-I40 -> 0 | J41: =J37-J38-J39-J40 -> 0 | K41: =K37-K38-K39-K40 -> 0 | L41: =L37-L38-L39-L40 -> 0 | M41: =M37-M38-M39-M40 -> 0 | N41: =N37-N38-N39-N40 -> 0 | ... S41: =S37-S38-S39-S40 -> 0
C44: FINAL
G45: 2010 | H45: 2011 | I45: 2012 | J45: 2013 | K45: 2014 | L45: 2015 | M45: 2016 | N45: 2017 | O45: 2018 | P45: 2019 | Q45: 2020 | R45: 2021 | S45: 2022 | T45: 2023 | U45: 2024 | V45: 2025 | W45: 2026 | X45: 2027 | Y45: 2028 | Z45: 2029 | AA45: 2030 | AB45: 2031 | AC45: 2032 | AD45: 2033 | AE45: 2034 | AF45: 2035
D46: Actividad [Mt residuos] | G46: =G32 -> 0.0055 | H46: =H32 -> 0.0064 | I46: =I32 -> 0.0073 | J46: =J32 -> 0.0222 | K46: =K32 -> 0.0372 | L46: =L32 -> 0.0322 | M46: =M32 -> 0.0272 | N46: =N32 -> 0.0305 | ... S46: =S32 -> 0.0337 | T46: 0.0356 | U46: 0.0376 | V46: 0.0396 | W46: 0.0417 | X46: 0.0437 | Y46: 0.0459 | Z46: 0.048 | AA46: 0.0502 | AB46: 0.0512 | AC46: 0.0521 | AD46: 0.0531 | AE46: 0.0541 | AF46: 0.0551
D47: FE [MtCO2e/Mt residuos] | G47: =G33 -> 0.1915 | H47: =H33 -> 0.1915 | I47: =I33 -> 0.1915 | J47: =J33 -> 0.1915 | K47: =K33 -> 0.1915 | L47: =L33 -> 0.1915 | M47: =M33 -> 0.1915 | N47: =N33 -> 0.1915 | ... S47: =S33 -> 0.1915 | T47: =S47 -> 0.1915 | U47: =T47 -> 0.1915 | V47: =U47 -> 0.1915 | W47: =V47 -> 0.1915 | X47: =W47 -> 0.1915 | Y47: =X47 -> 0.1915 | Z47: =Y47 -> 0.1915 | AA47: =Z47 -> 0.1915 | ... AF47: =AE47 -> 0.1915
D48: FE [MtCO2/Mt residuos] | G48: =G34 -> 0 | H48: =H34 -> 0 | I48: =I34 -> 0 | J48: =J34 -> 0 | K48: =K34 -> 0 | L48: =L34 -> 0 | M48: =M34 -> 0 | N48: =N34 -> 0 | ... S48: =S34 -> 0 | T48: 0 | U48: 0 | V48: 0 | W48: 0 | X48: 0 | Y48: 0 | Z48: 0 | AA48: 0 | AB48: 0 | AC48: 0 | AD48: 0 | AE48: 0 | AF48: 0
D49: FE [MtCH4/Mt residuos] | G49: =ROUND(G16,4) -> 0.004 | H49: =ROUND(H16,4) -> 0.004 | I49: =ROUND(I16,4) -> 0.004 | J49: =ROUND(J16,4) -> 0.004 | K49: =ROUND(K16,4) -> 0.004 | L49: =ROUND(L16,4) -> 0.004 | M49: =ROUND(M16,4) -> 0.004 | N49: =ROUND(N16,4) -> 0.004 | ... S49: =ROUND(S16,4) -> 0.004 | T49: =S49 -> 0.004 | U49: =T49 -> 0.004 | V49: =U49 -> 0.004 | W49: =V49 -> 0.004 | X49: =W49 -> 0.004 | Y49: =X49 -> 0.004 | Z49: =Y49 -> 0.004 | AA49: =Z49 -> 0.004 | ... AF49: =AE49 -> 0.004
D50: FE [MtN2O/Mt residuos] | G50: =ROUND(G15,4) -> 0.0003 | H50: =ROUND(H15,4) -> 0.0003 | I50: =ROUND(I15,4) -> 0.0003 | J50: =ROUND(J15,4) -> 0.0003 | K50: =ROUND(K15,4) -> 0.0003 | L50: =ROUND(L15,4) -> 0.0003 | M50: =ROUND(M15,4) -> 0.0003 | N50: =ROUND(N15,4) -> 0.0003 | ... S50: =ROUND(S15,4) -> 0.0003 | T50: =S50 -> 0.0003 | U50: =T50 -> 0.0003 | V50: =U50 -> 0.0003 | W50: =V50 -> 0.0003 | X50: =W50 -> 0.0003 | Y50: =X50 -> 0.0003 | Z50: =Y50 -> 0.0003 | AA50: =Z50 -> 0.0003 | ... AF50: =AE50 -> 0.0003
D51: Emisiones [MtCO2e] | G51: =G46*G47 -> 0.00105325 | H51: =H46*H47 -> 0.0012256 | I51: =I46*I47 -> 0.00139795 | J51: =J46*J47 -> 0.0042513 | K51: =K46*K47 -> 0.0071238 | L51: =L46*L47 -> 0.0061663 | M51: =M46*M47 -> 0.0052088 | N51: =N46*N47 -> 0.00584075 | ... AF51: =AF46*AF47 -> 0.01055165
D52: Emisiones [MtCO2] | G52: =G46*G48 -> 0 | H52: =H46*H48 -> 0 | I52: =I46*I48 -> 0 | J52: =J46*J48 -> 0 | K52: =K46*K48 -> 0 | L52: =L46*L48 -> 0 | M52: =M46*M48 -> 0 | N52: =N46*N48 -> 0 | ... AF52: =AF46*AF48 -> 0
D53: Emisiones [MtCH4] | G53: =G46*G49 -> 2.2e-05 | H53: =H46*H49 -> 2.56e-05 | I53: =I46*I49 -> 2.92e-05 | J53: =J46*J49 -> 8.88e-05 | K53: =K46*K49 -> 0.0001488 | L53: =L46*L49 -> 0.0001288 | M53: =M46*M49 -> 0.0001088 | N53: =N46*N49 -> 0.000122 | ... AF53: =AF46*AF49 -> 0.0002204
D54: Emisiones [MtN2O] | G54: =G46*G50 -> 1.65e-06 | H54: =H46*H50 -> 1.92e-06 | I54: =I46*I50 -> 2.19e-06 | J54: =J46*J50 -> 6.66e-06 | K54: =K46*K50 -> 1.116e-05 | L54: =L46*L50 -> 9.66e-06 | M54: =M46*M50 -> 8.16e-06 | N54: =N46*N50 -> 9.15e-06 | ... AF54: =AF46*AF50 -> 1.653e-05

Sheet T_Incineracion
B2: 5.C.1. Incineración de residuos
B3: Fuente: Table 5.C
C4: 2010 | D4: 2011 | E4: 2012 | F4: 2013 | G4: 2014 | H4: 2015 | I4: 2016 | J4: 2017 | K4: 2018 | L4: 2019 | M4: 2020 | N4: 2021 | O4: 2022
B5: Actividad (kt residuos incinerados o quemados a cielo abierto) o [Gg] | C5: 9.1007805 | D5: =D36/D37 -> 9.7188226 | E5: 10.370705 | F5: =F36/F37 -> 10.825826 | G5: 11.296062 | H5: =H36/H37 -> 11.232176 | I5: 11.168561 | J5: =J36/J37 -> 11.373139 | K5: 11.580481 | L5: =L36/L37 -> 15.114021 | M5: 19.284897 | N5: 9.129278 | O5: 13.651929
B6: FE [kgCO2/t de residuos] | C6: 1.4485257 | D6: =D28/D16 -> 1.4103882 | E6: 1.3722795 | F6: =F28/F16 -> 1.3498935 | G6: 1.3275183 | H6: =H28/H16 -> 1.3303816 | I6: 1.3332451 | J6: =J28/J16 -> 1.3242205 | K6: 1.3151976 | L6: =L28/L16 -> 1.2108969 | M6: 1.1072274 | N6: 1.4386684 | O6: 1.2364653
B7: FE [kgCH4/t de residuos] | C7: 5.3791321e-06 | D7: =D29/D17 -> 5.3829545e-06 | E7: 5.3791321e-06 | F7: =F29/F17 -> 5.3805677e-06 | G7: 5.3791321e-06 | H7: =H29/H17 -> 5.3791563e-06 | I7: 5.3791321e-06 | J7: =J29/J17 -> 5.3793744e-06 | K7: 5.3791321e-06 | L7: =L29/L17 -> 6.2277029e-06 | M7: 6.8678845e-06 | N7: 1.7041028e-05 | O7: 1.233453e-05
B8: FE [kgN2O/t de residuos] | C8: 7.5786279e-05 | D8: =D30/D18 -> 7.5840133e-05 | E8: 7.5786279e-05 | F8: =F30/F18 -> 7.5806506e-05 | G8: 7.5786279e-05 | H8: =H30/H18 -> 7.578662e-05 | I8: 7.5786279e-05 | J8: =J30/J18 -> 7.5789693e-05 | K8: 7.5786279e-05 | L8: =L30/L18 -> 8.4261152e-05 | M8: 9.0375893e-05 | N8: 8.4413386e-05 | O8: 8.8403213e-05
B9: Emisiones [ktCO2] o [Gg] | C9: 13.182715 | E9: 14.231506 | G9: 14.995729 | I9: 14.89043 | K9: 15.230622 | M9: 21.352766 | N9: 13.134003 | O9: 16.880137
B10: Emisiones [ktCH4] o [Gg] | C10: 4.89543e-05 | E10: 5.5785394e-05 | G10: 6.0763011e-05 | I10: 6.0077164e-05 | K10: 6.2292939e-05 | M10: 0.00013244645 | N10: 0.00015557228 | O10: 0.00016839013
B11: Emisiones [ktN2O] o [Gg] | C11: 0.00068971429 | E11: 0.00078595716 | G11: 0.00085608652 | I11: 0.00084642367 | K11: 0.00087764158 | M11: 0.0017428898 | N11: 0.00077063327 | O11: 0.0012068744
B15: PCG
B16: CO2 | C16: 1 | D16: 1 | E16: 1 | F16: 1 | G16: 1 | H16: 1 | I16: 1 | J16: 1 | K16: 1 | L16: 1 | M16: 1 | N16: 1 | O16: 1
B17: CH4 | C17: 28 | D17: 28 | E17: 28 | F17: 28 | G17: 28 | H17: 28 | I17: 28 | J17: 28 | K17: 28 | L17: 28 | M17: 28 | N17: 28 | O17: 28
B18: N2O | C18: 265 | D18: 265 | E18: 265 | F18: 265 | G18: 265 | H18: 265 | I18: 265 | J18: 265 | K18: 265 | L18: 265 | M18: 265 | N18: 265 | O18: 265
B21: Emisiones [ktCO2e por CO2] o [GgCO2e] | C21: =C5*C6*C16 -> 13.182715 | D21: =D5*D6*D16 -> 13.707313 | E21: =E5*E6*E16 -> 14.231506 | F21: =F5*F6*F16 -> 14.613712 | G21: =G5*G6*G16 -> 14.995729 | H21: =H5*H6*H16 -> 14.943081 | I21: =I5*I6*I16 -> 14.89043 | J21: =J5*J6*J16 -> 15.060543 | ... O21: =O5*O6*O16 -> 16.880137
B22: Emisiones [ktCO2e por CH4] o [GgCO2e] | C22: =C5*C7*C17 -> 0.0013707204 | D22: =D5*D7*D17 -> 0.0014648474 | E22: =E5*E7*E17 -> 0.001561991 | F22: =F5*F7*F17 -> 0.0016309745 | G22: =G5*G7*G17 -> 0.0017013643 | H22: =H5*H7*H17 -> 0.0016917497 | I22: =I5*I7*I17 -> 0.0016821606 | J22: =J5*J7*J17 -> 0.0017130504 | ... O22: =O5*O7*O17 -> 0.0047149235
B23: Emisiones [ktCO2e por N2O] o [GgCO2e] | C23: =C5*C8*C18 -> 0.18277429 | D23: =D5*D8*D18 -> 0.19532535 | E23: =E5*E8*E18 -> 0.20827865 | F23: =F5*F8*F18 -> 0.21747703 | G23: =G5*G8*G18 -> 0.22686293 | H23: =H5*H8*H18 -> 0.2255809 | I23: =I5*I8*I18 -> 0.22430227 | J23: =J5*J8*J18 -> 0.22842117 | ... O23: =O5*O8*O18 -> 0.31982172
B24: Emisiones totales [ktCO2e] o [GgCO2e] | C24: =SUM(C21:C23) -> 13.36686 | D24: =SUM(D21:D23) -> 13.904103 | E24: =SUM(E21:E23) -> 14.441346 | F24: =SUM(F21:F23) -> 14.83282 | G24: =SUM(G21:G23) -> 15.224293 | H24: =SUM(H21:H23) -> 15.170354 | I24: =SUM(I21:I23) -> 15.116414 | J24: =SUM(J21:J23) -> 15.290677 | ... O24: =SUM(O21:O23) -> 17.204674
B27: Factores de emisión finales
B28: GgCO2e por CO2/Gg | C28: =C6*C16 -> 1.4485257 | D28: =D37*D41 -> 1.4103882 | E28: =E6*E16 -> 1.3722795 | F28: =F37*F41 -> 1.3498935 | G28: =G6*G16 -> 1.3275183 | H28: =H37*H41 -> 1.3303816 | I28: =I6*I16 -> 1.3332451 | J28: =J37*J41 -> 1.3242205 | K28: =K6*K16 -> 1.3151976 | L28: =L37*L41 -> 1.2108969 | M28: =M6*M16 -> 1.1072274 | N28: =N6*N16 -> 1.4386684 | O28: =O6*O16 -> 1.2364653
B29: GgCO2e por CH4/Gg | C29: =C7*C17 -> 0.0001506157 | D29: =D37*D42 -> 0.00015072273 | E29: =E7*E17 -> 0.0001506157 | F29: =F37*F42 -> 0.0001506559 | G29: =G7*G17 -> 0.0001506157 | H29: =H37*H42 -> 0.00015061638 | I29: =I7*I17 -> 0.0001506157 | J29: =J37*J42 -> 0.00015062248 | K29: =K7*K17 -> 0.0001506157 | L29: =L37*L42 -> 0.00017437568 | M29: =M7*M17 -> 0.00019230077 | N29: =N7*N17 -> 0.00047714877 | O29: =O7*O17 -> 0.00034536683
B30: GgCO2e por N20/Gg | C30: =C8*C18 -> 0.020083364 | D30: =D37*D43 -> 0.020097635 | E30: =E8*E18 -> 0.020083364 | F30: =F37*F43 -> 0.020088724 | G30: =G8*G18 -> 0.020083364 | H30: =H37*H43 -> 0.020083454 | I30: =I8*I18 -> 0.020083364 | J30: =J37*J43 -> 0.020084269 | K30: =K8*K18 -> 0.020083364 | L30: =L37*L43 -> 0.022329205 | M30: =M8*M18 -> 0.023949612 | N30: =N8*N18 -> 0.022369547 | O30: =O8*O18 -> 0.023426851
B31: GgCO2e total/Gg | C31: =SUM(C28:C30) -> 1.4687597 | D31: =SUM(D28:D30) -> 1.4306366 | E31: =SUM(E28:E30) -> 1.3925134 | F31: =SUM(F28:F30) -> 1.3701328 | G31: =SUM(G28:G30) -> 1.3477522 | H31: =SUM(H28:H30) -> 1.3506157 | I31: =SUM(I28:I30) -> 1.3534791 | J31: =SUM(J28:J30) -> 1.3444554 | ... O31: =SUM(O28:O30) -> 1.2602376
B35: Emisiones 5CN interpolada
B36: 5.C.1. Incineración de residuos | C36: 13.36686 | D36: 13.904103 | E36: 14.441346 | F36: 14.83282 | G36: 15.224293 | H36: 15.170354 | I36: 15.116414 | J36: 15.290677 | K36: 15.464941 | L36: 18.64164 | M36: 21.81834 | N36: 13.342577 | O36: 17.204674
